INFO:aiogram.dispatcher:Start polling
INFO:aiogram.dispatcher:Run polling for bot @mariam_chat_bot id=7628846836 - 'mariam_chat_bot'
INFO:aiogram.event:Update id=607674295 is handled. Duration 430 ms by bot id=7628846836
INFO:aiogram.event:Update id=607674296 is not handled. Duration 1 ms by bot id=7628846836
INFO:aiogram.event:Update id=607674297 is handled. Duration 136 ms by bot id=7628846836
INFO:aiogram.event:Update id=607674298 is handled. Duration 188 ms by bot id=7628846836
WARNING:aiogram.dispatcher:Received SIGINT signal
INFO:aiogram.dispatcher:Polling stopped for bot @mariam_chat_bot id=7628846836 - 'mariam_chat_bot'
INFO:aiogram.dispatcher:Polling stopped
INFO:aiogram.dispatcher:Start polling
INFO:aiogram.dispatcher:Run polling for bot @mariam_chat_bot id=7628846836 - 'mariam_chat_bot'
INFO:aiogram.event:Update id=607674299 is handled. Duration 323 ms by bot id=7628846836
INFO:aiogram.event:Update id=607674300 is handled. Duration 167 ms by bot id=7628846836
WARNING:aiogram.dispatcher:Received SIGINT signal
INFO:aiogram.dispatcher:Polling stopped for bot @mariam_chat_bot id=7628846836 - 'mariam_chat_bot'
INFO:aiogram.dispatcher:Polling stopped
INFO:aiogram.dispatcher:Start polling
INFO:aiogram.dispatcher:Run polling for bot @mariam_chat_bot id=7628846836 - 'mariam_chat_bot'
INFO:aiogram.event:Update id=607674301 is handled. Duration 341 ms by bot id=7628846836
WARNING:aiogram.dispatcher:Received SIGINT signal
INFO:aiogram.dispatcher:Polling stopped for bot @mariam_chat_bot id=7628846836 - 'mariam_chat_bot'
INFO:aiogram.dispatcher:Polling stopped
INFO:aiogram.dispatcher:Start polling
INFO:aiogram.dispatcher:Run polling for bot @mariam_chat_bot id=7628846836 - 'mariam_chat_bot'
WARNING:aiogram.dispatcher:Received SIGINT signal
INFO:aiogram.dispatcher:Polling stopped for bot @mariam_chat_bot id=7628846836 - 'mariam_chat_bot'
INFO:aiogram.dispatcher:Polling stopped
INFO:aiogram.dispatcher:Start polling
INFO:aiogram.dispatcher:Run polling for bot @mariam_chat_bot id=7628846836 - 'mariam_chat_bot'
WARNING:aiogram.dispatcher:Received SIGINT signal
INFO:aiogram.dispatcher:Polling stopped for bot @mariam_chat_bot id=7628846836 - 'mariam_chat_bot'
INFO:aiogram.dispatcher:Polling stopped
INFO:aiogram.dispatcher:Start polling
INFO:aiogram.dispatcher:Run polling for bot @mariam_chat_bot id=7628846836 - 'mariam_chat_bot'
INFO:aiogram.event:Update id=607674302 is not handled. Duration 8 ms by bot id=7628846836
ERROR:aiogram.event:Cause exception while process update id=607674302 by bot id=7628846836
TypeError: global_error_handler() missing 1 required positional argument: 'error'
Traceback (most recent call last):
  File "/Users/hubievkasym/Desktop/Python Projects/IT_round/.venv/lib/python3.12/site-packages/aiogram/dispatcher/middlewares/error.py", line 25, in __call__
    return await handler(event, data)
           ^^^^^^^^^^^^^^^^^^^^^^^^^^
  File "/Users/hubievkasym/Desktop/Python Projects/IT_round/.venv/lib/python3.12/site-packages/aiogram/dispatcher/middlewares/user_context.py", line 56, in __call__
    return await handler(event, data)
           ^^^^^^^^^^^^^^^^^^^^^^^^^^
  File "/Users/hubievkasym/Desktop/Python Projects/IT_round/.venv/lib/python3.12/site-packages/aiogram/fsm/middleware.py", line 42, in __call__
    return await handler(event, data)
           ^^^^^^^^^^^^^^^^^^^^^^^^^^
  File "/Users/hubievkasym/Desktop/Python Projects/IT_round/.venv/lib/python3.12/site-packages/aiogram/dispatcher/event/telegram.py", line 121, in trigger
    return await wrapped_inner(event, kwargs)
           ^^^^^^^^^^^^^^^^^^^^^^^^^^^^^^^^^^
  File "/Users/hubievkasym/Desktop/Python Projects/IT_round/.venv/lib/python3.12/site-packages/aiogram/dispatcher/event/handler.py", line 43, in call
    return await wrapped()
           ^^^^^^^^^^^^^^^
  File "/Users/hubievkasym/Desktop/Python Projects/IT_round/.venv/lib/python3.12/site-packages/aiogram/dispatcher/dispatcher.py", line 276, in _listen_update
    return await self.propagate_event(update_type=update_type, event=event, **kwargs)
           ^^^^^^^^^^^^^^^^^^^^^^^^^^^^^^^^^^^^^^^^^^^^^^^^^^^^^^^^^^^^^^^^^^^^^^^^^^
  File "/Users/hubievkasym/Desktop/Python Projects/IT_round/.venv/lib/python3.12/site-packages/aiogram/dispatcher/router.py", line 146, in propagate_event
    return await observer.wrap_outer_middleware(_wrapped, event=event, data=kwargs)
           ^^^^^^^^^^^^^^^^^^^^^^^^^^^^^^^^^^^^^^^^^^^^^^^^^^^^^^^^^^^^^^^^^^^^^^^^
  File "/Users/hubievkasym/Desktop/Python Projects/IT_round/.venv/lib/python3.12/site-packages/aiogram/dispatcher/router.py", line 141, in _wrapped
    return await self._propagate_event(
           ^^^^^^^^^^^^^^^^^^^^^^^^^^^^
  File "/Users/hubievkasym/Desktop/Python Projects/IT_round/.venv/lib/python3.12/site-packages/aiogram/dispatcher/router.py", line 166, in _propagate_event
    response = await observer.trigger(event, **kwargs)
               ^^^^^^^^^^^^^^^^^^^^^^^^^^^^^^^^^^^^^^^
  File "/Users/hubievkasym/Desktop/Python Projects/IT_round/.venv/lib/python3.12/site-packages/aiogram/dispatcher/event/telegram.py", line 121, in trigger
    return await wrapped_inner(event, kwargs)
           ^^^^^^^^^^^^^^^^^^^^^^^^^^^^^^^^^^
  File "/Users/hubievkasym/Desktop/Python Projects/IT_round/.venv/lib/python3.12/site-packages/aiogram/dispatcher/event/handler.py", line 43, in call
    return await wrapped()
           ^^^^^^^^^^^^^^^
  File "/Users/hubievkasym/Desktop/Python Projects/IT_round/app/telebot.py", line 74, in wrapper
    if not database.account_exists(user_id=str(message.chat.id)):
           ^^^^^^^^^^^^^^^^^^^^^^^^^^^^^^^^^^^^^^^^^^^^^^^^^^^^^
  File "/Users/hubievkasym/Desktop/Python Projects/IT_round/app/database/sql.py", line 18, in wrapper
    result = func(session=session, *args, **kwargs)
             ^^^^^^^^^^^^^^^^^^^^^^^^^^^^^^^^^^^^^^
  File "/Users/hubievkasym/Desktop/Python Projects/IT_round/app/database/sql.py", line 84, in account_exists
    session.query(AccountData)
  File "/Users/hubievkasym/Desktop/Python Projects/IT_round/.venv/lib/python3.12/site-packages/sqlalchemy/orm/session.py", line 2955, in query
    return self._query_cls(entities, self, **kwargs)
           ^^^^^^^^^^^^^^^^^^^^^^^^^^^^^^^^^^^^^^^^^
  File "/Users/hubievkasym/Desktop/Python Projects/IT_round/.venv/lib/python3.12/site-packages/sqlalchemy/orm/query.py", line 276, in __init__
    self._set_entities(entities)
  File "/Users/hubievkasym/Desktop/Python Projects/IT_round/.venv/lib/python3.12/site-packages/sqlalchemy/orm/query.py", line 289, in _set_entities
    coercions.expect(
  File "/Users/hubievkasym/Desktop/Python Projects/IT_round/.venv/lib/python3.12/site-packages/sqlalchemy/sql/coercions.py", line 388, in expect
    insp._post_inspect
  File "/Users/hubievkasym/Desktop/Python Projects/IT_round/.venv/lib/python3.12/site-packages/sqlalchemy/util/langhelpers.py", line 1338, in __get__
    obj.__dict__[self.__name__] = result = self.fget(obj)
                                           ^^^^^^^^^^^^^^
  File "/Users/hubievkasym/Desktop/Python Projects/IT_round/.venv/lib/python3.12/site-packages/sqlalchemy/orm/mapper.py", line 2724, in _post_inspect
    self._check_configure()
  File "/Users/hubievkasym/Desktop/Python Projects/IT_round/.venv/lib/python3.12/site-packages/sqlalchemy/orm/mapper.py", line 2401, in _check_configure
    _configure_registries({self.registry}, cascade=True)
  File "/Users/hubievkasym/Desktop/Python Projects/IT_round/.venv/lib/python3.12/site-packages/sqlalchemy/orm/mapper.py", line 4214, in _configure_registries
    _do_configure_registries(registries, cascade)
  File "/Users/hubievkasym/Desktop/Python Projects/IT_round/.venv/lib/python3.12/site-packages/sqlalchemy/orm/mapper.py", line 4255, in _do_configure_registries
    mapper._post_configure_properties()
  File "/Users/hubievkasym/Desktop/Python Projects/IT_round/.venv/lib/python3.12/site-packages/sqlalchemy/orm/mapper.py", line 2418, in _post_configure_properties
    prop.init()
  File "/Users/hubievkasym/Desktop/Python Projects/IT_round/.venv/lib/python3.12/site-packages/sqlalchemy/orm/interfaces.py", line 589, in init
    self.do_init()
  File "/Users/hubievkasym/Desktop/Python Projects/IT_round/.venv/lib/python3.12/site-packages/sqlalchemy/orm/relationships.py", line 1656, in do_init
    self._setup_entity()
  File "/Users/hubievkasym/Desktop/Python Projects/IT_round/.venv/lib/python3.12/site-packages/sqlalchemy/orm/relationships.py", line 1886, in _setup_entity
    raise sa_exc.ArgumentError(
sqlalchemy.exc.ArgumentError: relationship 'group' expects a class or a mapper argument (received: <class 'sqlalchemy.sql.schema.Table'>)

During handling of the above exception, another exception occurred:

Traceback (most recent call last):
  File "/Users/hubievkasym/Desktop/Python Projects/IT_round/.venv/lib/python3.12/site-packages/aiogram/dispatcher/dispatcher.py", line 309, in _process_update
    response = await self.feed_update(bot, update, **kwargs)
               ^^^^^^^^^^^^^^^^^^^^^^^^^^^^^^^^^^^^^^^^^^^^^
  File "/Users/hubievkasym/Desktop/Python Projects/IT_round/.venv/lib/python3.12/site-packages/aiogram/dispatcher/dispatcher.py", line 158, in feed_update
    response = await self.update.wrap_outer_middleware(
               ^^^^^^^^^^^^^^^^^^^^^^^^^^^^^^^^^^^^^^^^
  File "/Users/hubievkasym/Desktop/Python Projects/IT_round/.venv/lib/python3.12/site-packages/aiogram/dispatcher/middlewares/error.py", line 29, in __call__
    response = await self.router.propagate_event(
               ^^^^^^^^^^^^^^^^^^^^^^^^^^^^^^^^^^
  File "/Users/hubievkasym/Desktop/Python Projects/IT_round/.venv/lib/python3.12/site-packages/aiogram/dispatcher/router.py", line 146, in propagate_event
    return await observer.wrap_outer_middleware(_wrapped, event=event, data=kwargs)
           ^^^^^^^^^^^^^^^^^^^^^^^^^^^^^^^^^^^^^^^^^^^^^^^^^^^^^^^^^^^^^^^^^^^^^^^^
  File "/Users/hubievkasym/Desktop/Python Projects/IT_round/.venv/lib/python3.12/site-packages/aiogram/dispatcher/router.py", line 141, in _wrapped
    return await self._propagate_event(
           ^^^^^^^^^^^^^^^^^^^^^^^^^^^^
  File "/Users/hubievkasym/Desktop/Python Projects/IT_round/.venv/lib/python3.12/site-packages/aiogram/dispatcher/router.py", line 166, in _propagate_event
    response = await observer.trigger(event, **kwargs)
               ^^^^^^^^^^^^^^^^^^^^^^^^^^^^^^^^^^^^^^^
  File "/Users/hubievkasym/Desktop/Python Projects/IT_round/.venv/lib/python3.12/site-packages/aiogram/dispatcher/event/telegram.py", line 121, in trigger
    return await wrapped_inner(event, kwargs)
           ^^^^^^^^^^^^^^^^^^^^^^^^^^^^^^^^^^
  File "/Users/hubievkasym/Desktop/Python Projects/IT_round/.venv/lib/python3.12/site-packages/aiogram/dispatcher/event/handler.py", line 43, in call
    return await wrapped()
                 ^^^^^^^^^
TypeError: global_error_handler() missing 1 required positional argument: 'error'
WARNING:aiogram.dispatcher:Received SIGINT signal
INFO:aiogram.dispatcher:Polling stopped for bot @mariam_chat_bot id=7628846836 - 'mariam_chat_bot'
INFO:aiogram.dispatcher:Polling stopped
INFO:aiogram.dispatcher:Start polling
INFO:aiogram.dispatcher:Run polling for bot @mariam_chat_bot id=7628846836 - 'mariam_chat_bot'
INFO:aiogram.event:Update id=607674303 is not handled. Duration 3 ms by bot id=7628846836
ERROR:aiogram.event:Cause exception while process update id=607674303 by bot id=7628846836
TypeError: global_error_handler() missing 1 required positional argument: 'error'
Traceback (most recent call last):
  File "/Users/hubievkasym/Desktop/Python Projects/IT_round/.venv/lib/python3.12/site-packages/sqlalchemy/orm/clsregistry.py", line 516, in _resolve_name
    rval = d[token]
           ~^^^^^^^
  File "/Users/hubievkasym/Desktop/Python Projects/IT_round/.venv/lib/python3.12/site-packages/sqlalchemy/util/_collections.py", line 345, in __missing__
    self[key] = val = self.creator(key)
                      ^^^^^^^^^^^^^^^^^
  File "/Users/hubievkasym/Desktop/Python Projects/IT_round/.venv/lib/python3.12/site-packages/sqlalchemy/orm/clsregistry.py", line 484, in _access_cls
    return self.fallback[key]
           ~~~~~~~~~~~~~^^^^^
KeyError: 'AccountTable'

The above exception was the direct cause of the following exception:

Traceback (most recent call last):
  File "/Users/hubievkasym/Desktop/Python Projects/IT_round/.venv/lib/python3.12/site-packages/aiogram/dispatcher/middlewares/error.py", line 25, in __call__
    return await handler(event, data)
           ^^^^^^^^^^^^^^^^^^^^^^^^^^
  File "/Users/hubievkasym/Desktop/Python Projects/IT_round/.venv/lib/python3.12/site-packages/aiogram/dispatcher/middlewares/user_context.py", line 56, in __call__
    return await handler(event, data)
           ^^^^^^^^^^^^^^^^^^^^^^^^^^
  File "/Users/hubievkasym/Desktop/Python Projects/IT_round/.venv/lib/python3.12/site-packages/aiogram/fsm/middleware.py", line 42, in __call__
    return await handler(event, data)
           ^^^^^^^^^^^^^^^^^^^^^^^^^^
  File "/Users/hubievkasym/Desktop/Python Projects/IT_round/.venv/lib/python3.12/site-packages/aiogram/dispatcher/event/telegram.py", line 121, in trigger
    return await wrapped_inner(event, kwargs)
           ^^^^^^^^^^^^^^^^^^^^^^^^^^^^^^^^^^
  File "/Users/hubievkasym/Desktop/Python Projects/IT_round/.venv/lib/python3.12/site-packages/aiogram/dispatcher/event/handler.py", line 43, in call
    return await wrapped()
           ^^^^^^^^^^^^^^^
  File "/Users/hubievkasym/Desktop/Python Projects/IT_round/.venv/lib/python3.12/site-packages/aiogram/dispatcher/dispatcher.py", line 276, in _listen_update
    return await self.propagate_event(update_type=update_type, event=event, **kwargs)
           ^^^^^^^^^^^^^^^^^^^^^^^^^^^^^^^^^^^^^^^^^^^^^^^^^^^^^^^^^^^^^^^^^^^^^^^^^^
  File "/Users/hubievkasym/Desktop/Python Projects/IT_round/.venv/lib/python3.12/site-packages/aiogram/dispatcher/router.py", line 146, in propagate_event
    return await observer.wrap_outer_middleware(_wrapped, event=event, data=kwargs)
           ^^^^^^^^^^^^^^^^^^^^^^^^^^^^^^^^^^^^^^^^^^^^^^^^^^^^^^^^^^^^^^^^^^^^^^^^
  File "/Users/hubievkasym/Desktop/Python Projects/IT_round/.venv/lib/python3.12/site-packages/aiogram/dispatcher/router.py", line 141, in _wrapped
    return await self._propagate_event(
           ^^^^^^^^^^^^^^^^^^^^^^^^^^^^
  File "/Users/hubievkasym/Desktop/Python Projects/IT_round/.venv/lib/python3.12/site-packages/aiogram/dispatcher/router.py", line 166, in _propagate_event
    response = await observer.trigger(event, **kwargs)
               ^^^^^^^^^^^^^^^^^^^^^^^^^^^^^^^^^^^^^^^
  File "/Users/hubievkasym/Desktop/Python Projects/IT_round/.venv/lib/python3.12/site-packages/aiogram/dispatcher/event/telegram.py", line 121, in trigger
    return await wrapped_inner(event, kwargs)
           ^^^^^^^^^^^^^^^^^^^^^^^^^^^^^^^^^^
  File "/Users/hubievkasym/Desktop/Python Projects/IT_round/.venv/lib/python3.12/site-packages/aiogram/dispatcher/event/handler.py", line 43, in call
    return await wrapped()
           ^^^^^^^^^^^^^^^
  File "/Users/hubievkasym/Desktop/Python Projects/IT_round/app/telebot.py", line 74, in wrapper
    if not database.account_exists(user_id=str(message.chat.id)):
           ^^^^^^^^^^^^^^^^^^^^^^^^^^^^^^^^^^^^^^^^^^^^^^^^^^^^^
  File "/Users/hubievkasym/Desktop/Python Projects/IT_round/app/database/sql.py", line 18, in wrapper
    result = func(session=session, *args, **kwargs)
             ^^^^^^^^^^^^^^^^^^^^^^^^^^^^^^^^^^^^^^
  File "/Users/hubievkasym/Desktop/Python Projects/IT_round/app/database/sql.py", line 84, in account_exists
    session.query(AccountData)
  File "/Users/hubievkasym/Desktop/Python Projects/IT_round/.venv/lib/python3.12/site-packages/sqlalchemy/orm/session.py", line 2955, in query
    return self._query_cls(entities, self, **kwargs)
           ^^^^^^^^^^^^^^^^^^^^^^^^^^^^^^^^^^^^^^^^^
  File "/Users/hubievkasym/Desktop/Python Projects/IT_round/.venv/lib/python3.12/site-packages/sqlalchemy/orm/query.py", line 276, in __init__
    self._set_entities(entities)
  File "/Users/hubievkasym/Desktop/Python Projects/IT_round/.venv/lib/python3.12/site-packages/sqlalchemy/orm/query.py", line 289, in _set_entities
    coercions.expect(
  File "/Users/hubievkasym/Desktop/Python Projects/IT_round/.venv/lib/python3.12/site-packages/sqlalchemy/sql/coercions.py", line 388, in expect
    insp._post_inspect
  File "/Users/hubievkasym/Desktop/Python Projects/IT_round/.venv/lib/python3.12/site-packages/sqlalchemy/util/langhelpers.py", line 1338, in __get__
    obj.__dict__[self.__name__] = result = self.fget(obj)
                                           ^^^^^^^^^^^^^^
  File "/Users/hubievkasym/Desktop/Python Projects/IT_round/.venv/lib/python3.12/site-packages/sqlalchemy/orm/mapper.py", line 2724, in _post_inspect
    self._check_configure()
  File "/Users/hubievkasym/Desktop/Python Projects/IT_round/.venv/lib/python3.12/site-packages/sqlalchemy/orm/mapper.py", line 2401, in _check_configure
    _configure_registries({self.registry}, cascade=True)
  File "/Users/hubievkasym/Desktop/Python Projects/IT_round/.venv/lib/python3.12/site-packages/sqlalchemy/orm/mapper.py", line 4214, in _configure_registries
    _do_configure_registries(registries, cascade)
  File "/Users/hubievkasym/Desktop/Python Projects/IT_round/.venv/lib/python3.12/site-packages/sqlalchemy/orm/mapper.py", line 4255, in _do_configure_registries
    mapper._post_configure_properties()
  File "/Users/hubievkasym/Desktop/Python Projects/IT_round/.venv/lib/python3.12/site-packages/sqlalchemy/orm/mapper.py", line 2418, in _post_configure_properties
    prop.init()
  File "/Users/hubievkasym/Desktop/Python Projects/IT_round/.venv/lib/python3.12/site-packages/sqlalchemy/orm/interfaces.py", line 589, in init
    self.do_init()
  File "/Users/hubievkasym/Desktop/Python Projects/IT_round/.venv/lib/python3.12/site-packages/sqlalchemy/orm/relationships.py", line 1656, in do_init
    self._setup_entity()
  File "/Users/hubievkasym/Desktop/Python Projects/IT_round/.venv/lib/python3.12/site-packages/sqlalchemy/orm/relationships.py", line 1866, in _setup_entity
    self._clsregistry_resolve_name(argument)(),
    ^^^^^^^^^^^^^^^^^^^^^^^^^^^^^^^^^^^^^^^^^^
  File "/Users/hubievkasym/Desktop/Python Projects/IT_round/.venv/lib/python3.12/site-packages/sqlalchemy/orm/clsregistry.py", line 520, in _resolve_name
    self._raise_for_name(name, err)
  File "/Users/hubievkasym/Desktop/Python Projects/IT_round/.venv/lib/python3.12/site-packages/sqlalchemy/orm/clsregistry.py", line 501, in _raise_for_name
    raise exc.InvalidRequestError(
sqlalchemy.exc.InvalidRequestError: When initializing mapper Mapper[Event(event)], expression 'AccountTable' failed to locate a name ('AccountTable'). If this is a class name, consider adding this relationship() to the <class 'app.database.base.Event'> class after both dependent classes have been defined.

During handling of the above exception, another exception occurred:

Traceback (most recent call last):
  File "/Users/hubievkasym/Desktop/Python Projects/IT_round/.venv/lib/python3.12/site-packages/aiogram/dispatcher/dispatcher.py", line 309, in _process_update
    response = await self.feed_update(bot, update, **kwargs)
               ^^^^^^^^^^^^^^^^^^^^^^^^^^^^^^^^^^^^^^^^^^^^^
  File "/Users/hubievkasym/Desktop/Python Projects/IT_round/.venv/lib/python3.12/site-packages/aiogram/dispatcher/dispatcher.py", line 158, in feed_update
    response = await self.update.wrap_outer_middleware(
               ^^^^^^^^^^^^^^^^^^^^^^^^^^^^^^^^^^^^^^^^
  File "/Users/hubievkasym/Desktop/Python Projects/IT_round/.venv/lib/python3.12/site-packages/aiogram/dispatcher/middlewares/error.py", line 29, in __call__
    response = await self.router.propagate_event(
               ^^^^^^^^^^^^^^^^^^^^^^^^^^^^^^^^^^
  File "/Users/hubievkasym/Desktop/Python Projects/IT_round/.venv/lib/python3.12/site-packages/aiogram/dispatcher/router.py", line 146, in propagate_event
    return await observer.wrap_outer_middleware(_wrapped, event=event, data=kwargs)
           ^^^^^^^^^^^^^^^^^^^^^^^^^^^^^^^^^^^^^^^^^^^^^^^^^^^^^^^^^^^^^^^^^^^^^^^^
  File "/Users/hubievkasym/Desktop/Python Projects/IT_round/.venv/lib/python3.12/site-packages/aiogram/dispatcher/router.py", line 141, in _wrapped
    return await self._propagate_event(
           ^^^^^^^^^^^^^^^^^^^^^^^^^^^^
  File "/Users/hubievkasym/Desktop/Python Projects/IT_round/.venv/lib/python3.12/site-packages/aiogram/dispatcher/router.py", line 166, in _propagate_event
    response = await observer.trigger(event, **kwargs)
               ^^^^^^^^^^^^^^^^^^^^^^^^^^^^^^^^^^^^^^^
  File "/Users/hubievkasym/Desktop/Python Projects/IT_round/.venv/lib/python3.12/site-packages/aiogram/dispatcher/event/telegram.py", line 121, in trigger
    return await wrapped_inner(event, kwargs)
           ^^^^^^^^^^^^^^^^^^^^^^^^^^^^^^^^^^
  File "/Users/hubievkasym/Desktop/Python Projects/IT_round/.venv/lib/python3.12/site-packages/aiogram/dispatcher/event/handler.py", line 43, in call
    return await wrapped()
                 ^^^^^^^^^
TypeError: global_error_handler() missing 1 required positional argument: 'error'
WARNING:aiogram.dispatcher:Received SIGINT signal
INFO:aiogram.dispatcher:Polling stopped for bot @mariam_chat_bot id=7628846836 - 'mariam_chat_bot'
INFO:aiogram.dispatcher:Polling stopped
INFO:aiogram.dispatcher:Start polling
INFO:aiogram.dispatcher:Run polling for bot @mariam_chat_bot id=7628846836 - 'mariam_chat_bot'
INFO:aiogram.event:Update id=607674304 is not handled. Duration 5 ms by bot id=7628846836
ERROR:aiogram.event:Cause exception while process update id=607674304 by bot id=7628846836
TypeError: global_error_handler() missing 1 required positional argument: 'error'
Traceback (most recent call last):
  File "/Users/hubievkasym/Desktop/Python Projects/IT_round/.venv/lib/python3.12/site-packages/aiogram/dispatcher/middlewares/error.py", line 25, in __call__
    return await handler(event, data)
           ^^^^^^^^^^^^^^^^^^^^^^^^^^
  File "/Users/hubievkasym/Desktop/Python Projects/IT_round/.venv/lib/python3.12/site-packages/aiogram/dispatcher/middlewares/user_context.py", line 56, in __call__
    return await handler(event, data)
           ^^^^^^^^^^^^^^^^^^^^^^^^^^
  File "/Users/hubievkasym/Desktop/Python Projects/IT_round/.venv/lib/python3.12/site-packages/aiogram/fsm/middleware.py", line 42, in __call__
    return await handler(event, data)
           ^^^^^^^^^^^^^^^^^^^^^^^^^^
  File "/Users/hubievkasym/Desktop/Python Projects/IT_round/.venv/lib/python3.12/site-packages/aiogram/dispatcher/event/telegram.py", line 121, in trigger
    return await wrapped_inner(event, kwargs)
           ^^^^^^^^^^^^^^^^^^^^^^^^^^^^^^^^^^
  File "/Users/hubievkasym/Desktop/Python Projects/IT_round/.venv/lib/python3.12/site-packages/aiogram/dispatcher/event/handler.py", line 43, in call
    return await wrapped()
           ^^^^^^^^^^^^^^^
  File "/Users/hubievkasym/Desktop/Python Projects/IT_round/.venv/lib/python3.12/site-packages/aiogram/dispatcher/dispatcher.py", line 276, in _listen_update
    return await self.propagate_event(update_type=update_type, event=event, **kwargs)
           ^^^^^^^^^^^^^^^^^^^^^^^^^^^^^^^^^^^^^^^^^^^^^^^^^^^^^^^^^^^^^^^^^^^^^^^^^^
  File "/Users/hubievkasym/Desktop/Python Projects/IT_round/.venv/lib/python3.12/site-packages/aiogram/dispatcher/router.py", line 146, in propagate_event
    return await observer.wrap_outer_middleware(_wrapped, event=event, data=kwargs)
           ^^^^^^^^^^^^^^^^^^^^^^^^^^^^^^^^^^^^^^^^^^^^^^^^^^^^^^^^^^^^^^^^^^^^^^^^
  File "/Users/hubievkasym/Desktop/Python Projects/IT_round/.venv/lib/python3.12/site-packages/aiogram/dispatcher/router.py", line 141, in _wrapped
    return await self._propagate_event(
           ^^^^^^^^^^^^^^^^^^^^^^^^^^^^
  File "/Users/hubievkasym/Desktop/Python Projects/IT_round/.venv/lib/python3.12/site-packages/aiogram/dispatcher/router.py", line 166, in _propagate_event
    response = await observer.trigger(event, **kwargs)
               ^^^^^^^^^^^^^^^^^^^^^^^^^^^^^^^^^^^^^^^
  File "/Users/hubievkasym/Desktop/Python Projects/IT_round/.venv/lib/python3.12/site-packages/aiogram/dispatcher/event/telegram.py", line 121, in trigger
    return await wrapped_inner(event, kwargs)
           ^^^^^^^^^^^^^^^^^^^^^^^^^^^^^^^^^^
  File "/Users/hubievkasym/Desktop/Python Projects/IT_round/.venv/lib/python3.12/site-packages/aiogram/dispatcher/event/handler.py", line 43, in call
    return await wrapped()
           ^^^^^^^^^^^^^^^
  File "/Users/hubievkasym/Desktop/Python Projects/IT_round/app/telebot.py", line 74, in wrapper
    if not database.account_exists(user_id=str(message.chat.id)):
           ^^^^^^^^^^^^^^^^^^^^^^^^^^^^^^^^^^^^^^^^^^^^^^^^^^^^^
  File "/Users/hubievkasym/Desktop/Python Projects/IT_round/app/database/sql.py", line 18, in wrapper
    result = func(session=session, *args, **kwargs)
             ^^^^^^^^^^^^^^^^^^^^^^^^^^^^^^^^^^^^^^
  File "/Users/hubievkasym/Desktop/Python Projects/IT_round/app/database/sql.py", line 84, in account_exists
    session.query(AccountData)
  File "/Users/hubievkasym/Desktop/Python Projects/IT_round/.venv/lib/python3.12/site-packages/sqlalchemy/orm/session.py", line 2955, in query
    return self._query_cls(entities, self, **kwargs)
           ^^^^^^^^^^^^^^^^^^^^^^^^^^^^^^^^^^^^^^^^^
  File "/Users/hubievkasym/Desktop/Python Projects/IT_round/.venv/lib/python3.12/site-packages/sqlalchemy/orm/query.py", line 276, in __init__
    self._set_entities(entities)
  File "/Users/hubievkasym/Desktop/Python Projects/IT_round/.venv/lib/python3.12/site-packages/sqlalchemy/orm/query.py", line 289, in _set_entities
    coercions.expect(
  File "/Users/hubievkasym/Desktop/Python Projects/IT_round/.venv/lib/python3.12/site-packages/sqlalchemy/sql/coercions.py", line 388, in expect
    insp._post_inspect
  File "/Users/hubievkasym/Desktop/Python Projects/IT_round/.venv/lib/python3.12/site-packages/sqlalchemy/util/langhelpers.py", line 1338, in __get__
    obj.__dict__[self.__name__] = result = self.fget(obj)
                                           ^^^^^^^^^^^^^^
  File "/Users/hubievkasym/Desktop/Python Projects/IT_round/.venv/lib/python3.12/site-packages/sqlalchemy/orm/mapper.py", line 2724, in _post_inspect
    self._check_configure()
  File "/Users/hubievkasym/Desktop/Python Projects/IT_round/.venv/lib/python3.12/site-packages/sqlalchemy/orm/mapper.py", line 2401, in _check_configure
    _configure_registries({self.registry}, cascade=True)
  File "/Users/hubievkasym/Desktop/Python Projects/IT_round/.venv/lib/python3.12/site-packages/sqlalchemy/orm/mapper.py", line 4214, in _configure_registries
    _do_configure_registries(registries, cascade)
  File "/Users/hubievkasym/Desktop/Python Projects/IT_round/.venv/lib/python3.12/site-packages/sqlalchemy/orm/mapper.py", line 4255, in _do_configure_registries
    mapper._post_configure_properties()
  File "/Users/hubievkasym/Desktop/Python Projects/IT_round/.venv/lib/python3.12/site-packages/sqlalchemy/orm/mapper.py", line 2418, in _post_configure_properties
    prop.init()
  File "/Users/hubievkasym/Desktop/Python Projects/IT_round/.venv/lib/python3.12/site-packages/sqlalchemy/orm/interfaces.py", line 589, in init
    self.do_init()
  File "/Users/hubievkasym/Desktop/Python Projects/IT_round/.venv/lib/python3.12/site-packages/sqlalchemy/orm/relationships.py", line 1656, in do_init
    self._setup_entity()
  File "/Users/hubievkasym/Desktop/Python Projects/IT_round/.venv/lib/python3.12/site-packages/sqlalchemy/orm/relationships.py", line 1886, in _setup_entity
    raise sa_exc.ArgumentError(
sqlalchemy.exc.ArgumentError: relationship 'user' expects a class or a mapper argument (received: <class 'sqlalchemy.sql.schema.Table'>)

During handling of the above exception, another exception occurred:

Traceback (most recent call last):
  File "/Users/hubievkasym/Desktop/Python Projects/IT_round/.venv/lib/python3.12/site-packages/aiogram/dispatcher/dispatcher.py", line 309, in _process_update
    response = await self.feed_update(bot, update, **kwargs)
               ^^^^^^^^^^^^^^^^^^^^^^^^^^^^^^^^^^^^^^^^^^^^^
  File "/Users/hubievkasym/Desktop/Python Projects/IT_round/.venv/lib/python3.12/site-packages/aiogram/dispatcher/dispatcher.py", line 158, in feed_update
    response = await self.update.wrap_outer_middleware(
               ^^^^^^^^^^^^^^^^^^^^^^^^^^^^^^^^^^^^^^^^
  File "/Users/hubievkasym/Desktop/Python Projects/IT_round/.venv/lib/python3.12/site-packages/aiogram/dispatcher/middlewares/error.py", line 29, in __call__
    response = await self.router.propagate_event(
               ^^^^^^^^^^^^^^^^^^^^^^^^^^^^^^^^^^
  File "/Users/hubievkasym/Desktop/Python Projects/IT_round/.venv/lib/python3.12/site-packages/aiogram/dispatcher/router.py", line 146, in propagate_event
    return await observer.wrap_outer_middleware(_wrapped, event=event, data=kwargs)
           ^^^^^^^^^^^^^^^^^^^^^^^^^^^^^^^^^^^^^^^^^^^^^^^^^^^^^^^^^^^^^^^^^^^^^^^^
  File "/Users/hubievkasym/Desktop/Python Projects/IT_round/.venv/lib/python3.12/site-packages/aiogram/dispatcher/router.py", line 141, in _wrapped
    return await self._propagate_event(
           ^^^^^^^^^^^^^^^^^^^^^^^^^^^^
  File "/Users/hubievkasym/Desktop/Python Projects/IT_round/.venv/lib/python3.12/site-packages/aiogram/dispatcher/router.py", line 166, in _propagate_event
    response = await observer.trigger(event, **kwargs)
               ^^^^^^^^^^^^^^^^^^^^^^^^^^^^^^^^^^^^^^^
  File "/Users/hubievkasym/Desktop/Python Projects/IT_round/.venv/lib/python3.12/site-packages/aiogram/dispatcher/event/telegram.py", line 121, in trigger
    return await wrapped_inner(event, kwargs)
           ^^^^^^^^^^^^^^^^^^^^^^^^^^^^^^^^^^
  File "/Users/hubievkasym/Desktop/Python Projects/IT_round/.venv/lib/python3.12/site-packages/aiogram/dispatcher/event/handler.py", line 43, in call
    return await wrapped()
                 ^^^^^^^^^
TypeError: global_error_handler() missing 1 required positional argument: 'error'
WARNING:aiogram.dispatcher:Received SIGINT signal
INFO:aiogram.dispatcher:Polling stopped for bot @mariam_chat_bot id=7628846836 - 'mariam_chat_bot'
INFO:aiogram.dispatcher:Polling stopped
INFO:aiogram.dispatcher:Start polling
INFO:aiogram.dispatcher:Run polling for bot @mariam_chat_bot id=7628846836 - 'mariam_chat_bot'
INFO:aiogram.event:Update id=607674305 is not handled. Duration 25 ms by bot id=7628846836
ERROR:aiogram.event:Cause exception while process update id=607674305 by bot id=7628846836
TypeError: global_error_handler() missing 1 required positional argument: 'error'
Traceback (most recent call last):
  File "/Users/hubievkasym/Desktop/Python Projects/IT_round/.venv/lib/python3.12/site-packages/aiogram/dispatcher/middlewares/error.py", line 25, in __call__
    return await handler(event, data)
           ^^^^^^^^^^^^^^^^^^^^^^^^^^
  File "/Users/hubievkasym/Desktop/Python Projects/IT_round/.venv/lib/python3.12/site-packages/aiogram/dispatcher/middlewares/user_context.py", line 56, in __call__
    return await handler(event, data)
           ^^^^^^^^^^^^^^^^^^^^^^^^^^
  File "/Users/hubievkasym/Desktop/Python Projects/IT_round/.venv/lib/python3.12/site-packages/aiogram/fsm/middleware.py", line 42, in __call__
    return await handler(event, data)
           ^^^^^^^^^^^^^^^^^^^^^^^^^^
  File "/Users/hubievkasym/Desktop/Python Projects/IT_round/.venv/lib/python3.12/site-packages/aiogram/dispatcher/event/telegram.py", line 121, in trigger
    return await wrapped_inner(event, kwargs)
           ^^^^^^^^^^^^^^^^^^^^^^^^^^^^^^^^^^
  File "/Users/hubievkasym/Desktop/Python Projects/IT_round/.venv/lib/python3.12/site-packages/aiogram/dispatcher/event/handler.py", line 43, in call
    return await wrapped()
           ^^^^^^^^^^^^^^^
  File "/Users/hubievkasym/Desktop/Python Projects/IT_round/.venv/lib/python3.12/site-packages/aiogram/dispatcher/dispatcher.py", line 276, in _listen_update
    return await self.propagate_event(update_type=update_type, event=event, **kwargs)
           ^^^^^^^^^^^^^^^^^^^^^^^^^^^^^^^^^^^^^^^^^^^^^^^^^^^^^^^^^^^^^^^^^^^^^^^^^^
  File "/Users/hubievkasym/Desktop/Python Projects/IT_round/.venv/lib/python3.12/site-packages/aiogram/dispatcher/router.py", line 146, in propagate_event
    return await observer.wrap_outer_middleware(_wrapped, event=event, data=kwargs)
           ^^^^^^^^^^^^^^^^^^^^^^^^^^^^^^^^^^^^^^^^^^^^^^^^^^^^^^^^^^^^^^^^^^^^^^^^
  File "/Users/hubievkasym/Desktop/Python Projects/IT_round/.venv/lib/python3.12/site-packages/aiogram/dispatcher/router.py", line 141, in _wrapped
    return await self._propagate_event(
           ^^^^^^^^^^^^^^^^^^^^^^^^^^^^
  File "/Users/hubievkasym/Desktop/Python Projects/IT_round/.venv/lib/python3.12/site-packages/aiogram/dispatcher/router.py", line 166, in _propagate_event
    response = await observer.trigger(event, **kwargs)
               ^^^^^^^^^^^^^^^^^^^^^^^^^^^^^^^^^^^^^^^
  File "/Users/hubievkasym/Desktop/Python Projects/IT_round/.venv/lib/python3.12/site-packages/aiogram/dispatcher/event/telegram.py", line 121, in trigger
    return await wrapped_inner(event, kwargs)
           ^^^^^^^^^^^^^^^^^^^^^^^^^^^^^^^^^^
  File "/Users/hubievkasym/Desktop/Python Projects/IT_round/.venv/lib/python3.12/site-packages/aiogram/dispatcher/event/handler.py", line 43, in call
    return await wrapped()
           ^^^^^^^^^^^^^^^
  File "/Users/hubievkasym/Desktop/Python Projects/IT_round/app/telebot.py", line 75, in wrapper
    database.add_account(str(user_id=message.chat.id))
                         ^^^^^^^^^^^^^^^^^^^^^^^^^^^^
TypeError: 'user_id' is an invalid keyword argument for str()

During handling of the above exception, another exception occurred:

Traceback (most recent call last):
  File "/Users/hubievkasym/Desktop/Python Projects/IT_round/.venv/lib/python3.12/site-packages/aiogram/dispatcher/dispatcher.py", line 309, in _process_update
    response = await self.feed_update(bot, update, **kwargs)
               ^^^^^^^^^^^^^^^^^^^^^^^^^^^^^^^^^^^^^^^^^^^^^
  File "/Users/hubievkasym/Desktop/Python Projects/IT_round/.venv/lib/python3.12/site-packages/aiogram/dispatcher/dispatcher.py", line 158, in feed_update
    response = await self.update.wrap_outer_middleware(
               ^^^^^^^^^^^^^^^^^^^^^^^^^^^^^^^^^^^^^^^^
  File "/Users/hubievkasym/Desktop/Python Projects/IT_round/.venv/lib/python3.12/site-packages/aiogram/dispatcher/middlewares/error.py", line 29, in __call__
    response = await self.router.propagate_event(
               ^^^^^^^^^^^^^^^^^^^^^^^^^^^^^^^^^^
  File "/Users/hubievkasym/Desktop/Python Projects/IT_round/.venv/lib/python3.12/site-packages/aiogram/dispatcher/router.py", line 146, in propagate_event
    return await observer.wrap_outer_middleware(_wrapped, event=event, data=kwargs)
           ^^^^^^^^^^^^^^^^^^^^^^^^^^^^^^^^^^^^^^^^^^^^^^^^^^^^^^^^^^^^^^^^^^^^^^^^
  File "/Users/hubievkasym/Desktop/Python Projects/IT_round/.venv/lib/python3.12/site-packages/aiogram/dispatcher/router.py", line 141, in _wrapped
    return await self._propagate_event(
           ^^^^^^^^^^^^^^^^^^^^^^^^^^^^
  File "/Users/hubievkasym/Desktop/Python Projects/IT_round/.venv/lib/python3.12/site-packages/aiogram/dispatcher/router.py", line 166, in _propagate_event
    response = await observer.trigger(event, **kwargs)
               ^^^^^^^^^^^^^^^^^^^^^^^^^^^^^^^^^^^^^^^
  File "/Users/hubievkasym/Desktop/Python Projects/IT_round/.venv/lib/python3.12/site-packages/aiogram/dispatcher/event/telegram.py", line 121, in trigger
    return await wrapped_inner(event, kwargs)
           ^^^^^^^^^^^^^^^^^^^^^^^^^^^^^^^^^^
  File "/Users/hubievkasym/Desktop/Python Projects/IT_round/.venv/lib/python3.12/site-packages/aiogram/dispatcher/event/handler.py", line 43, in call
    return await wrapped()
                 ^^^^^^^^^
TypeError: global_error_handler() missing 1 required positional argument: 'error'
INFO:aiogram.event:Update id=607674306 is not handled. Duration 37 ms by bot id=7628846836
ERROR:aiogram.event:Cause exception while process update id=607674306 by bot id=7628846836
TypeError: global_error_handler() missing 1 required positional argument: 'error'
Traceback (most recent call last):
  File "/Users/hubievkasym/Desktop/Python Projects/IT_round/.venv/lib/python3.12/site-packages/aiogram/dispatcher/middlewares/error.py", line 25, in __call__
    return await handler(event, data)
           ^^^^^^^^^^^^^^^^^^^^^^^^^^
  File "/Users/hubievkasym/Desktop/Python Projects/IT_round/.venv/lib/python3.12/site-packages/aiogram/dispatcher/middlewares/user_context.py", line 56, in __call__
    return await handler(event, data)
           ^^^^^^^^^^^^^^^^^^^^^^^^^^
  File "/Users/hubievkasym/Desktop/Python Projects/IT_round/.venv/lib/python3.12/site-packages/aiogram/fsm/middleware.py", line 42, in __call__
    return await handler(event, data)
           ^^^^^^^^^^^^^^^^^^^^^^^^^^
  File "/Users/hubievkasym/Desktop/Python Projects/IT_round/.venv/lib/python3.12/site-packages/aiogram/dispatcher/event/telegram.py", line 121, in trigger
    return await wrapped_inner(event, kwargs)
           ^^^^^^^^^^^^^^^^^^^^^^^^^^^^^^^^^^
  File "/Users/hubievkasym/Desktop/Python Projects/IT_round/.venv/lib/python3.12/site-packages/aiogram/dispatcher/event/handler.py", line 43, in call
    return await wrapped()
           ^^^^^^^^^^^^^^^
  File "/Users/hubievkasym/Desktop/Python Projects/IT_round/.venv/lib/python3.12/site-packages/aiogram/dispatcher/dispatcher.py", line 276, in _listen_update
    return await self.propagate_event(update_type=update_type, event=event, **kwargs)
           ^^^^^^^^^^^^^^^^^^^^^^^^^^^^^^^^^^^^^^^^^^^^^^^^^^^^^^^^^^^^^^^^^^^^^^^^^^
  File "/Users/hubievkasym/Desktop/Python Projects/IT_round/.venv/lib/python3.12/site-packages/aiogram/dispatcher/router.py", line 146, in propagate_event
    return await observer.wrap_outer_middleware(_wrapped, event=event, data=kwargs)
           ^^^^^^^^^^^^^^^^^^^^^^^^^^^^^^^^^^^^^^^^^^^^^^^^^^^^^^^^^^^^^^^^^^^^^^^^
  File "/Users/hubievkasym/Desktop/Python Projects/IT_round/.venv/lib/python3.12/site-packages/aiogram/dispatcher/router.py", line 141, in _wrapped
    return await self._propagate_event(
           ^^^^^^^^^^^^^^^^^^^^^^^^^^^^
  File "/Users/hubievkasym/Desktop/Python Projects/IT_round/.venv/lib/python3.12/site-packages/aiogram/dispatcher/router.py", line 166, in _propagate_event
    response = await observer.trigger(event, **kwargs)
               ^^^^^^^^^^^^^^^^^^^^^^^^^^^^^^^^^^^^^^^
  File "/Users/hubievkasym/Desktop/Python Projects/IT_round/.venv/lib/python3.12/site-packages/aiogram/dispatcher/event/telegram.py", line 121, in trigger
    return await wrapped_inner(event, kwargs)
           ^^^^^^^^^^^^^^^^^^^^^^^^^^^^^^^^^^
  File "/Users/hubievkasym/Desktop/Python Projects/IT_round/.venv/lib/python3.12/site-packages/aiogram/dispatcher/event/handler.py", line 43, in call
    return await wrapped()
           ^^^^^^^^^^^^^^^
  File "/Users/hubievkasym/Desktop/Python Projects/IT_round/app/telebot.py", line 75, in wrapper
    database.add_account(str(user_id=message.chat.id))
                         ^^^^^^^^^^^^^^^^^^^^^^^^^^^^
TypeError: 'user_id' is an invalid keyword argument for str()

During handling of the above exception, another exception occurred:

Traceback (most recent call last):
  File "/Users/hubievkasym/Desktop/Python Projects/IT_round/.venv/lib/python3.12/site-packages/aiogram/dispatcher/dispatcher.py", line 309, in _process_update
    response = await self.feed_update(bot, update, **kwargs)
               ^^^^^^^^^^^^^^^^^^^^^^^^^^^^^^^^^^^^^^^^^^^^^
  File "/Users/hubievkasym/Desktop/Python Projects/IT_round/.venv/lib/python3.12/site-packages/aiogram/dispatcher/dispatcher.py", line 158, in feed_update
    response = await self.update.wrap_outer_middleware(
               ^^^^^^^^^^^^^^^^^^^^^^^^^^^^^^^^^^^^^^^^
  File "/Users/hubievkasym/Desktop/Python Projects/IT_round/.venv/lib/python3.12/site-packages/aiogram/dispatcher/middlewares/error.py", line 29, in __call__
    response = await self.router.propagate_event(
               ^^^^^^^^^^^^^^^^^^^^^^^^^^^^^^^^^^
  File "/Users/hubievkasym/Desktop/Python Projects/IT_round/.venv/lib/python3.12/site-packages/aiogram/dispatcher/router.py", line 146, in propagate_event
    return await observer.wrap_outer_middleware(_wrapped, event=event, data=kwargs)
           ^^^^^^^^^^^^^^^^^^^^^^^^^^^^^^^^^^^^^^^^^^^^^^^^^^^^^^^^^^^^^^^^^^^^^^^^
  File "/Users/hubievkasym/Desktop/Python Projects/IT_round/.venv/lib/python3.12/site-packages/aiogram/dispatcher/router.py", line 141, in _wrapped
    return await self._propagate_event(
           ^^^^^^^^^^^^^^^^^^^^^^^^^^^^
  File "/Users/hubievkasym/Desktop/Python Projects/IT_round/.venv/lib/python3.12/site-packages/aiogram/dispatcher/router.py", line 166, in _propagate_event
    response = await observer.trigger(event, **kwargs)
               ^^^^^^^^^^^^^^^^^^^^^^^^^^^^^^^^^^^^^^^
  File "/Users/hubievkasym/Desktop/Python Projects/IT_round/.venv/lib/python3.12/site-packages/aiogram/dispatcher/event/telegram.py", line 121, in trigger
    return await wrapped_inner(event, kwargs)
           ^^^^^^^^^^^^^^^^^^^^^^^^^^^^^^^^^^
  File "/Users/hubievkasym/Desktop/Python Projects/IT_round/.venv/lib/python3.12/site-packages/aiogram/dispatcher/event/handler.py", line 43, in call
    return await wrapped()
                 ^^^^^^^^^
TypeError: global_error_handler() missing 1 required positional argument: 'error'
INFO:aiogram.event:Update id=607674307 is not handled. Duration 1 ms by bot id=7628846836
ERROR:aiogram.event:Cause exception while process update id=607674307 by bot id=7628846836
TypeError: global_error_handler() missing 1 required positional argument: 'error'
Traceback (most recent call last):
  File "/Users/hubievkasym/Desktop/Python Projects/IT_round/.venv/lib/python3.12/site-packages/aiogram/dispatcher/middlewares/error.py", line 25, in __call__
    return await handler(event, data)
           ^^^^^^^^^^^^^^^^^^^^^^^^^^
  File "/Users/hubievkasym/Desktop/Python Projects/IT_round/.venv/lib/python3.12/site-packages/aiogram/dispatcher/middlewares/user_context.py", line 56, in __call__
    return await handler(event, data)
           ^^^^^^^^^^^^^^^^^^^^^^^^^^
  File "/Users/hubievkasym/Desktop/Python Projects/IT_round/.venv/lib/python3.12/site-packages/aiogram/fsm/middleware.py", line 42, in __call__
    return await handler(event, data)
           ^^^^^^^^^^^^^^^^^^^^^^^^^^
  File "/Users/hubievkasym/Desktop/Python Projects/IT_round/.venv/lib/python3.12/site-packages/aiogram/dispatcher/event/telegram.py", line 121, in trigger
    return await wrapped_inner(event, kwargs)
           ^^^^^^^^^^^^^^^^^^^^^^^^^^^^^^^^^^
  File "/Users/hubievkasym/Desktop/Python Projects/IT_round/.venv/lib/python3.12/site-packages/aiogram/dispatcher/event/handler.py", line 43, in call
    return await wrapped()
           ^^^^^^^^^^^^^^^
  File "/Users/hubievkasym/Desktop/Python Projects/IT_round/.venv/lib/python3.12/site-packages/aiogram/dispatcher/dispatcher.py", line 276, in _listen_update
    return await self.propagate_event(update_type=update_type, event=event, **kwargs)
           ^^^^^^^^^^^^^^^^^^^^^^^^^^^^^^^^^^^^^^^^^^^^^^^^^^^^^^^^^^^^^^^^^^^^^^^^^^
  File "/Users/hubievkasym/Desktop/Python Projects/IT_round/.venv/lib/python3.12/site-packages/aiogram/dispatcher/router.py", line 146, in propagate_event
    return await observer.wrap_outer_middleware(_wrapped, event=event, data=kwargs)
           ^^^^^^^^^^^^^^^^^^^^^^^^^^^^^^^^^^^^^^^^^^^^^^^^^^^^^^^^^^^^^^^^^^^^^^^^
  File "/Users/hubievkasym/Desktop/Python Projects/IT_round/.venv/lib/python3.12/site-packages/aiogram/dispatcher/router.py", line 141, in _wrapped
    return await self._propagate_event(
           ^^^^^^^^^^^^^^^^^^^^^^^^^^^^
  File "/Users/hubievkasym/Desktop/Python Projects/IT_round/.venv/lib/python3.12/site-packages/aiogram/dispatcher/router.py", line 166, in _propagate_event
    response = await observer.trigger(event, **kwargs)
               ^^^^^^^^^^^^^^^^^^^^^^^^^^^^^^^^^^^^^^^
  File "/Users/hubievkasym/Desktop/Python Projects/IT_round/.venv/lib/python3.12/site-packages/aiogram/dispatcher/event/telegram.py", line 121, in trigger
    return await wrapped_inner(event, kwargs)
           ^^^^^^^^^^^^^^^^^^^^^^^^^^^^^^^^^^
  File "/Users/hubievkasym/Desktop/Python Projects/IT_round/.venv/lib/python3.12/site-packages/aiogram/dispatcher/event/handler.py", line 43, in call
    return await wrapped()
           ^^^^^^^^^^^^^^^
  File "/Users/hubievkasym/Desktop/Python Projects/IT_round/app/telebot.py", line 75, in wrapper
    database.add_account(str(user_id=message.chat.id))
                         ^^^^^^^^^^^^^^^^^^^^^^^^^^^^
TypeError: 'user_id' is an invalid keyword argument for str()

During handling of the above exception, another exception occurred:

Traceback (most recent call last):
  File "/Users/hubievkasym/Desktop/Python Projects/IT_round/.venv/lib/python3.12/site-packages/aiogram/dispatcher/dispatcher.py", line 309, in _process_update
    response = await self.feed_update(bot, update, **kwargs)
               ^^^^^^^^^^^^^^^^^^^^^^^^^^^^^^^^^^^^^^^^^^^^^
  File "/Users/hubievkasym/Desktop/Python Projects/IT_round/.venv/lib/python3.12/site-packages/aiogram/dispatcher/dispatcher.py", line 158, in feed_update
    response = await self.update.wrap_outer_middleware(
               ^^^^^^^^^^^^^^^^^^^^^^^^^^^^^^^^^^^^^^^^
  File "/Users/hubievkasym/Desktop/Python Projects/IT_round/.venv/lib/python3.12/site-packages/aiogram/dispatcher/middlewares/error.py", line 29, in __call__
    response = await self.router.propagate_event(
               ^^^^^^^^^^^^^^^^^^^^^^^^^^^^^^^^^^
  File "/Users/hubievkasym/Desktop/Python Projects/IT_round/.venv/lib/python3.12/site-packages/aiogram/dispatcher/router.py", line 146, in propagate_event
    return await observer.wrap_outer_middleware(_wrapped, event=event, data=kwargs)
           ^^^^^^^^^^^^^^^^^^^^^^^^^^^^^^^^^^^^^^^^^^^^^^^^^^^^^^^^^^^^^^^^^^^^^^^^
  File "/Users/hubievkasym/Desktop/Python Projects/IT_round/.venv/lib/python3.12/site-packages/aiogram/dispatcher/router.py", line 141, in _wrapped
    return await self._propagate_event(
           ^^^^^^^^^^^^^^^^^^^^^^^^^^^^
  File "/Users/hubievkasym/Desktop/Python Projects/IT_round/.venv/lib/python3.12/site-packages/aiogram/dispatcher/router.py", line 166, in _propagate_event
    response = await observer.trigger(event, **kwargs)
               ^^^^^^^^^^^^^^^^^^^^^^^^^^^^^^^^^^^^^^^
  File "/Users/hubievkasym/Desktop/Python Projects/IT_round/.venv/lib/python3.12/site-packages/aiogram/dispatcher/event/telegram.py", line 121, in trigger
    return await wrapped_inner(event, kwargs)
           ^^^^^^^^^^^^^^^^^^^^^^^^^^^^^^^^^^
  File "/Users/hubievkasym/Desktop/Python Projects/IT_round/.venv/lib/python3.12/site-packages/aiogram/dispatcher/event/handler.py", line 43, in call
    return await wrapped()
                 ^^^^^^^^^
TypeError: global_error_handler() missing 1 required positional argument: 'error'
WARNING:aiogram.dispatcher:Received SIGINT signal
INFO:aiogram.dispatcher:Polling stopped for bot @mariam_chat_bot id=7628846836 - 'mariam_chat_bot'
INFO:aiogram.dispatcher:Polling stopped
INFO:aiogram.dispatcher:Start polling
INFO:aiogram.dispatcher:Run polling for bot @mariam_chat_bot id=7628846836 - 'mariam_chat_bot'
INFO:aiogram.event:Update id=607674308 is not handled. Duration 24 ms by bot id=7628846836
ERROR:aiogram.event:Cause exception while process update id=607674308 by bot id=7628846836
TypeError: global_error_handler() missing 1 required positional argument: 'error'
Traceback (most recent call last):
  File "/Users/hubievkasym/Desktop/Python Projects/IT_round/.venv/lib/python3.12/site-packages/aiogram/dispatcher/middlewares/error.py", line 25, in __call__
    return await handler(event, data)
           ^^^^^^^^^^^^^^^^^^^^^^^^^^
  File "/Users/hubievkasym/Desktop/Python Projects/IT_round/.venv/lib/python3.12/site-packages/aiogram/dispatcher/middlewares/user_context.py", line 56, in __call__
    return await handler(event, data)
           ^^^^^^^^^^^^^^^^^^^^^^^^^^
  File "/Users/hubievkasym/Desktop/Python Projects/IT_round/.venv/lib/python3.12/site-packages/aiogram/fsm/middleware.py", line 42, in __call__
    return await handler(event, data)
           ^^^^^^^^^^^^^^^^^^^^^^^^^^
  File "/Users/hubievkasym/Desktop/Python Projects/IT_round/.venv/lib/python3.12/site-packages/aiogram/dispatcher/event/telegram.py", line 121, in trigger
    return await wrapped_inner(event, kwargs)
           ^^^^^^^^^^^^^^^^^^^^^^^^^^^^^^^^^^
  File "/Users/hubievkasym/Desktop/Python Projects/IT_round/.venv/lib/python3.12/site-packages/aiogram/dispatcher/event/handler.py", line 43, in call
    return await wrapped()
           ^^^^^^^^^^^^^^^
  File "/Users/hubievkasym/Desktop/Python Projects/IT_round/.venv/lib/python3.12/site-packages/aiogram/dispatcher/dispatcher.py", line 276, in _listen_update
    return await self.propagate_event(update_type=update_type, event=event, **kwargs)
           ^^^^^^^^^^^^^^^^^^^^^^^^^^^^^^^^^^^^^^^^^^^^^^^^^^^^^^^^^^^^^^^^^^^^^^^^^^
  File "/Users/hubievkasym/Desktop/Python Projects/IT_round/.venv/lib/python3.12/site-packages/aiogram/dispatcher/router.py", line 146, in propagate_event
    return await observer.wrap_outer_middleware(_wrapped, event=event, data=kwargs)
           ^^^^^^^^^^^^^^^^^^^^^^^^^^^^^^^^^^^^^^^^^^^^^^^^^^^^^^^^^^^^^^^^^^^^^^^^
  File "/Users/hubievkasym/Desktop/Python Projects/IT_round/.venv/lib/python3.12/site-packages/aiogram/dispatcher/router.py", line 141, in _wrapped
    return await self._propagate_event(
           ^^^^^^^^^^^^^^^^^^^^^^^^^^^^
  File "/Users/hubievkasym/Desktop/Python Projects/IT_round/.venv/lib/python3.12/site-packages/aiogram/dispatcher/router.py", line 166, in _propagate_event
    response = await observer.trigger(event, **kwargs)
               ^^^^^^^^^^^^^^^^^^^^^^^^^^^^^^^^^^^^^^^
  File "/Users/hubievkasym/Desktop/Python Projects/IT_round/.venv/lib/python3.12/site-packages/aiogram/dispatcher/event/telegram.py", line 121, in trigger
    return await wrapped_inner(event, kwargs)
           ^^^^^^^^^^^^^^^^^^^^^^^^^^^^^^^^^^
  File "/Users/hubievkasym/Desktop/Python Projects/IT_round/.venv/lib/python3.12/site-packages/aiogram/dispatcher/event/handler.py", line 43, in call
    return await wrapped()
           ^^^^^^^^^^^^^^^
  File "/Users/hubievkasym/Desktop/Python Projects/IT_round/app/telebot.py", line 75, in wrapper
    database.add_account(str(user_id=message.chat.id))
                         ^^^^^^^^^^^^^^^^^^^^^^^^^^^^
TypeError: 'user_id' is an invalid keyword argument for str()

During handling of the above exception, another exception occurred:

Traceback (most recent call last):
  File "/Users/hubievkasym/Desktop/Python Projects/IT_round/.venv/lib/python3.12/site-packages/aiogram/dispatcher/dispatcher.py", line 309, in _process_update
    response = await self.feed_update(bot, update, **kwargs)
               ^^^^^^^^^^^^^^^^^^^^^^^^^^^^^^^^^^^^^^^^^^^^^
  File "/Users/hubievkasym/Desktop/Python Projects/IT_round/.venv/lib/python3.12/site-packages/aiogram/dispatcher/dispatcher.py", line 158, in feed_update
    response = await self.update.wrap_outer_middleware(
               ^^^^^^^^^^^^^^^^^^^^^^^^^^^^^^^^^^^^^^^^
  File "/Users/hubievkasym/Desktop/Python Projects/IT_round/.venv/lib/python3.12/site-packages/aiogram/dispatcher/middlewares/error.py", line 29, in __call__
    response = await self.router.propagate_event(
               ^^^^^^^^^^^^^^^^^^^^^^^^^^^^^^^^^^
  File "/Users/hubievkasym/Desktop/Python Projects/IT_round/.venv/lib/python3.12/site-packages/aiogram/dispatcher/router.py", line 146, in propagate_event
    return await observer.wrap_outer_middleware(_wrapped, event=event, data=kwargs)
           ^^^^^^^^^^^^^^^^^^^^^^^^^^^^^^^^^^^^^^^^^^^^^^^^^^^^^^^^^^^^^^^^^^^^^^^^
  File "/Users/hubievkasym/Desktop/Python Projects/IT_round/.venv/lib/python3.12/site-packages/aiogram/dispatcher/router.py", line 141, in _wrapped
    return await self._propagate_event(
           ^^^^^^^^^^^^^^^^^^^^^^^^^^^^
  File "/Users/hubievkasym/Desktop/Python Projects/IT_round/.venv/lib/python3.12/site-packages/aiogram/dispatcher/router.py", line 166, in _propagate_event
    response = await observer.trigger(event, **kwargs)
               ^^^^^^^^^^^^^^^^^^^^^^^^^^^^^^^^^^^^^^^
  File "/Users/hubievkasym/Desktop/Python Projects/IT_round/.venv/lib/python3.12/site-packages/aiogram/dispatcher/event/telegram.py", line 121, in trigger
    return await wrapped_inner(event, kwargs)
           ^^^^^^^^^^^^^^^^^^^^^^^^^^^^^^^^^^
  File "/Users/hubievkasym/Desktop/Python Projects/IT_round/.venv/lib/python3.12/site-packages/aiogram/dispatcher/event/handler.py", line 43, in call
    return await wrapped()
                 ^^^^^^^^^
TypeError: global_error_handler() missing 1 required positional argument: 'error'
WARNING:aiogram.dispatcher:Received SIGINT signal
INFO:aiogram.dispatcher:Polling stopped for bot @mariam_chat_bot id=7628846836 - 'mariam_chat_bot'
INFO:aiogram.dispatcher:Polling stopped
INFO:aiogram.dispatcher:Start polling
INFO:aiogram.dispatcher:Run polling for bot @mariam_chat_bot id=7628846836 - 'mariam_chat_bot'
INFO:aiogram.event:Update id=607674309 is not handled. Duration 45 ms by bot id=7628846836
ERROR:aiogram.event:Cause exception while process update id=607674309 by bot id=7628846836
TypeError: global_error_handler() missing 1 required positional argument: 'error'
Traceback (most recent call last):
  File "/Users/hubievkasym/Desktop/Python Projects/IT_round/.venv/lib/python3.12/site-packages/sqlalchemy/engine/base.py", line 1963, in _exec_single_context
    self.dialect.do_execute(
  File "/Users/hubievkasym/Desktop/Python Projects/IT_round/.venv/lib/python3.12/site-packages/sqlalchemy/engine/default.py", line 943, in do_execute
    cursor.execute(statement, parameters)
sqlite3.IntegrityError: NOT NULL constraint failed: account.first_name

The above exception was the direct cause of the following exception:

Traceback (most recent call last):
  File "/Users/hubievkasym/Desktop/Python Projects/IT_round/.venv/lib/python3.12/site-packages/aiogram/dispatcher/middlewares/error.py", line 25, in __call__
    return await handler(event, data)
           ^^^^^^^^^^^^^^^^^^^^^^^^^^
  File "/Users/hubievkasym/Desktop/Python Projects/IT_round/.venv/lib/python3.12/site-packages/aiogram/dispatcher/middlewares/user_context.py", line 56, in __call__
    return await handler(event, data)
           ^^^^^^^^^^^^^^^^^^^^^^^^^^
  File "/Users/hubievkasym/Desktop/Python Projects/IT_round/.venv/lib/python3.12/site-packages/aiogram/fsm/middleware.py", line 42, in __call__
    return await handler(event, data)
           ^^^^^^^^^^^^^^^^^^^^^^^^^^
  File "/Users/hubievkasym/Desktop/Python Projects/IT_round/.venv/lib/python3.12/site-packages/aiogram/dispatcher/event/telegram.py", line 121, in trigger
    return await wrapped_inner(event, kwargs)
           ^^^^^^^^^^^^^^^^^^^^^^^^^^^^^^^^^^
  File "/Users/hubievkasym/Desktop/Python Projects/IT_round/.venv/lib/python3.12/site-packages/aiogram/dispatcher/event/handler.py", line 43, in call
    return await wrapped()
           ^^^^^^^^^^^^^^^
  File "/Users/hubievkasym/Desktop/Python Projects/IT_round/.venv/lib/python3.12/site-packages/aiogram/dispatcher/dispatcher.py", line 276, in _listen_update
    return await self.propagate_event(update_type=update_type, event=event, **kwargs)
           ^^^^^^^^^^^^^^^^^^^^^^^^^^^^^^^^^^^^^^^^^^^^^^^^^^^^^^^^^^^^^^^^^^^^^^^^^^
  File "/Users/hubievkasym/Desktop/Python Projects/IT_round/.venv/lib/python3.12/site-packages/aiogram/dispatcher/router.py", line 146, in propagate_event
    return await observer.wrap_outer_middleware(_wrapped, event=event, data=kwargs)
           ^^^^^^^^^^^^^^^^^^^^^^^^^^^^^^^^^^^^^^^^^^^^^^^^^^^^^^^^^^^^^^^^^^^^^^^^
  File "/Users/hubievkasym/Desktop/Python Projects/IT_round/.venv/lib/python3.12/site-packages/aiogram/dispatcher/router.py", line 141, in _wrapped
    return await self._propagate_event(
           ^^^^^^^^^^^^^^^^^^^^^^^^^^^^
  File "/Users/hubievkasym/Desktop/Python Projects/IT_round/.venv/lib/python3.12/site-packages/aiogram/dispatcher/router.py", line 166, in _propagate_event
    response = await observer.trigger(event, **kwargs)
               ^^^^^^^^^^^^^^^^^^^^^^^^^^^^^^^^^^^^^^^
  File "/Users/hubievkasym/Desktop/Python Projects/IT_round/.venv/lib/python3.12/site-packages/aiogram/dispatcher/event/telegram.py", line 121, in trigger
    return await wrapped_inner(event, kwargs)
           ^^^^^^^^^^^^^^^^^^^^^^^^^^^^^^^^^^
  File "/Users/hubievkasym/Desktop/Python Projects/IT_round/.venv/lib/python3.12/site-packages/aiogram/dispatcher/event/handler.py", line 43, in call
    return await wrapped()
           ^^^^^^^^^^^^^^^
  File "/Users/hubievkasym/Desktop/Python Projects/IT_round/app/telebot.py", line 75, in wrapper
    database.add_account(user_id=str(message.chat.id))
  File "/Users/hubievkasym/Desktop/Python Projects/IT_round/app/database/sql.py", line 25, in wrapper
    raise e
  File "/Users/hubievkasym/Desktop/Python Projects/IT_round/app/database/sql.py", line 19, in wrapper
    session.commit()
  File "/Users/hubievkasym/Desktop/Python Projects/IT_round/.venv/lib/python3.12/site-packages/sqlalchemy/orm/session.py", line 2032, in commit
    trans.commit(_to_root=True)
  File "<string>", line 2, in commit
  File "/Users/hubievkasym/Desktop/Python Projects/IT_round/.venv/lib/python3.12/site-packages/sqlalchemy/orm/state_changes.py", line 139, in _go
    ret_value = fn(self, *arg, **kw)
                ^^^^^^^^^^^^^^^^^^^^
  File "/Users/hubievkasym/Desktop/Python Projects/IT_round/.venv/lib/python3.12/site-packages/sqlalchemy/orm/session.py", line 1313, in commit
    self._prepare_impl()
  File "<string>", line 2, in _prepare_impl
  File "/Users/hubievkasym/Desktop/Python Projects/IT_round/.venv/lib/python3.12/site-packages/sqlalchemy/orm/state_changes.py", line 139, in _go
    ret_value = fn(self, *arg, **kw)
                ^^^^^^^^^^^^^^^^^^^^
  File "/Users/hubievkasym/Desktop/Python Projects/IT_round/.venv/lib/python3.12/site-packages/sqlalchemy/orm/session.py", line 1288, in _prepare_impl
    self.session.flush()
  File "/Users/hubievkasym/Desktop/Python Projects/IT_round/.venv/lib/python3.12/site-packages/sqlalchemy/orm/session.py", line 4345, in flush
    self._flush(objects)
  File "/Users/hubievkasym/Desktop/Python Projects/IT_round/.venv/lib/python3.12/site-packages/sqlalchemy/orm/session.py", line 4480, in _flush
    with util.safe_reraise():
         ^^^^^^^^^^^^^^^^^^^
  File "/Users/hubievkasym/Desktop/Python Projects/IT_round/.venv/lib/python3.12/site-packages/sqlalchemy/util/langhelpers.py", line 224, in __exit__
    raise exc_value.with_traceback(exc_tb)
  File "/Users/hubievkasym/Desktop/Python Projects/IT_round/.venv/lib/python3.12/site-packages/sqlalchemy/orm/session.py", line 4441, in _flush
    flush_context.execute()
  File "/Users/hubievkasym/Desktop/Python Projects/IT_round/.venv/lib/python3.12/site-packages/sqlalchemy/orm/unitofwork.py", line 466, in execute
    rec.execute(self)
  File "/Users/hubievkasym/Desktop/Python Projects/IT_round/.venv/lib/python3.12/site-packages/sqlalchemy/orm/unitofwork.py", line 642, in execute
    util.preloaded.orm_persistence.save_obj(
  File "/Users/hubievkasym/Desktop/Python Projects/IT_round/.venv/lib/python3.12/site-packages/sqlalchemy/orm/persistence.py", line 93, in save_obj
    _emit_insert_statements(
  File "/Users/hubievkasym/Desktop/Python Projects/IT_round/.venv/lib/python3.12/site-packages/sqlalchemy/orm/persistence.py", line 1233, in _emit_insert_statements
    result = connection.execute(
             ^^^^^^^^^^^^^^^^^^^
  File "/Users/hubievkasym/Desktop/Python Projects/IT_round/.venv/lib/python3.12/site-packages/sqlalchemy/engine/base.py", line 1415, in execute
    return meth(
           ^^^^^
  File "/Users/hubievkasym/Desktop/Python Projects/IT_round/.venv/lib/python3.12/site-packages/sqlalchemy/sql/elements.py", line 523, in _execute_on_connection
    return connection._execute_clauseelement(
           ^^^^^^^^^^^^^^^^^^^^^^^^^^^^^^^^^^
  File "/Users/hubievkasym/Desktop/Python Projects/IT_round/.venv/lib/python3.12/site-packages/sqlalchemy/engine/base.py", line 1637, in _execute_clauseelement
    ret = self._execute_context(
          ^^^^^^^^^^^^^^^^^^^^^^
  File "/Users/hubievkasym/Desktop/Python Projects/IT_round/.venv/lib/python3.12/site-packages/sqlalchemy/engine/base.py", line 1842, in _execute_context
    return self._exec_single_context(
           ^^^^^^^^^^^^^^^^^^^^^^^^^^
  File "/Users/hubievkasym/Desktop/Python Projects/IT_round/.venv/lib/python3.12/site-packages/sqlalchemy/engine/base.py", line 1982, in _exec_single_context
    self._handle_dbapi_exception(
  File "/Users/hubievkasym/Desktop/Python Projects/IT_round/.venv/lib/python3.12/site-packages/sqlalchemy/engine/base.py", line 2351, in _handle_dbapi_exception
    raise sqlalchemy_exception.with_traceback(exc_info[2]) from e
  File "/Users/hubievkasym/Desktop/Python Projects/IT_round/.venv/lib/python3.12/site-packages/sqlalchemy/engine/base.py", line 1963, in _exec_single_context
    self.dialect.do_execute(
  File "/Users/hubievkasym/Desktop/Python Projects/IT_round/.venv/lib/python3.12/site-packages/sqlalchemy/engine/default.py", line 943, in do_execute
    cursor.execute(statement, parameters)
sqlalchemy.exc.IntegrityError: (sqlite3.IntegrityError) NOT NULL constraint failed: account.first_name
[SQL: INSERT INTO account (chat_id) VALUES (?)]
[parameters: ('1038292559',)]
(Background on this error at: https://sqlalche.me/e/20/gkpj)

During handling of the above exception, another exception occurred:

Traceback (most recent call last):
  File "/Users/hubievkasym/Desktop/Python Projects/IT_round/.venv/lib/python3.12/site-packages/aiogram/dispatcher/dispatcher.py", line 309, in _process_update
    response = await self.feed_update(bot, update, **kwargs)
               ^^^^^^^^^^^^^^^^^^^^^^^^^^^^^^^^^^^^^^^^^^^^^
  File "/Users/hubievkasym/Desktop/Python Projects/IT_round/.venv/lib/python3.12/site-packages/aiogram/dispatcher/dispatcher.py", line 158, in feed_update
    response = await self.update.wrap_outer_middleware(
               ^^^^^^^^^^^^^^^^^^^^^^^^^^^^^^^^^^^^^^^^
  File "/Users/hubievkasym/Desktop/Python Projects/IT_round/.venv/lib/python3.12/site-packages/aiogram/dispatcher/middlewares/error.py", line 29, in __call__
    response = await self.router.propagate_event(
               ^^^^^^^^^^^^^^^^^^^^^^^^^^^^^^^^^^
  File "/Users/hubievkasym/Desktop/Python Projects/IT_round/.venv/lib/python3.12/site-packages/aiogram/dispatcher/router.py", line 146, in propagate_event
    return await observer.wrap_outer_middleware(_wrapped, event=event, data=kwargs)
           ^^^^^^^^^^^^^^^^^^^^^^^^^^^^^^^^^^^^^^^^^^^^^^^^^^^^^^^^^^^^^^^^^^^^^^^^
  File "/Users/hubievkasym/Desktop/Python Projects/IT_round/.venv/lib/python3.12/site-packages/aiogram/dispatcher/router.py", line 141, in _wrapped
    return await self._propagate_event(
           ^^^^^^^^^^^^^^^^^^^^^^^^^^^^
  File "/Users/hubievkasym/Desktop/Python Projects/IT_round/.venv/lib/python3.12/site-packages/aiogram/dispatcher/router.py", line 166, in _propagate_event
    response = await observer.trigger(event, **kwargs)
               ^^^^^^^^^^^^^^^^^^^^^^^^^^^^^^^^^^^^^^^
  File "/Users/hubievkasym/Desktop/Python Projects/IT_round/.venv/lib/python3.12/site-packages/aiogram/dispatcher/event/telegram.py", line 121, in trigger
    return await wrapped_inner(event, kwargs)
           ^^^^^^^^^^^^^^^^^^^^^^^^^^^^^^^^^^
  File "/Users/hubievkasym/Desktop/Python Projects/IT_round/.venv/lib/python3.12/site-packages/aiogram/dispatcher/event/handler.py", line 43, in call
    return await wrapped()
                 ^^^^^^^^^
TypeError: global_error_handler() missing 1 required positional argument: 'error'
WARNING:aiogram.dispatcher:Received SIGINT signal
INFO:aiogram.dispatcher:Polling stopped for bot @mariam_chat_bot id=7628846836 - 'mariam_chat_bot'
INFO:aiogram.dispatcher:Polling stopped
INFO:aiogram.dispatcher:Start polling
INFO:aiogram.dispatcher:Run polling for bot @mariam_chat_bot id=7628846836 - 'mariam_chat_bot'
INFO:aiogram.event:Update id=607674310 is handled. Duration 24 ms by bot id=7628846836
INFO:aiogram.event:Update id=607674311 is handled. Duration 17 ms by bot id=7628846836
INFO:aiogram.event:Update id=607674312 is handled. Duration 5 ms by bot id=7628846836
WARNING:aiogram.dispatcher:Received SIGINT signal
INFO:aiogram.dispatcher:Polling stopped for bot @mariam_chat_bot id=7628846836 - 'mariam_chat_bot'
INFO:aiogram.dispatcher:Polling stopped
INFO:aiogram.dispatcher:Start polling
INFO:aiogram.dispatcher:Run polling for bot @mariam_chat_bot id=7628846836 - 'mariam_chat_bot'
INFO:aiogram.event:Update id=607674313 is handled. Duration 28 ms by bot id=7628846836
WARNING:aiogram.dispatcher:Received SIGINT signal
INFO:aiogram.dispatcher:Polling stopped for bot @mariam_chat_bot id=7628846836 - 'mariam_chat_bot'
INFO:aiogram.dispatcher:Polling stopped
INFO:aiogram.dispatcher:Start polling
INFO:aiogram.dispatcher:Run polling for bot @mariam_chat_bot id=7628846836 - 'mariam_chat_bot'
INFO:aiogram.event:Update id=607674314 is handled. Duration 292 ms by bot id=7628846836
WARNING:aiogram.dispatcher:Received SIGINT signal
INFO:aiogram.dispatcher:Polling stopped for bot @mariam_chat_bot id=7628846836 - 'mariam_chat_bot'
INFO:aiogram.dispatcher:Polling stopped
INFO:aiogram.dispatcher:Start polling
INFO:aiogram.dispatcher:Run polling for bot @mariam_chat_bot id=7628846836 - 'mariam_chat_bot'
INFO:aiogram.event:Update id=607674315 is handled. Duration 36 ms by bot id=7628846836
INFO:aiogram.event:Update id=607674316 is handled. Duration 7 ms by bot id=7628846836
INFO:aiogram.event:Update id=607674317 is handled. Duration 1 ms by bot id=7628846836
INFO:aiogram.event:Update id=607674318 is not handled. Duration 0 ms by bot id=7628846836
INFO:aiogram.event:Update id=607674319 is handled. Duration 2 ms by bot id=7628846836
WARNING:aiogram.dispatcher:Received SIGINT signal
INFO:aiogram.dispatcher:Polling stopped for bot @mariam_chat_bot id=7628846836 - 'mariam_chat_bot'
INFO:aiogram.dispatcher:Polling stopped
INFO:aiogram.dispatcher:Start polling
INFO:aiogram.dispatcher:Run polling for bot @mariam_chat_bot id=7628846836 - 'mariam_chat_bot'
INFO:aiogram.event:Update id=607674320 is handled. Duration 397 ms by bot id=7628846836
INFO:aiogram.event:Update id=607674321 is handled. Duration 100 ms by bot id=7628846836
INFO:aiogram.event:Update id=607674322 is handled. Duration 125 ms by bot id=7628846836
INFO:aiogram.event:Update id=607674323 is not handled. Duration 2 ms by bot id=7628846836
ERROR:aiogram.event:Cause exception while process update id=607674323 by bot id=7628846836
TypeError: global_error_handler() missing 1 required positional argument: 'error'
Traceback (most recent call last):
  File "/Users/hubievkasym/Desktop/Python Projects/IT_round/.venv/lib/python3.12/site-packages/aiogram/dispatcher/middlewares/error.py", line 25, in __call__
    return await handler(event, data)
           ^^^^^^^^^^^^^^^^^^^^^^^^^^
  File "/Users/hubievkasym/Desktop/Python Projects/IT_round/.venv/lib/python3.12/site-packages/aiogram/dispatcher/middlewares/user_context.py", line 56, in __call__
    return await handler(event, data)
           ^^^^^^^^^^^^^^^^^^^^^^^^^^
  File "/Users/hubievkasym/Desktop/Python Projects/IT_round/.venv/lib/python3.12/site-packages/aiogram/fsm/middleware.py", line 42, in __call__
    return await handler(event, data)
           ^^^^^^^^^^^^^^^^^^^^^^^^^^
  File "/Users/hubievkasym/Desktop/Python Projects/IT_round/.venv/lib/python3.12/site-packages/aiogram/dispatcher/event/telegram.py", line 121, in trigger
    return await wrapped_inner(event, kwargs)
           ^^^^^^^^^^^^^^^^^^^^^^^^^^^^^^^^^^
  File "/Users/hubievkasym/Desktop/Python Projects/IT_round/.venv/lib/python3.12/site-packages/aiogram/dispatcher/event/handler.py", line 43, in call
    return await wrapped()
           ^^^^^^^^^^^^^^^
  File "/Users/hubievkasym/Desktop/Python Projects/IT_round/.venv/lib/python3.12/site-packages/aiogram/dispatcher/dispatcher.py", line 276, in _listen_update
    return await self.propagate_event(update_type=update_type, event=event, **kwargs)
           ^^^^^^^^^^^^^^^^^^^^^^^^^^^^^^^^^^^^^^^^^^^^^^^^^^^^^^^^^^^^^^^^^^^^^^^^^^
  File "/Users/hubievkasym/Desktop/Python Projects/IT_round/.venv/lib/python3.12/site-packages/aiogram/dispatcher/router.py", line 146, in propagate_event
    return await observer.wrap_outer_middleware(_wrapped, event=event, data=kwargs)
           ^^^^^^^^^^^^^^^^^^^^^^^^^^^^^^^^^^^^^^^^^^^^^^^^^^^^^^^^^^^^^^^^^^^^^^^^
  File "/Users/hubievkasym/Desktop/Python Projects/IT_round/.venv/lib/python3.12/site-packages/aiogram/dispatcher/router.py", line 141, in _wrapped
    return await self._propagate_event(
           ^^^^^^^^^^^^^^^^^^^^^^^^^^^^
  File "/Users/hubievkasym/Desktop/Python Projects/IT_round/.venv/lib/python3.12/site-packages/aiogram/dispatcher/router.py", line 166, in _propagate_event
    response = await observer.trigger(event, **kwargs)
               ^^^^^^^^^^^^^^^^^^^^^^^^^^^^^^^^^^^^^^^
  File "/Users/hubievkasym/Desktop/Python Projects/IT_round/.venv/lib/python3.12/site-packages/aiogram/dispatcher/event/telegram.py", line 121, in trigger
    return await wrapped_inner(event, kwargs)
           ^^^^^^^^^^^^^^^^^^^^^^^^^^^^^^^^^^
  File "/Users/hubievkasym/Desktop/Python Projects/IT_round/.venv/lib/python3.12/site-packages/aiogram/dispatcher/event/handler.py", line 43, in call
    return await wrapped()
           ^^^^^^^^^^^^^^^
  File "/Users/hubievkasym/Desktop/Python Projects/IT_round/app/telebot.py", line 103, in show_schedule
    period = message.get_command()[1:]  # Remove leading '/'
             ^^^^^^^^^^^^^^^^^^^
  File "/Users/hubievkasym/Desktop/Python Projects/IT_round/.venv/lib/python3.12/site-packages/pydantic/main.py", line 991, in __getattr__
    raise AttributeError(f'{type(self).__name__!r} object has no attribute {item!r}')
AttributeError: 'Message' object has no attribute 'get_command'

During handling of the above exception, another exception occurred:

Traceback (most recent call last):
  File "/Users/hubievkasym/Desktop/Python Projects/IT_round/.venv/lib/python3.12/site-packages/aiogram/dispatcher/dispatcher.py", line 309, in _process_update
    response = await self.feed_update(bot, update, **kwargs)
               ^^^^^^^^^^^^^^^^^^^^^^^^^^^^^^^^^^^^^^^^^^^^^
  File "/Users/hubievkasym/Desktop/Python Projects/IT_round/.venv/lib/python3.12/site-packages/aiogram/dispatcher/dispatcher.py", line 158, in feed_update
    response = await self.update.wrap_outer_middleware(
               ^^^^^^^^^^^^^^^^^^^^^^^^^^^^^^^^^^^^^^^^
  File "/Users/hubievkasym/Desktop/Python Projects/IT_round/.venv/lib/python3.12/site-packages/aiogram/dispatcher/middlewares/error.py", line 29, in __call__
    response = await self.router.propagate_event(
               ^^^^^^^^^^^^^^^^^^^^^^^^^^^^^^^^^^
  File "/Users/hubievkasym/Desktop/Python Projects/IT_round/.venv/lib/python3.12/site-packages/aiogram/dispatcher/router.py", line 146, in propagate_event
    return await observer.wrap_outer_middleware(_wrapped, event=event, data=kwargs)
           ^^^^^^^^^^^^^^^^^^^^^^^^^^^^^^^^^^^^^^^^^^^^^^^^^^^^^^^^^^^^^^^^^^^^^^^^
  File "/Users/hubievkasym/Desktop/Python Projects/IT_round/.venv/lib/python3.12/site-packages/aiogram/dispatcher/router.py", line 141, in _wrapped
    return await self._propagate_event(
           ^^^^^^^^^^^^^^^^^^^^^^^^^^^^
  File "/Users/hubievkasym/Desktop/Python Projects/IT_round/.venv/lib/python3.12/site-packages/aiogram/dispatcher/router.py", line 166, in _propagate_event
    response = await observer.trigger(event, **kwargs)
               ^^^^^^^^^^^^^^^^^^^^^^^^^^^^^^^^^^^^^^^
  File "/Users/hubievkasym/Desktop/Python Projects/IT_round/.venv/lib/python3.12/site-packages/aiogram/dispatcher/event/telegram.py", line 121, in trigger
    return await wrapped_inner(event, kwargs)
           ^^^^^^^^^^^^^^^^^^^^^^^^^^^^^^^^^^
  File "/Users/hubievkasym/Desktop/Python Projects/IT_round/.venv/lib/python3.12/site-packages/aiogram/dispatcher/event/handler.py", line 43, in call
    return await wrapped()
                 ^^^^^^^^^
TypeError: global_error_handler() missing 1 required positional argument: 'error'
WARNING:aiogram.dispatcher:Received SIGINT signal
INFO:aiogram.dispatcher:Polling stopped for bot @mariam_chat_bot id=7628846836 - 'mariam_chat_bot'
INFO:aiogram.dispatcher:Polling stopped
INFO:aiogram.dispatcher:Start polling
INFO:aiogram.dispatcher:Run polling for bot @mariam_chat_bot id=7628846836 - 'mariam_chat_bot'
INFO:aiogram.event:Update id=607674324 is handled. Duration 289 ms by bot id=7628846836
INFO:aiogram.event:Update id=607674325 is handled. Duration 118 ms by bot id=7628846836
INFO:aiogram.event:Update id=607674326 is handled. Duration 228 ms by bot id=7628846836
WARNING:aiogram.dispatcher:Received SIGINT signal
INFO:aiogram.dispatcher:Polling stopped for bot @mariam_chat_bot id=7628846836 - 'mariam_chat_bot'
INFO:aiogram.dispatcher:Polling stopped
INFO:aiogram.dispatcher:Start polling
INFO:aiogram.dispatcher:Run polling for bot @mariam_chat_bot id=7628846836 - 'mariam_chat_bot'
INFO:aiogram.event:Update id=607674327 is handled. Duration 458 ms by bot id=7628846836
INFO:aiogram.event:Update id=607674328 is handled. Duration 518 ms by bot id=7628846836
WARNING:aiogram.dispatcher:Received SIGINT signal
INFO:aiogram.dispatcher:Polling stopped for bot @mariam_chat_bot id=7628846836 - 'mariam_chat_bot'
INFO:aiogram.dispatcher:Polling stopped
INFO:aiogram.dispatcher:Start polling
INFO:aiogram.dispatcher:Run polling for bot @mariam_chat_bot id=7628846836 - 'mariam_chat_bot'
WARNING:aiogram.dispatcher:Received SIGINT signal
INFO:aiogram.dispatcher:Polling stopped for bot @mariam_chat_bot id=7628846836 - 'mariam_chat_bot'
INFO:aiogram.dispatcher:Polling stopped
INFO:aiogram.dispatcher:Start polling
INFO:aiogram.dispatcher:Run polling for bot @mariam_chat_bot id=7628846836 - 'mariam_chat_bot'
WARNING:aiogram.dispatcher:Received SIGINT signal
INFO:aiogram.dispatcher:Polling stopped for bot @mariam_chat_bot id=7628846836 - 'mariam_chat_bot'
INFO:aiogram.dispatcher:Polling stopped
INFO:aiogram.dispatcher:Start polling
INFO:aiogram.dispatcher:Run polling for bot @mariam_chat_bot id=7628846836 - 'mariam_chat_bot'
INFO:aiogram.event:Update id=607674329 is handled. Duration 294 ms by bot id=7628846836
INFO:aiogram.event:Update id=607674330 is handled. Duration 296 ms by bot id=7628846836
WARNING:aiogram.dispatcher:Received SIGINT signal
INFO:aiogram.dispatcher:Polling stopped for bot @mariam_chat_bot id=7628846836 - 'mariam_chat_bot'
INFO:aiogram.dispatcher:Polling stopped
INFO:aiogram.dispatcher:Start polling
INFO:aiogram.dispatcher:Run polling for bot @mariam_chat_bot id=7628846836 - 'mariam_chat_bot'
INFO:aiogram.event:Update id=607674331 is not handled. Duration 14 ms by bot id=7628846836
ERROR:aiogram.event:Cause exception while process update id=607674331 by bot id=7628846836
TypeError: global_error_handler() missing 1 required positional argument: 'error'
Traceback (most recent call last):
  File "/Users/hubievkasym/Desktop/Python Projects/IT_round/.venv/lib/python3.12/site-packages/aiogram/dispatcher/middlewares/error.py", line 25, in __call__
    return await handler(event, data)
           ^^^^^^^^^^^^^^^^^^^^^^^^^^
  File "/Users/hubievkasym/Desktop/Python Projects/IT_round/.venv/lib/python3.12/site-packages/aiogram/dispatcher/middlewares/user_context.py", line 56, in __call__
    return await handler(event, data)
           ^^^^^^^^^^^^^^^^^^^^^^^^^^
  File "/Users/hubievkasym/Desktop/Python Projects/IT_round/.venv/lib/python3.12/site-packages/aiogram/fsm/middleware.py", line 42, in __call__
    return await handler(event, data)
           ^^^^^^^^^^^^^^^^^^^^^^^^^^
  File "/Users/hubievkasym/Desktop/Python Projects/IT_round/.venv/lib/python3.12/site-packages/aiogram/dispatcher/event/telegram.py", line 121, in trigger
    return await wrapped_inner(event, kwargs)
           ^^^^^^^^^^^^^^^^^^^^^^^^^^^^^^^^^^
  File "/Users/hubievkasym/Desktop/Python Projects/IT_round/.venv/lib/python3.12/site-packages/aiogram/dispatcher/event/handler.py", line 43, in call
    return await wrapped()
           ^^^^^^^^^^^^^^^
  File "/Users/hubievkasym/Desktop/Python Projects/IT_round/.venv/lib/python3.12/site-packages/aiogram/dispatcher/dispatcher.py", line 276, in _listen_update
    return await self.propagate_event(update_type=update_type, event=event, **kwargs)
           ^^^^^^^^^^^^^^^^^^^^^^^^^^^^^^^^^^^^^^^^^^^^^^^^^^^^^^^^^^^^^^^^^^^^^^^^^^
  File "/Users/hubievkasym/Desktop/Python Projects/IT_round/.venv/lib/python3.12/site-packages/aiogram/dispatcher/router.py", line 146, in propagate_event
    return await observer.wrap_outer_middleware(_wrapped, event=event, data=kwargs)
           ^^^^^^^^^^^^^^^^^^^^^^^^^^^^^^^^^^^^^^^^^^^^^^^^^^^^^^^^^^^^^^^^^^^^^^^^
  File "/Users/hubievkasym/Desktop/Python Projects/IT_round/.venv/lib/python3.12/site-packages/aiogram/dispatcher/router.py", line 141, in _wrapped
    return await self._propagate_event(
           ^^^^^^^^^^^^^^^^^^^^^^^^^^^^
  File "/Users/hubievkasym/Desktop/Python Projects/IT_round/.venv/lib/python3.12/site-packages/aiogram/dispatcher/router.py", line 166, in _propagate_event
    response = await observer.trigger(event, **kwargs)
               ^^^^^^^^^^^^^^^^^^^^^^^^^^^^^^^^^^^^^^^
  File "/Users/hubievkasym/Desktop/Python Projects/IT_round/.venv/lib/python3.12/site-packages/aiogram/dispatcher/event/telegram.py", line 121, in trigger
    return await wrapped_inner(event, kwargs)
           ^^^^^^^^^^^^^^^^^^^^^^^^^^^^^^^^^^
  File "/Users/hubievkasym/Desktop/Python Projects/IT_round/.venv/lib/python3.12/site-packages/aiogram/dispatcher/event/handler.py", line 43, in call
    return await wrapped()
           ^^^^^^^^^^^^^^^
  File "/Users/hubievkasym/Desktop/Python Projects/IT_round/app/telebot.py", line 103, in show_schedule
    await message.reply_to_message(schedule)
          ^^^^^^^^^^^^^^^^^^^^^^^^^^^^^^^^^^
TypeError: 'NoneType' object is not callable

During handling of the above exception, another exception occurred:

Traceback (most recent call last):
  File "/Users/hubievkasym/Desktop/Python Projects/IT_round/.venv/lib/python3.12/site-packages/aiogram/dispatcher/dispatcher.py", line 309, in _process_update
    response = await self.feed_update(bot, update, **kwargs)
               ^^^^^^^^^^^^^^^^^^^^^^^^^^^^^^^^^^^^^^^^^^^^^
  File "/Users/hubievkasym/Desktop/Python Projects/IT_round/.venv/lib/python3.12/site-packages/aiogram/dispatcher/dispatcher.py", line 158, in feed_update
    response = await self.update.wrap_outer_middleware(
               ^^^^^^^^^^^^^^^^^^^^^^^^^^^^^^^^^^^^^^^^
  File "/Users/hubievkasym/Desktop/Python Projects/IT_round/.venv/lib/python3.12/site-packages/aiogram/dispatcher/middlewares/error.py", line 29, in __call__
    response = await self.router.propagate_event(
               ^^^^^^^^^^^^^^^^^^^^^^^^^^^^^^^^^^
  File "/Users/hubievkasym/Desktop/Python Projects/IT_round/.venv/lib/python3.12/site-packages/aiogram/dispatcher/router.py", line 146, in propagate_event
    return await observer.wrap_outer_middleware(_wrapped, event=event, data=kwargs)
           ^^^^^^^^^^^^^^^^^^^^^^^^^^^^^^^^^^^^^^^^^^^^^^^^^^^^^^^^^^^^^^^^^^^^^^^^
  File "/Users/hubievkasym/Desktop/Python Projects/IT_round/.venv/lib/python3.12/site-packages/aiogram/dispatcher/router.py", line 141, in _wrapped
    return await self._propagate_event(
           ^^^^^^^^^^^^^^^^^^^^^^^^^^^^
  File "/Users/hubievkasym/Desktop/Python Projects/IT_round/.venv/lib/python3.12/site-packages/aiogram/dispatcher/router.py", line 166, in _propagate_event
    response = await observer.trigger(event, **kwargs)
               ^^^^^^^^^^^^^^^^^^^^^^^^^^^^^^^^^^^^^^^
  File "/Users/hubievkasym/Desktop/Python Projects/IT_round/.venv/lib/python3.12/site-packages/aiogram/dispatcher/event/telegram.py", line 121, in trigger
    return await wrapped_inner(event, kwargs)
           ^^^^^^^^^^^^^^^^^^^^^^^^^^^^^^^^^^
  File "/Users/hubievkasym/Desktop/Python Projects/IT_round/.venv/lib/python3.12/site-packages/aiogram/dispatcher/event/handler.py", line 43, in call
    return await wrapped()
                 ^^^^^^^^^
TypeError: global_error_handler() missing 1 required positional argument: 'error'
INFO:aiogram.event:Update id=607674332 is not handled. Duration 5 ms by bot id=7628846836
ERROR:aiogram.event:Cause exception while process update id=607674332 by bot id=7628846836
TypeError: global_error_handler() missing 1 required positional argument: 'error'
Traceback (most recent call last):
  File "/Users/hubievkasym/Desktop/Python Projects/IT_round/.venv/lib/python3.12/site-packages/aiogram/dispatcher/middlewares/error.py", line 25, in __call__
    return await handler(event, data)
           ^^^^^^^^^^^^^^^^^^^^^^^^^^
  File "/Users/hubievkasym/Desktop/Python Projects/IT_round/.venv/lib/python3.12/site-packages/aiogram/dispatcher/middlewares/user_context.py", line 56, in __call__
    return await handler(event, data)
           ^^^^^^^^^^^^^^^^^^^^^^^^^^
  File "/Users/hubievkasym/Desktop/Python Projects/IT_round/.venv/lib/python3.12/site-packages/aiogram/fsm/middleware.py", line 42, in __call__
    return await handler(event, data)
           ^^^^^^^^^^^^^^^^^^^^^^^^^^
  File "/Users/hubievkasym/Desktop/Python Projects/IT_round/.venv/lib/python3.12/site-packages/aiogram/dispatcher/event/telegram.py", line 121, in trigger
    return await wrapped_inner(event, kwargs)
           ^^^^^^^^^^^^^^^^^^^^^^^^^^^^^^^^^^
  File "/Users/hubievkasym/Desktop/Python Projects/IT_round/.venv/lib/python3.12/site-packages/aiogram/dispatcher/event/handler.py", line 43, in call
    return await wrapped()
           ^^^^^^^^^^^^^^^
  File "/Users/hubievkasym/Desktop/Python Projects/IT_round/.venv/lib/python3.12/site-packages/aiogram/dispatcher/dispatcher.py", line 276, in _listen_update
    return await self.propagate_event(update_type=update_type, event=event, **kwargs)
           ^^^^^^^^^^^^^^^^^^^^^^^^^^^^^^^^^^^^^^^^^^^^^^^^^^^^^^^^^^^^^^^^^^^^^^^^^^
  File "/Users/hubievkasym/Desktop/Python Projects/IT_round/.venv/lib/python3.12/site-packages/aiogram/dispatcher/router.py", line 146, in propagate_event
    return await observer.wrap_outer_middleware(_wrapped, event=event, data=kwargs)
           ^^^^^^^^^^^^^^^^^^^^^^^^^^^^^^^^^^^^^^^^^^^^^^^^^^^^^^^^^^^^^^^^^^^^^^^^
  File "/Users/hubievkasym/Desktop/Python Projects/IT_round/.venv/lib/python3.12/site-packages/aiogram/dispatcher/router.py", line 141, in _wrapped
    return await self._propagate_event(
           ^^^^^^^^^^^^^^^^^^^^^^^^^^^^
  File "/Users/hubievkasym/Desktop/Python Projects/IT_round/.venv/lib/python3.12/site-packages/aiogram/dispatcher/router.py", line 166, in _propagate_event
    response = await observer.trigger(event, **kwargs)
               ^^^^^^^^^^^^^^^^^^^^^^^^^^^^^^^^^^^^^^^
  File "/Users/hubievkasym/Desktop/Python Projects/IT_round/.venv/lib/python3.12/site-packages/aiogram/dispatcher/event/telegram.py", line 121, in trigger
    return await wrapped_inner(event, kwargs)
           ^^^^^^^^^^^^^^^^^^^^^^^^^^^^^^^^^^
  File "/Users/hubievkasym/Desktop/Python Projects/IT_round/.venv/lib/python3.12/site-packages/aiogram/dispatcher/event/handler.py", line 43, in call
    return await wrapped()
           ^^^^^^^^^^^^^^^
  File "/Users/hubievkasym/Desktop/Python Projects/IT_round/app/telebot.py", line 107, in show_schedule
    await message.reply(schedule)
          ^^^^^^^^^^^^^^^^^^^^^^^
  File "/Users/hubievkasym/Desktop/Python Projects/IT_round/.venv/lib/python3.12/site-packages/aiogram/types/message.py", line 2026, in reply
    return SendMessage(
           ^^^^^^^^^^^^
  File "/Users/hubievkasym/Desktop/Python Projects/IT_round/.venv/lib/python3.12/site-packages/pydantic/main.py", line 253, in __init__
    validated_self = self.__pydantic_validator__.validate_python(data, self_instance=self)
                     ^^^^^^^^^^^^^^^^^^^^^^^^^^^^^^^^^^^^^^^^^^^^^^^^^^^^^^^^^^^^^^^^^^^^^
pydantic_core._pydantic_core.ValidationError: 1 validation error for SendMessage
text
  Input should be a valid string [type=string_type, input_value=None, input_type=NoneType]
    For further information visit https://errors.pydantic.dev/2.11/v/string_type

During handling of the above exception, another exception occurred:

Traceback (most recent call last):
  File "/Users/hubievkasym/Desktop/Python Projects/IT_round/.venv/lib/python3.12/site-packages/aiogram/dispatcher/dispatcher.py", line 309, in _process_update
    response = await self.feed_update(bot, update, **kwargs)
               ^^^^^^^^^^^^^^^^^^^^^^^^^^^^^^^^^^^^^^^^^^^^^
  File "/Users/hubievkasym/Desktop/Python Projects/IT_round/.venv/lib/python3.12/site-packages/aiogram/dispatcher/dispatcher.py", line 158, in feed_update
    response = await self.update.wrap_outer_middleware(
               ^^^^^^^^^^^^^^^^^^^^^^^^^^^^^^^^^^^^^^^^
  File "/Users/hubievkasym/Desktop/Python Projects/IT_round/.venv/lib/python3.12/site-packages/aiogram/dispatcher/middlewares/error.py", line 29, in __call__
    response = await self.router.propagate_event(
               ^^^^^^^^^^^^^^^^^^^^^^^^^^^^^^^^^^
  File "/Users/hubievkasym/Desktop/Python Projects/IT_round/.venv/lib/python3.12/site-packages/aiogram/dispatcher/router.py", line 146, in propagate_event
    return await observer.wrap_outer_middleware(_wrapped, event=event, data=kwargs)
           ^^^^^^^^^^^^^^^^^^^^^^^^^^^^^^^^^^^^^^^^^^^^^^^^^^^^^^^^^^^^^^^^^^^^^^^^
  File "/Users/hubievkasym/Desktop/Python Projects/IT_round/.venv/lib/python3.12/site-packages/aiogram/dispatcher/router.py", line 141, in _wrapped
    return await self._propagate_event(
           ^^^^^^^^^^^^^^^^^^^^^^^^^^^^
  File "/Users/hubievkasym/Desktop/Python Projects/IT_round/.venv/lib/python3.12/site-packages/aiogram/dispatcher/router.py", line 166, in _propagate_event
    response = await observer.trigger(event, **kwargs)
               ^^^^^^^^^^^^^^^^^^^^^^^^^^^^^^^^^^^^^^^
  File "/Users/hubievkasym/Desktop/Python Projects/IT_round/.venv/lib/python3.12/site-packages/aiogram/dispatcher/event/telegram.py", line 121, in trigger
    return await wrapped_inner(event, kwargs)
           ^^^^^^^^^^^^^^^^^^^^^^^^^^^^^^^^^^
  File "/Users/hubievkasym/Desktop/Python Projects/IT_round/.venv/lib/python3.12/site-packages/aiogram/dispatcher/event/handler.py", line 43, in call
    return await wrapped()
                 ^^^^^^^^^
TypeError: global_error_handler() missing 1 required positional argument: 'error'
WARNING:aiogram.dispatcher:Received SIGINT signal
INFO:aiogram.dispatcher:Polling stopped for bot @mariam_chat_bot id=7628846836 - 'mariam_chat_bot'
INFO:aiogram.dispatcher:Polling stopped
INFO:aiogram.dispatcher:Start polling
INFO:aiogram.dispatcher:Run polling for bot @mariam_chat_bot id=7628846836 - 'mariam_chat_bot'
INFO:aiogram.event:Update id=607674333 is handled. Duration 285 ms by bot id=7628846836
WARNING:aiogram.dispatcher:Received SIGINT signal
INFO:aiogram.dispatcher:Polling stopped for bot @mariam_chat_bot id=7628846836 - 'mariam_chat_bot'
INFO:aiogram.dispatcher:Polling stopped
INFO:aiogram.dispatcher:Start polling
INFO:aiogram.dispatcher:Run polling for bot @mariam_chat_bot id=7628846836 - 'mariam_chat_bot'
INFO:aiogram.event:Update id=607674334 is handled. Duration 336 ms by bot id=7628846836
INFO:aiogram.event:Update id=607674335 is not handled. Duration 0 ms by bot id=7628846836
WARNING:aiogram.dispatcher:Received SIGINT signal
INFO:aiogram.dispatcher:Polling stopped for bot @mariam_chat_bot id=7628846836 - 'mariam_chat_bot'
INFO:aiogram.dispatcher:Polling stopped
INFO:aiogram.dispatcher:Start polling
INFO:aiogram.dispatcher:Run polling for bot @mariam_chat_bot id=7628846836 - 'mariam_chat_bot'
INFO:aiogram.event:Update id=607674336 is handled. Duration 722 ms by bot id=7628846836
WARNING:aiogram.dispatcher:Received SIGINT signal
INFO:aiogram.dispatcher:Polling stopped for bot @mariam_chat_bot id=7628846836 - 'mariam_chat_bot'
INFO:aiogram.dispatcher:Polling stopped
INFO:aiogram.dispatcher:Start polling
INFO:aiogram.dispatcher:Run polling for bot @mariam_chat_bot id=7628846836 - 'mariam_chat_bot'
INFO:aiogram.event:Update id=607674337 is handled. Duration 479 ms by bot id=7628846836
INFO:aiogram.event:Update id=607674338 is handled. Duration 141 ms by bot id=7628846836
INFO:aiogram.event:Update id=607674339 is not handled. Duration 98 ms by bot id=7628846836
ERROR:aiogram.event:Cause exception while process update id=607674339 by bot id=7628846836
TypeError: global_error_handler() missing 1 required positional argument: 'error'
Traceback (most recent call last):
  File "/Users/hubievkasym/Desktop/Python Projects/IT_round/.venv/lib/python3.12/site-packages/aiogram/dispatcher/middlewares/error.py", line 25, in __call__
    return await handler(event, data)
           ^^^^^^^^^^^^^^^^^^^^^^^^^^
  File "/Users/hubievkasym/Desktop/Python Projects/IT_round/.venv/lib/python3.12/site-packages/aiogram/dispatcher/middlewares/user_context.py", line 56, in __call__
    return await handler(event, data)
           ^^^^^^^^^^^^^^^^^^^^^^^^^^
  File "/Users/hubievkasym/Desktop/Python Projects/IT_round/.venv/lib/python3.12/site-packages/aiogram/fsm/middleware.py", line 42, in __call__
    return await handler(event, data)
           ^^^^^^^^^^^^^^^^^^^^^^^^^^
  File "/Users/hubievkasym/Desktop/Python Projects/IT_round/.venv/lib/python3.12/site-packages/aiogram/dispatcher/event/telegram.py", line 121, in trigger
    return await wrapped_inner(event, kwargs)
           ^^^^^^^^^^^^^^^^^^^^^^^^^^^^^^^^^^
  File "/Users/hubievkasym/Desktop/Python Projects/IT_round/.venv/lib/python3.12/site-packages/aiogram/dispatcher/event/handler.py", line 43, in call
    return await wrapped()
           ^^^^^^^^^^^^^^^
  File "/Users/hubievkasym/Desktop/Python Projects/IT_round/.venv/lib/python3.12/site-packages/aiogram/dispatcher/dispatcher.py", line 276, in _listen_update
    return await self.propagate_event(update_type=update_type, event=event, **kwargs)
           ^^^^^^^^^^^^^^^^^^^^^^^^^^^^^^^^^^^^^^^^^^^^^^^^^^^^^^^^^^^^^^^^^^^^^^^^^^
  File "/Users/hubievkasym/Desktop/Python Projects/IT_round/.venv/lib/python3.12/site-packages/aiogram/dispatcher/router.py", line 146, in propagate_event
    return await observer.wrap_outer_middleware(_wrapped, event=event, data=kwargs)
           ^^^^^^^^^^^^^^^^^^^^^^^^^^^^^^^^^^^^^^^^^^^^^^^^^^^^^^^^^^^^^^^^^^^^^^^^
  File "/Users/hubievkasym/Desktop/Python Projects/IT_round/.venv/lib/python3.12/site-packages/aiogram/dispatcher/router.py", line 141, in _wrapped
    return await self._propagate_event(
           ^^^^^^^^^^^^^^^^^^^^^^^^^^^^
  File "/Users/hubievkasym/Desktop/Python Projects/IT_round/.venv/lib/python3.12/site-packages/aiogram/dispatcher/router.py", line 166, in _propagate_event
    response = await observer.trigger(event, **kwargs)
               ^^^^^^^^^^^^^^^^^^^^^^^^^^^^^^^^^^^^^^^
  File "/Users/hubievkasym/Desktop/Python Projects/IT_round/.venv/lib/python3.12/site-packages/aiogram/dispatcher/event/telegram.py", line 121, in trigger
    return await wrapped_inner(event, kwargs)
           ^^^^^^^^^^^^^^^^^^^^^^^^^^^^^^^^^^
  File "/Users/hubievkasym/Desktop/Python Projects/IT_round/.venv/lib/python3.12/site-packages/aiogram/dispatcher/event/handler.py", line 43, in call
    return await wrapped()
           ^^^^^^^^^^^^^^^
  File "/Users/hubievkasym/Desktop/Python Projects/IT_round/app/telebot.py", line 119, in show_schedule
    await message.reply(response)
  File "/Users/hubievkasym/Desktop/Python Projects/IT_round/.venv/lib/python3.12/site-packages/aiogram/methods/base.py", line 84, in emit
    return await bot(self)
           ^^^^^^^^^^^^^^^
  File "/Users/hubievkasym/Desktop/Python Projects/IT_round/.venv/lib/python3.12/site-packages/aiogram/client/bot.py", line 482, in __call__
    return await self.session(self, method, timeout=request_timeout)
           ^^^^^^^^^^^^^^^^^^^^^^^^^^^^^^^^^^^^^^^^^^^^^^^^^^^^^^^^^
  File "/Users/hubievkasym/Desktop/Python Projects/IT_round/.venv/lib/python3.12/site-packages/aiogram/client/session/base.py", line 254, in __call__
    return cast(TelegramType, await middleware(bot, method))
                              ^^^^^^^^^^^^^^^^^^^^^^^^^^^^^
  File "/Users/hubievkasym/Desktop/Python Projects/IT_round/.venv/lib/python3.12/site-packages/aiogram/client/session/aiohttp.py", line 185, in make_request
    response = self.check_response(
               ^^^^^^^^^^^^^^^^^^^^
  File "/Users/hubievkasym/Desktop/Python Projects/IT_round/.venv/lib/python3.12/site-packages/aiogram/client/session/base.py", line 120, in check_response
    raise TelegramBadRequest(method=method, message=description)
aiogram.exceptions.TelegramBadRequest: Telegram server says - Bad Request: message text is empty

During handling of the above exception, another exception occurred:

Traceback (most recent call last):
  File "/Users/hubievkasym/Desktop/Python Projects/IT_round/.venv/lib/python3.12/site-packages/aiogram/dispatcher/dispatcher.py", line 309, in _process_update
    response = await self.feed_update(bot, update, **kwargs)
               ^^^^^^^^^^^^^^^^^^^^^^^^^^^^^^^^^^^^^^^^^^^^^
  File "/Users/hubievkasym/Desktop/Python Projects/IT_round/.venv/lib/python3.12/site-packages/aiogram/dispatcher/dispatcher.py", line 158, in feed_update
    response = await self.update.wrap_outer_middleware(
               ^^^^^^^^^^^^^^^^^^^^^^^^^^^^^^^^^^^^^^^^
  File "/Users/hubievkasym/Desktop/Python Projects/IT_round/.venv/lib/python3.12/site-packages/aiogram/dispatcher/middlewares/error.py", line 29, in __call__
    response = await self.router.propagate_event(
               ^^^^^^^^^^^^^^^^^^^^^^^^^^^^^^^^^^
  File "/Users/hubievkasym/Desktop/Python Projects/IT_round/.venv/lib/python3.12/site-packages/aiogram/dispatcher/router.py", line 146, in propagate_event
    return await observer.wrap_outer_middleware(_wrapped, event=event, data=kwargs)
           ^^^^^^^^^^^^^^^^^^^^^^^^^^^^^^^^^^^^^^^^^^^^^^^^^^^^^^^^^^^^^^^^^^^^^^^^
  File "/Users/hubievkasym/Desktop/Python Projects/IT_round/.venv/lib/python3.12/site-packages/aiogram/dispatcher/router.py", line 141, in _wrapped
    return await self._propagate_event(
           ^^^^^^^^^^^^^^^^^^^^^^^^^^^^
  File "/Users/hubievkasym/Desktop/Python Projects/IT_round/.venv/lib/python3.12/site-packages/aiogram/dispatcher/router.py", line 166, in _propagate_event
    response = await observer.trigger(event, **kwargs)
               ^^^^^^^^^^^^^^^^^^^^^^^^^^^^^^^^^^^^^^^
  File "/Users/hubievkasym/Desktop/Python Projects/IT_round/.venv/lib/python3.12/site-packages/aiogram/dispatcher/event/telegram.py", line 121, in trigger
    return await wrapped_inner(event, kwargs)
           ^^^^^^^^^^^^^^^^^^^^^^^^^^^^^^^^^^
  File "/Users/hubievkasym/Desktop/Python Projects/IT_round/.venv/lib/python3.12/site-packages/aiogram/dispatcher/event/handler.py", line 43, in call
    return await wrapped()
                 ^^^^^^^^^
TypeError: global_error_handler() missing 1 required positional argument: 'error'
INFO:aiogram.event:Update id=607674340 is not handled. Duration 92 ms by bot id=7628846836
ERROR:aiogram.event:Cause exception while process update id=607674340 by bot id=7628846836
TypeError: global_error_handler() missing 1 required positional argument: 'error'
Traceback (most recent call last):
  File "/Users/hubievkasym/Desktop/Python Projects/IT_round/.venv/lib/python3.12/site-packages/aiogram/dispatcher/middlewares/error.py", line 25, in __call__
    return await handler(event, data)
           ^^^^^^^^^^^^^^^^^^^^^^^^^^
  File "/Users/hubievkasym/Desktop/Python Projects/IT_round/.venv/lib/python3.12/site-packages/aiogram/dispatcher/middlewares/user_context.py", line 56, in __call__
    return await handler(event, data)
           ^^^^^^^^^^^^^^^^^^^^^^^^^^
  File "/Users/hubievkasym/Desktop/Python Projects/IT_round/.venv/lib/python3.12/site-packages/aiogram/fsm/middleware.py", line 42, in __call__
    return await handler(event, data)
           ^^^^^^^^^^^^^^^^^^^^^^^^^^
  File "/Users/hubievkasym/Desktop/Python Projects/IT_round/.venv/lib/python3.12/site-packages/aiogram/dispatcher/event/telegram.py", line 121, in trigger
    return await wrapped_inner(event, kwargs)
           ^^^^^^^^^^^^^^^^^^^^^^^^^^^^^^^^^^
  File "/Users/hubievkasym/Desktop/Python Projects/IT_round/.venv/lib/python3.12/site-packages/aiogram/dispatcher/event/handler.py", line 43, in call
    return await wrapped()
           ^^^^^^^^^^^^^^^
  File "/Users/hubievkasym/Desktop/Python Projects/IT_round/.venv/lib/python3.12/site-packages/aiogram/dispatcher/dispatcher.py", line 276, in _listen_update
    return await self.propagate_event(update_type=update_type, event=event, **kwargs)
           ^^^^^^^^^^^^^^^^^^^^^^^^^^^^^^^^^^^^^^^^^^^^^^^^^^^^^^^^^^^^^^^^^^^^^^^^^^
  File "/Users/hubievkasym/Desktop/Python Projects/IT_round/.venv/lib/python3.12/site-packages/aiogram/dispatcher/router.py", line 146, in propagate_event
    return await observer.wrap_outer_middleware(_wrapped, event=event, data=kwargs)
           ^^^^^^^^^^^^^^^^^^^^^^^^^^^^^^^^^^^^^^^^^^^^^^^^^^^^^^^^^^^^^^^^^^^^^^^^
  File "/Users/hubievkasym/Desktop/Python Projects/IT_round/.venv/lib/python3.12/site-packages/aiogram/dispatcher/router.py", line 141, in _wrapped
    return await self._propagate_event(
           ^^^^^^^^^^^^^^^^^^^^^^^^^^^^
  File "/Users/hubievkasym/Desktop/Python Projects/IT_round/.venv/lib/python3.12/site-packages/aiogram/dispatcher/router.py", line 166, in _propagate_event
    response = await observer.trigger(event, **kwargs)
               ^^^^^^^^^^^^^^^^^^^^^^^^^^^^^^^^^^^^^^^
  File "/Users/hubievkasym/Desktop/Python Projects/IT_round/.venv/lib/python3.12/site-packages/aiogram/dispatcher/event/telegram.py", line 121, in trigger
    return await wrapped_inner(event, kwargs)
           ^^^^^^^^^^^^^^^^^^^^^^^^^^^^^^^^^^
  File "/Users/hubievkasym/Desktop/Python Projects/IT_round/.venv/lib/python3.12/site-packages/aiogram/dispatcher/event/handler.py", line 43, in call
    return await wrapped()
           ^^^^^^^^^^^^^^^
  File "/Users/hubievkasym/Desktop/Python Projects/IT_round/app/telebot.py", line 119, in show_schedule
    await message.reply(response)
  File "/Users/hubievkasym/Desktop/Python Projects/IT_round/.venv/lib/python3.12/site-packages/aiogram/methods/base.py", line 84, in emit
    return await bot(self)
           ^^^^^^^^^^^^^^^
  File "/Users/hubievkasym/Desktop/Python Projects/IT_round/.venv/lib/python3.12/site-packages/aiogram/client/bot.py", line 482, in __call__
    return await self.session(self, method, timeout=request_timeout)
           ^^^^^^^^^^^^^^^^^^^^^^^^^^^^^^^^^^^^^^^^^^^^^^^^^^^^^^^^^
  File "/Users/hubievkasym/Desktop/Python Projects/IT_round/.venv/lib/python3.12/site-packages/aiogram/client/session/base.py", line 254, in __call__
    return cast(TelegramType, await middleware(bot, method))
                              ^^^^^^^^^^^^^^^^^^^^^^^^^^^^^
  File "/Users/hubievkasym/Desktop/Python Projects/IT_round/.venv/lib/python3.12/site-packages/aiogram/client/session/aiohttp.py", line 185, in make_request
    response = self.check_response(
               ^^^^^^^^^^^^^^^^^^^^
  File "/Users/hubievkasym/Desktop/Python Projects/IT_round/.venv/lib/python3.12/site-packages/aiogram/client/session/base.py", line 120, in check_response
    raise TelegramBadRequest(method=method, message=description)
aiogram.exceptions.TelegramBadRequest: Telegram server says - Bad Request: message text is empty

During handling of the above exception, another exception occurred:

Traceback (most recent call last):
  File "/Users/hubievkasym/Desktop/Python Projects/IT_round/.venv/lib/python3.12/site-packages/aiogram/dispatcher/dispatcher.py", line 309, in _process_update
    response = await self.feed_update(bot, update, **kwargs)
               ^^^^^^^^^^^^^^^^^^^^^^^^^^^^^^^^^^^^^^^^^^^^^
  File "/Users/hubievkasym/Desktop/Python Projects/IT_round/.venv/lib/python3.12/site-packages/aiogram/dispatcher/dispatcher.py", line 158, in feed_update
    response = await self.update.wrap_outer_middleware(
               ^^^^^^^^^^^^^^^^^^^^^^^^^^^^^^^^^^^^^^^^
  File "/Users/hubievkasym/Desktop/Python Projects/IT_round/.venv/lib/python3.12/site-packages/aiogram/dispatcher/middlewares/error.py", line 29, in __call__
    response = await self.router.propagate_event(
               ^^^^^^^^^^^^^^^^^^^^^^^^^^^^^^^^^^
  File "/Users/hubievkasym/Desktop/Python Projects/IT_round/.venv/lib/python3.12/site-packages/aiogram/dispatcher/router.py", line 146, in propagate_event
    return await observer.wrap_outer_middleware(_wrapped, event=event, data=kwargs)
           ^^^^^^^^^^^^^^^^^^^^^^^^^^^^^^^^^^^^^^^^^^^^^^^^^^^^^^^^^^^^^^^^^^^^^^^^
  File "/Users/hubievkasym/Desktop/Python Projects/IT_round/.venv/lib/python3.12/site-packages/aiogram/dispatcher/router.py", line 141, in _wrapped
    return await self._propagate_event(
           ^^^^^^^^^^^^^^^^^^^^^^^^^^^^
  File "/Users/hubievkasym/Desktop/Python Projects/IT_round/.venv/lib/python3.12/site-packages/aiogram/dispatcher/router.py", line 166, in _propagate_event
    response = await observer.trigger(event, **kwargs)
               ^^^^^^^^^^^^^^^^^^^^^^^^^^^^^^^^^^^^^^^
  File "/Users/hubievkasym/Desktop/Python Projects/IT_round/.venv/lib/python3.12/site-packages/aiogram/dispatcher/event/telegram.py", line 121, in trigger
    return await wrapped_inner(event, kwargs)
           ^^^^^^^^^^^^^^^^^^^^^^^^^^^^^^^^^^
  File "/Users/hubievkasym/Desktop/Python Projects/IT_round/.venv/lib/python3.12/site-packages/aiogram/dispatcher/event/handler.py", line 43, in call
    return await wrapped()
                 ^^^^^^^^^
TypeError: global_error_handler() missing 1 required positional argument: 'error'
INFO:aiogram.event:Update id=607674341 is handled. Duration 192 ms by bot id=7628846836
INFO:aiogram.event:Update id=607674342 is handled. Duration 202 ms by bot id=7628846836
INFO:aiogram.event:Update id=607674343 is handled. Duration 226 ms by bot id=7628846836
INFO:aiogram.event:Update id=607674344 is handled. Duration 215 ms by bot id=7628846836
INFO:aiogram.event:Update id=607674345 is not handled. Duration 159 ms by bot id=7628846836
ERROR:aiogram.event:Cause exception while process update id=607674345 by bot id=7628846836
TypeError: global_error_handler() missing 1 required positional argument: 'error'
Traceback (most recent call last):
  File "/Users/hubievkasym/Desktop/Python Projects/IT_round/.venv/lib/python3.12/site-packages/aiogram/dispatcher/middlewares/error.py", line 25, in __call__
    return await handler(event, data)
           ^^^^^^^^^^^^^^^^^^^^^^^^^^
  File "/Users/hubievkasym/Desktop/Python Projects/IT_round/.venv/lib/python3.12/site-packages/aiogram/dispatcher/middlewares/user_context.py", line 56, in __call__
    return await handler(event, data)
           ^^^^^^^^^^^^^^^^^^^^^^^^^^
  File "/Users/hubievkasym/Desktop/Python Projects/IT_round/.venv/lib/python3.12/site-packages/aiogram/fsm/middleware.py", line 42, in __call__
    return await handler(event, data)
           ^^^^^^^^^^^^^^^^^^^^^^^^^^
  File "/Users/hubievkasym/Desktop/Python Projects/IT_round/.venv/lib/python3.12/site-packages/aiogram/dispatcher/event/telegram.py", line 121, in trigger
    return await wrapped_inner(event, kwargs)
           ^^^^^^^^^^^^^^^^^^^^^^^^^^^^^^^^^^
  File "/Users/hubievkasym/Desktop/Python Projects/IT_round/.venv/lib/python3.12/site-packages/aiogram/dispatcher/event/handler.py", line 43, in call
    return await wrapped()
           ^^^^^^^^^^^^^^^
  File "/Users/hubievkasym/Desktop/Python Projects/IT_round/.venv/lib/python3.12/site-packages/aiogram/dispatcher/dispatcher.py", line 276, in _listen_update
    return await self.propagate_event(update_type=update_type, event=event, **kwargs)
           ^^^^^^^^^^^^^^^^^^^^^^^^^^^^^^^^^^^^^^^^^^^^^^^^^^^^^^^^^^^^^^^^^^^^^^^^^^
  File "/Users/hubievkasym/Desktop/Python Projects/IT_round/.venv/lib/python3.12/site-packages/aiogram/dispatcher/router.py", line 146, in propagate_event
    return await observer.wrap_outer_middleware(_wrapped, event=event, data=kwargs)
           ^^^^^^^^^^^^^^^^^^^^^^^^^^^^^^^^^^^^^^^^^^^^^^^^^^^^^^^^^^^^^^^^^^^^^^^^
  File "/Users/hubievkasym/Desktop/Python Projects/IT_round/.venv/lib/python3.12/site-packages/aiogram/dispatcher/router.py", line 141, in _wrapped
    return await self._propagate_event(
           ^^^^^^^^^^^^^^^^^^^^^^^^^^^^
  File "/Users/hubievkasym/Desktop/Python Projects/IT_round/.venv/lib/python3.12/site-packages/aiogram/dispatcher/router.py", line 166, in _propagate_event
    response = await observer.trigger(event, **kwargs)
               ^^^^^^^^^^^^^^^^^^^^^^^^^^^^^^^^^^^^^^^
  File "/Users/hubievkasym/Desktop/Python Projects/IT_round/.venv/lib/python3.12/site-packages/aiogram/dispatcher/event/telegram.py", line 121, in trigger
    return await wrapped_inner(event, kwargs)
           ^^^^^^^^^^^^^^^^^^^^^^^^^^^^^^^^^^
  File "/Users/hubievkasym/Desktop/Python Projects/IT_round/.venv/lib/python3.12/site-packages/aiogram/dispatcher/event/handler.py", line 43, in call
    return await wrapped()
           ^^^^^^^^^^^^^^^
  File "/Users/hubievkasym/Desktop/Python Projects/IT_round/app/telebot.py", line 119, in show_schedule
    await message.reply(response)
  File "/Users/hubievkasym/Desktop/Python Projects/IT_round/.venv/lib/python3.12/site-packages/aiogram/methods/base.py", line 84, in emit
    return await bot(self)
           ^^^^^^^^^^^^^^^
  File "/Users/hubievkasym/Desktop/Python Projects/IT_round/.venv/lib/python3.12/site-packages/aiogram/client/bot.py", line 482, in __call__
    return await self.session(self, method, timeout=request_timeout)
           ^^^^^^^^^^^^^^^^^^^^^^^^^^^^^^^^^^^^^^^^^^^^^^^^^^^^^^^^^
  File "/Users/hubievkasym/Desktop/Python Projects/IT_round/.venv/lib/python3.12/site-packages/aiogram/client/session/base.py", line 254, in __call__
    return cast(TelegramType, await middleware(bot, method))
                              ^^^^^^^^^^^^^^^^^^^^^^^^^^^^^
  File "/Users/hubievkasym/Desktop/Python Projects/IT_round/.venv/lib/python3.12/site-packages/aiogram/client/session/aiohttp.py", line 185, in make_request
    response = self.check_response(
               ^^^^^^^^^^^^^^^^^^^^
  File "/Users/hubievkasym/Desktop/Python Projects/IT_round/.venv/lib/python3.12/site-packages/aiogram/client/session/base.py", line 120, in check_response
    raise TelegramBadRequest(method=method, message=description)
aiogram.exceptions.TelegramBadRequest: Telegram server says - Bad Request: message text is empty

During handling of the above exception, another exception occurred:

Traceback (most recent call last):
  File "/Users/hubievkasym/Desktop/Python Projects/IT_round/.venv/lib/python3.12/site-packages/aiogram/dispatcher/dispatcher.py", line 309, in _process_update
    response = await self.feed_update(bot, update, **kwargs)
               ^^^^^^^^^^^^^^^^^^^^^^^^^^^^^^^^^^^^^^^^^^^^^
  File "/Users/hubievkasym/Desktop/Python Projects/IT_round/.venv/lib/python3.12/site-packages/aiogram/dispatcher/dispatcher.py", line 158, in feed_update
    response = await self.update.wrap_outer_middleware(
               ^^^^^^^^^^^^^^^^^^^^^^^^^^^^^^^^^^^^^^^^
  File "/Users/hubievkasym/Desktop/Python Projects/IT_round/.venv/lib/python3.12/site-packages/aiogram/dispatcher/middlewares/error.py", line 29, in __call__
    response = await self.router.propagate_event(
               ^^^^^^^^^^^^^^^^^^^^^^^^^^^^^^^^^^
  File "/Users/hubievkasym/Desktop/Python Projects/IT_round/.venv/lib/python3.12/site-packages/aiogram/dispatcher/router.py", line 146, in propagate_event
    return await observer.wrap_outer_middleware(_wrapped, event=event, data=kwargs)
           ^^^^^^^^^^^^^^^^^^^^^^^^^^^^^^^^^^^^^^^^^^^^^^^^^^^^^^^^^^^^^^^^^^^^^^^^
  File "/Users/hubievkasym/Desktop/Python Projects/IT_round/.venv/lib/python3.12/site-packages/aiogram/dispatcher/router.py", line 141, in _wrapped
    return await self._propagate_event(
           ^^^^^^^^^^^^^^^^^^^^^^^^^^^^
  File "/Users/hubievkasym/Desktop/Python Projects/IT_round/.venv/lib/python3.12/site-packages/aiogram/dispatcher/router.py", line 166, in _propagate_event
    response = await observer.trigger(event, **kwargs)
               ^^^^^^^^^^^^^^^^^^^^^^^^^^^^^^^^^^^^^^^
  File "/Users/hubievkasym/Desktop/Python Projects/IT_round/.venv/lib/python3.12/site-packages/aiogram/dispatcher/event/telegram.py", line 121, in trigger
    return await wrapped_inner(event, kwargs)
           ^^^^^^^^^^^^^^^^^^^^^^^^^^^^^^^^^^
  File "/Users/hubievkasym/Desktop/Python Projects/IT_round/.venv/lib/python3.12/site-packages/aiogram/dispatcher/event/handler.py", line 43, in call
    return await wrapped()
                 ^^^^^^^^^
TypeError: global_error_handler() missing 1 required positional argument: 'error'
INFO:aiogram.event:Update id=607674346 is not handled. Duration 1 ms by bot id=7628846836
INFO:aiogram.event:Update id=607674347 is handled. Duration 230 ms by bot id=7628846836
INFO:aiogram.event:Update id=607674348 is handled. Duration 135 ms by bot id=7628846836
INFO:aiogram.event:Update id=607674349 is not handled. Duration 89 ms by bot id=7628846836
ERROR:aiogram.event:Cause exception while process update id=607674349 by bot id=7628846836
TypeError: global_error_handler() missing 1 required positional argument: 'error'
Traceback (most recent call last):
  File "/Users/hubievkasym/Desktop/Python Projects/IT_round/.venv/lib/python3.12/site-packages/aiogram/dispatcher/middlewares/error.py", line 25, in __call__
    return await handler(event, data)
           ^^^^^^^^^^^^^^^^^^^^^^^^^^
  File "/Users/hubievkasym/Desktop/Python Projects/IT_round/.venv/lib/python3.12/site-packages/aiogram/dispatcher/middlewares/user_context.py", line 56, in __call__
    return await handler(event, data)
           ^^^^^^^^^^^^^^^^^^^^^^^^^^
  File "/Users/hubievkasym/Desktop/Python Projects/IT_round/.venv/lib/python3.12/site-packages/aiogram/fsm/middleware.py", line 42, in __call__
    return await handler(event, data)
           ^^^^^^^^^^^^^^^^^^^^^^^^^^
  File "/Users/hubievkasym/Desktop/Python Projects/IT_round/.venv/lib/python3.12/site-packages/aiogram/dispatcher/event/telegram.py", line 121, in trigger
    return await wrapped_inner(event, kwargs)
           ^^^^^^^^^^^^^^^^^^^^^^^^^^^^^^^^^^
  File "/Users/hubievkasym/Desktop/Python Projects/IT_round/.venv/lib/python3.12/site-packages/aiogram/dispatcher/event/handler.py", line 43, in call
    return await wrapped()
           ^^^^^^^^^^^^^^^
  File "/Users/hubievkasym/Desktop/Python Projects/IT_round/.venv/lib/python3.12/site-packages/aiogram/dispatcher/dispatcher.py", line 276, in _listen_update
    return await self.propagate_event(update_type=update_type, event=event, **kwargs)
           ^^^^^^^^^^^^^^^^^^^^^^^^^^^^^^^^^^^^^^^^^^^^^^^^^^^^^^^^^^^^^^^^^^^^^^^^^^
  File "/Users/hubievkasym/Desktop/Python Projects/IT_round/.venv/lib/python3.12/site-packages/aiogram/dispatcher/router.py", line 146, in propagate_event
    return await observer.wrap_outer_middleware(_wrapped, event=event, data=kwargs)
           ^^^^^^^^^^^^^^^^^^^^^^^^^^^^^^^^^^^^^^^^^^^^^^^^^^^^^^^^^^^^^^^^^^^^^^^^
  File "/Users/hubievkasym/Desktop/Python Projects/IT_round/.venv/lib/python3.12/site-packages/aiogram/dispatcher/router.py", line 141, in _wrapped
    return await self._propagate_event(
           ^^^^^^^^^^^^^^^^^^^^^^^^^^^^
  File "/Users/hubievkasym/Desktop/Python Projects/IT_round/.venv/lib/python3.12/site-packages/aiogram/dispatcher/router.py", line 166, in _propagate_event
    response = await observer.trigger(event, **kwargs)
               ^^^^^^^^^^^^^^^^^^^^^^^^^^^^^^^^^^^^^^^
  File "/Users/hubievkasym/Desktop/Python Projects/IT_round/.venv/lib/python3.12/site-packages/aiogram/dispatcher/event/telegram.py", line 121, in trigger
    return await wrapped_inner(event, kwargs)
           ^^^^^^^^^^^^^^^^^^^^^^^^^^^^^^^^^^
  File "/Users/hubievkasym/Desktop/Python Projects/IT_round/.venv/lib/python3.12/site-packages/aiogram/dispatcher/event/handler.py", line 43, in call
    return await wrapped()
           ^^^^^^^^^^^^^^^
  File "/Users/hubievkasym/Desktop/Python Projects/IT_round/app/telebot.py", line 119, in show_schedule
    await message.reply(response)
  File "/Users/hubievkasym/Desktop/Python Projects/IT_round/.venv/lib/python3.12/site-packages/aiogram/methods/base.py", line 84, in emit
    return await bot(self)
           ^^^^^^^^^^^^^^^
  File "/Users/hubievkasym/Desktop/Python Projects/IT_round/.venv/lib/python3.12/site-packages/aiogram/client/bot.py", line 482, in __call__
    return await self.session(self, method, timeout=request_timeout)
           ^^^^^^^^^^^^^^^^^^^^^^^^^^^^^^^^^^^^^^^^^^^^^^^^^^^^^^^^^
  File "/Users/hubievkasym/Desktop/Python Projects/IT_round/.venv/lib/python3.12/site-packages/aiogram/client/session/base.py", line 254, in __call__
    return cast(TelegramType, await middleware(bot, method))
                              ^^^^^^^^^^^^^^^^^^^^^^^^^^^^^
  File "/Users/hubievkasym/Desktop/Python Projects/IT_round/.venv/lib/python3.12/site-packages/aiogram/client/session/aiohttp.py", line 185, in make_request
    response = self.check_response(
               ^^^^^^^^^^^^^^^^^^^^
  File "/Users/hubievkasym/Desktop/Python Projects/IT_round/.venv/lib/python3.12/site-packages/aiogram/client/session/base.py", line 120, in check_response
    raise TelegramBadRequest(method=method, message=description)
aiogram.exceptions.TelegramBadRequest: Telegram server says - Bad Request: message text is empty

During handling of the above exception, another exception occurred:

Traceback (most recent call last):
  File "/Users/hubievkasym/Desktop/Python Projects/IT_round/.venv/lib/python3.12/site-packages/aiogram/dispatcher/dispatcher.py", line 309, in _process_update
    response = await self.feed_update(bot, update, **kwargs)
               ^^^^^^^^^^^^^^^^^^^^^^^^^^^^^^^^^^^^^^^^^^^^^
  File "/Users/hubievkasym/Desktop/Python Projects/IT_round/.venv/lib/python3.12/site-packages/aiogram/dispatcher/dispatcher.py", line 158, in feed_update
    response = await self.update.wrap_outer_middleware(
               ^^^^^^^^^^^^^^^^^^^^^^^^^^^^^^^^^^^^^^^^
  File "/Users/hubievkasym/Desktop/Python Projects/IT_round/.venv/lib/python3.12/site-packages/aiogram/dispatcher/middlewares/error.py", line 29, in __call__
    response = await self.router.propagate_event(
               ^^^^^^^^^^^^^^^^^^^^^^^^^^^^^^^^^^
  File "/Users/hubievkasym/Desktop/Python Projects/IT_round/.venv/lib/python3.12/site-packages/aiogram/dispatcher/router.py", line 146, in propagate_event
    return await observer.wrap_outer_middleware(_wrapped, event=event, data=kwargs)
           ^^^^^^^^^^^^^^^^^^^^^^^^^^^^^^^^^^^^^^^^^^^^^^^^^^^^^^^^^^^^^^^^^^^^^^^^
  File "/Users/hubievkasym/Desktop/Python Projects/IT_round/.venv/lib/python3.12/site-packages/aiogram/dispatcher/router.py", line 141, in _wrapped
    return await self._propagate_event(
           ^^^^^^^^^^^^^^^^^^^^^^^^^^^^
  File "/Users/hubievkasym/Desktop/Python Projects/IT_round/.venv/lib/python3.12/site-packages/aiogram/dispatcher/router.py", line 166, in _propagate_event
    response = await observer.trigger(event, **kwargs)
               ^^^^^^^^^^^^^^^^^^^^^^^^^^^^^^^^^^^^^^^
  File "/Users/hubievkasym/Desktop/Python Projects/IT_round/.venv/lib/python3.12/site-packages/aiogram/dispatcher/event/telegram.py", line 121, in trigger
    return await wrapped_inner(event, kwargs)
           ^^^^^^^^^^^^^^^^^^^^^^^^^^^^^^^^^^
  File "/Users/hubievkasym/Desktop/Python Projects/IT_round/.venv/lib/python3.12/site-packages/aiogram/dispatcher/event/handler.py", line 43, in call
    return await wrapped()
                 ^^^^^^^^^
TypeError: global_error_handler() missing 1 required positional argument: 'error'
INFO:aiogram.event:Update id=607674350 is not handled. Duration 100 ms by bot id=7628846836
ERROR:aiogram.event:Cause exception while process update id=607674350 by bot id=7628846836
TypeError: global_error_handler() missing 1 required positional argument: 'error'
Traceback (most recent call last):
  File "/Users/hubievkasym/Desktop/Python Projects/IT_round/.venv/lib/python3.12/site-packages/aiogram/dispatcher/middlewares/error.py", line 25, in __call__
    return await handler(event, data)
           ^^^^^^^^^^^^^^^^^^^^^^^^^^
  File "/Users/hubievkasym/Desktop/Python Projects/IT_round/.venv/lib/python3.12/site-packages/aiogram/dispatcher/middlewares/user_context.py", line 56, in __call__
    return await handler(event, data)
           ^^^^^^^^^^^^^^^^^^^^^^^^^^
  File "/Users/hubievkasym/Desktop/Python Projects/IT_round/.venv/lib/python3.12/site-packages/aiogram/fsm/middleware.py", line 42, in __call__
    return await handler(event, data)
           ^^^^^^^^^^^^^^^^^^^^^^^^^^
  File "/Users/hubievkasym/Desktop/Python Projects/IT_round/.venv/lib/python3.12/site-packages/aiogram/dispatcher/event/telegram.py", line 121, in trigger
    return await wrapped_inner(event, kwargs)
           ^^^^^^^^^^^^^^^^^^^^^^^^^^^^^^^^^^
  File "/Users/hubievkasym/Desktop/Python Projects/IT_round/.venv/lib/python3.12/site-packages/aiogram/dispatcher/event/handler.py", line 43, in call
    return await wrapped()
           ^^^^^^^^^^^^^^^
  File "/Users/hubievkasym/Desktop/Python Projects/IT_round/.venv/lib/python3.12/site-packages/aiogram/dispatcher/dispatcher.py", line 276, in _listen_update
    return await self.propagate_event(update_type=update_type, event=event, **kwargs)
           ^^^^^^^^^^^^^^^^^^^^^^^^^^^^^^^^^^^^^^^^^^^^^^^^^^^^^^^^^^^^^^^^^^^^^^^^^^
  File "/Users/hubievkasym/Desktop/Python Projects/IT_round/.venv/lib/python3.12/site-packages/aiogram/dispatcher/router.py", line 146, in propagate_event
    return await observer.wrap_outer_middleware(_wrapped, event=event, data=kwargs)
           ^^^^^^^^^^^^^^^^^^^^^^^^^^^^^^^^^^^^^^^^^^^^^^^^^^^^^^^^^^^^^^^^^^^^^^^^
  File "/Users/hubievkasym/Desktop/Python Projects/IT_round/.venv/lib/python3.12/site-packages/aiogram/dispatcher/router.py", line 141, in _wrapped
    return await self._propagate_event(
           ^^^^^^^^^^^^^^^^^^^^^^^^^^^^
  File "/Users/hubievkasym/Desktop/Python Projects/IT_round/.venv/lib/python3.12/site-packages/aiogram/dispatcher/router.py", line 166, in _propagate_event
    response = await observer.trigger(event, **kwargs)
               ^^^^^^^^^^^^^^^^^^^^^^^^^^^^^^^^^^^^^^^
  File "/Users/hubievkasym/Desktop/Python Projects/IT_round/.venv/lib/python3.12/site-packages/aiogram/dispatcher/event/telegram.py", line 121, in trigger
    return await wrapped_inner(event, kwargs)
           ^^^^^^^^^^^^^^^^^^^^^^^^^^^^^^^^^^
  File "/Users/hubievkasym/Desktop/Python Projects/IT_round/.venv/lib/python3.12/site-packages/aiogram/dispatcher/event/handler.py", line 43, in call
    return await wrapped()
           ^^^^^^^^^^^^^^^
  File "/Users/hubievkasym/Desktop/Python Projects/IT_round/app/telebot.py", line 119, in show_schedule
    await message.reply(response)
  File "/Users/hubievkasym/Desktop/Python Projects/IT_round/.venv/lib/python3.12/site-packages/aiogram/methods/base.py", line 84, in emit
    return await bot(self)
           ^^^^^^^^^^^^^^^
  File "/Users/hubievkasym/Desktop/Python Projects/IT_round/.venv/lib/python3.12/site-packages/aiogram/client/bot.py", line 482, in __call__
    return await self.session(self, method, timeout=request_timeout)
           ^^^^^^^^^^^^^^^^^^^^^^^^^^^^^^^^^^^^^^^^^^^^^^^^^^^^^^^^^
  File "/Users/hubievkasym/Desktop/Python Projects/IT_round/.venv/lib/python3.12/site-packages/aiogram/client/session/base.py", line 254, in __call__
    return cast(TelegramType, await middleware(bot, method))
                              ^^^^^^^^^^^^^^^^^^^^^^^^^^^^^
  File "/Users/hubievkasym/Desktop/Python Projects/IT_round/.venv/lib/python3.12/site-packages/aiogram/client/session/aiohttp.py", line 185, in make_request
    response = self.check_response(
               ^^^^^^^^^^^^^^^^^^^^
  File "/Users/hubievkasym/Desktop/Python Projects/IT_round/.venv/lib/python3.12/site-packages/aiogram/client/session/base.py", line 120, in check_response
    raise TelegramBadRequest(method=method, message=description)
aiogram.exceptions.TelegramBadRequest: Telegram server says - Bad Request: message text is empty

During handling of the above exception, another exception occurred:

Traceback (most recent call last):
  File "/Users/hubievkasym/Desktop/Python Projects/IT_round/.venv/lib/python3.12/site-packages/aiogram/dispatcher/dispatcher.py", line 309, in _process_update
    response = await self.feed_update(bot, update, **kwargs)
               ^^^^^^^^^^^^^^^^^^^^^^^^^^^^^^^^^^^^^^^^^^^^^
  File "/Users/hubievkasym/Desktop/Python Projects/IT_round/.venv/lib/python3.12/site-packages/aiogram/dispatcher/dispatcher.py", line 158, in feed_update
    response = await self.update.wrap_outer_middleware(
               ^^^^^^^^^^^^^^^^^^^^^^^^^^^^^^^^^^^^^^^^
  File "/Users/hubievkasym/Desktop/Python Projects/IT_round/.venv/lib/python3.12/site-packages/aiogram/dispatcher/middlewares/error.py", line 29, in __call__
    response = await self.router.propagate_event(
               ^^^^^^^^^^^^^^^^^^^^^^^^^^^^^^^^^^
  File "/Users/hubievkasym/Desktop/Python Projects/IT_round/.venv/lib/python3.12/site-packages/aiogram/dispatcher/router.py", line 146, in propagate_event
    return await observer.wrap_outer_middleware(_wrapped, event=event, data=kwargs)
           ^^^^^^^^^^^^^^^^^^^^^^^^^^^^^^^^^^^^^^^^^^^^^^^^^^^^^^^^^^^^^^^^^^^^^^^^
  File "/Users/hubievkasym/Desktop/Python Projects/IT_round/.venv/lib/python3.12/site-packages/aiogram/dispatcher/router.py", line 141, in _wrapped
    return await self._propagate_event(
           ^^^^^^^^^^^^^^^^^^^^^^^^^^^^
  File "/Users/hubievkasym/Desktop/Python Projects/IT_round/.venv/lib/python3.12/site-packages/aiogram/dispatcher/router.py", line 166, in _propagate_event
    response = await observer.trigger(event, **kwargs)
               ^^^^^^^^^^^^^^^^^^^^^^^^^^^^^^^^^^^^^^^
  File "/Users/hubievkasym/Desktop/Python Projects/IT_round/.venv/lib/python3.12/site-packages/aiogram/dispatcher/event/telegram.py", line 121, in trigger
    return await wrapped_inner(event, kwargs)
           ^^^^^^^^^^^^^^^^^^^^^^^^^^^^^^^^^^
  File "/Users/hubievkasym/Desktop/Python Projects/IT_round/.venv/lib/python3.12/site-packages/aiogram/dispatcher/event/handler.py", line 43, in call
    return await wrapped()
                 ^^^^^^^^^
TypeError: global_error_handler() missing 1 required positional argument: 'error'
INFO:aiogram.event:Update id=607674351 is handled. Duration 154 ms by bot id=7628846836
INFO:aiogram.event:Update id=607674352 is handled. Duration 294 ms by bot id=7628846836
INFO:aiogram.event:Update id=607674353 is handled. Duration 132 ms by bot id=7628846836
INFO:aiogram.event:Update id=607674354 is not handled. Duration 96 ms by bot id=7628846836
ERROR:aiogram.event:Cause exception while process update id=607674354 by bot id=7628846836
TypeError: global_error_handler() missing 1 required positional argument: 'error'
Traceback (most recent call last):
  File "/Users/hubievkasym/Desktop/Python Projects/IT_round/.venv/lib/python3.12/site-packages/aiogram/dispatcher/middlewares/error.py", line 25, in __call__
    return await handler(event, data)
           ^^^^^^^^^^^^^^^^^^^^^^^^^^
  File "/Users/hubievkasym/Desktop/Python Projects/IT_round/.venv/lib/python3.12/site-packages/aiogram/dispatcher/middlewares/user_context.py", line 56, in __call__
    return await handler(event, data)
           ^^^^^^^^^^^^^^^^^^^^^^^^^^
  File "/Users/hubievkasym/Desktop/Python Projects/IT_round/.venv/lib/python3.12/site-packages/aiogram/fsm/middleware.py", line 42, in __call__
    return await handler(event, data)
           ^^^^^^^^^^^^^^^^^^^^^^^^^^
  File "/Users/hubievkasym/Desktop/Python Projects/IT_round/.venv/lib/python3.12/site-packages/aiogram/dispatcher/event/telegram.py", line 121, in trigger
    return await wrapped_inner(event, kwargs)
           ^^^^^^^^^^^^^^^^^^^^^^^^^^^^^^^^^^
  File "/Users/hubievkasym/Desktop/Python Projects/IT_round/.venv/lib/python3.12/site-packages/aiogram/dispatcher/event/handler.py", line 43, in call
    return await wrapped()
           ^^^^^^^^^^^^^^^
  File "/Users/hubievkasym/Desktop/Python Projects/IT_round/.venv/lib/python3.12/site-packages/aiogram/dispatcher/dispatcher.py", line 276, in _listen_update
    return await self.propagate_event(update_type=update_type, event=event, **kwargs)
           ^^^^^^^^^^^^^^^^^^^^^^^^^^^^^^^^^^^^^^^^^^^^^^^^^^^^^^^^^^^^^^^^^^^^^^^^^^
  File "/Users/hubievkasym/Desktop/Python Projects/IT_round/.venv/lib/python3.12/site-packages/aiogram/dispatcher/router.py", line 146, in propagate_event
    return await observer.wrap_outer_middleware(_wrapped, event=event, data=kwargs)
           ^^^^^^^^^^^^^^^^^^^^^^^^^^^^^^^^^^^^^^^^^^^^^^^^^^^^^^^^^^^^^^^^^^^^^^^^
  File "/Users/hubievkasym/Desktop/Python Projects/IT_round/.venv/lib/python3.12/site-packages/aiogram/dispatcher/router.py", line 141, in _wrapped
    return await self._propagate_event(
           ^^^^^^^^^^^^^^^^^^^^^^^^^^^^
  File "/Users/hubievkasym/Desktop/Python Projects/IT_round/.venv/lib/python3.12/site-packages/aiogram/dispatcher/router.py", line 166, in _propagate_event
    response = await observer.trigger(event, **kwargs)
               ^^^^^^^^^^^^^^^^^^^^^^^^^^^^^^^^^^^^^^^
  File "/Users/hubievkasym/Desktop/Python Projects/IT_round/.venv/lib/python3.12/site-packages/aiogram/dispatcher/event/telegram.py", line 121, in trigger
    return await wrapped_inner(event, kwargs)
           ^^^^^^^^^^^^^^^^^^^^^^^^^^^^^^^^^^
  File "/Users/hubievkasym/Desktop/Python Projects/IT_round/.venv/lib/python3.12/site-packages/aiogram/dispatcher/event/handler.py", line 43, in call
    return await wrapped()
           ^^^^^^^^^^^^^^^
  File "/Users/hubievkasym/Desktop/Python Projects/IT_round/app/telebot.py", line 119, in show_schedule
    await message.reply(response)
  File "/Users/hubievkasym/Desktop/Python Projects/IT_round/.venv/lib/python3.12/site-packages/aiogram/methods/base.py", line 84, in emit
    return await bot(self)
           ^^^^^^^^^^^^^^^
  File "/Users/hubievkasym/Desktop/Python Projects/IT_round/.venv/lib/python3.12/site-packages/aiogram/client/bot.py", line 482, in __call__
    return await self.session(self, method, timeout=request_timeout)
           ^^^^^^^^^^^^^^^^^^^^^^^^^^^^^^^^^^^^^^^^^^^^^^^^^^^^^^^^^
  File "/Users/hubievkasym/Desktop/Python Projects/IT_round/.venv/lib/python3.12/site-packages/aiogram/client/session/base.py", line 254, in __call__
    return cast(TelegramType, await middleware(bot, method))
                              ^^^^^^^^^^^^^^^^^^^^^^^^^^^^^
  File "/Users/hubievkasym/Desktop/Python Projects/IT_round/.venv/lib/python3.12/site-packages/aiogram/client/session/aiohttp.py", line 185, in make_request
    response = self.check_response(
               ^^^^^^^^^^^^^^^^^^^^
  File "/Users/hubievkasym/Desktop/Python Projects/IT_round/.venv/lib/python3.12/site-packages/aiogram/client/session/base.py", line 120, in check_response
    raise TelegramBadRequest(method=method, message=description)
aiogram.exceptions.TelegramBadRequest: Telegram server says - Bad Request: message text is empty

During handling of the above exception, another exception occurred:

Traceback (most recent call last):
  File "/Users/hubievkasym/Desktop/Python Projects/IT_round/.venv/lib/python3.12/site-packages/aiogram/dispatcher/dispatcher.py", line 309, in _process_update
    response = await self.feed_update(bot, update, **kwargs)
               ^^^^^^^^^^^^^^^^^^^^^^^^^^^^^^^^^^^^^^^^^^^^^
  File "/Users/hubievkasym/Desktop/Python Projects/IT_round/.venv/lib/python3.12/site-packages/aiogram/dispatcher/dispatcher.py", line 158, in feed_update
    response = await self.update.wrap_outer_middleware(
               ^^^^^^^^^^^^^^^^^^^^^^^^^^^^^^^^^^^^^^^^
  File "/Users/hubievkasym/Desktop/Python Projects/IT_round/.venv/lib/python3.12/site-packages/aiogram/dispatcher/middlewares/error.py", line 29, in __call__
    response = await self.router.propagate_event(
               ^^^^^^^^^^^^^^^^^^^^^^^^^^^^^^^^^^
  File "/Users/hubievkasym/Desktop/Python Projects/IT_round/.venv/lib/python3.12/site-packages/aiogram/dispatcher/router.py", line 146, in propagate_event
    return await observer.wrap_outer_middleware(_wrapped, event=event, data=kwargs)
           ^^^^^^^^^^^^^^^^^^^^^^^^^^^^^^^^^^^^^^^^^^^^^^^^^^^^^^^^^^^^^^^^^^^^^^^^
  File "/Users/hubievkasym/Desktop/Python Projects/IT_round/.venv/lib/python3.12/site-packages/aiogram/dispatcher/router.py", line 141, in _wrapped
    return await self._propagate_event(
           ^^^^^^^^^^^^^^^^^^^^^^^^^^^^
  File "/Users/hubievkasym/Desktop/Python Projects/IT_round/.venv/lib/python3.12/site-packages/aiogram/dispatcher/router.py", line 166, in _propagate_event
    response = await observer.trigger(event, **kwargs)
               ^^^^^^^^^^^^^^^^^^^^^^^^^^^^^^^^^^^^^^^
  File "/Users/hubievkasym/Desktop/Python Projects/IT_round/.venv/lib/python3.12/site-packages/aiogram/dispatcher/event/telegram.py", line 121, in trigger
    return await wrapped_inner(event, kwargs)
           ^^^^^^^^^^^^^^^^^^^^^^^^^^^^^^^^^^
  File "/Users/hubievkasym/Desktop/Python Projects/IT_round/.venv/lib/python3.12/site-packages/aiogram/dispatcher/event/handler.py", line 43, in call
    return await wrapped()
                 ^^^^^^^^^
TypeError: global_error_handler() missing 1 required positional argument: 'error'
INFO:aiogram.event:Update id=607674355 is not handled. Duration 84 ms by bot id=7628846836
ERROR:aiogram.event:Cause exception while process update id=607674355 by bot id=7628846836
TypeError: global_error_handler() missing 1 required positional argument: 'error'
Traceback (most recent call last):
  File "/Users/hubievkasym/Desktop/Python Projects/IT_round/.venv/lib/python3.12/site-packages/aiogram/dispatcher/middlewares/error.py", line 25, in __call__
    return await handler(event, data)
           ^^^^^^^^^^^^^^^^^^^^^^^^^^
  File "/Users/hubievkasym/Desktop/Python Projects/IT_round/.venv/lib/python3.12/site-packages/aiogram/dispatcher/middlewares/user_context.py", line 56, in __call__
    return await handler(event, data)
           ^^^^^^^^^^^^^^^^^^^^^^^^^^
  File "/Users/hubievkasym/Desktop/Python Projects/IT_round/.venv/lib/python3.12/site-packages/aiogram/fsm/middleware.py", line 42, in __call__
    return await handler(event, data)
           ^^^^^^^^^^^^^^^^^^^^^^^^^^
  File "/Users/hubievkasym/Desktop/Python Projects/IT_round/.venv/lib/python3.12/site-packages/aiogram/dispatcher/event/telegram.py", line 121, in trigger
    return await wrapped_inner(event, kwargs)
           ^^^^^^^^^^^^^^^^^^^^^^^^^^^^^^^^^^
  File "/Users/hubievkasym/Desktop/Python Projects/IT_round/.venv/lib/python3.12/site-packages/aiogram/dispatcher/event/handler.py", line 43, in call
    return await wrapped()
           ^^^^^^^^^^^^^^^
  File "/Users/hubievkasym/Desktop/Python Projects/IT_round/.venv/lib/python3.12/site-packages/aiogram/dispatcher/dispatcher.py", line 276, in _listen_update
    return await self.propagate_event(update_type=update_type, event=event, **kwargs)
           ^^^^^^^^^^^^^^^^^^^^^^^^^^^^^^^^^^^^^^^^^^^^^^^^^^^^^^^^^^^^^^^^^^^^^^^^^^
  File "/Users/hubievkasym/Desktop/Python Projects/IT_round/.venv/lib/python3.12/site-packages/aiogram/dispatcher/router.py", line 146, in propagate_event
    return await observer.wrap_outer_middleware(_wrapped, event=event, data=kwargs)
           ^^^^^^^^^^^^^^^^^^^^^^^^^^^^^^^^^^^^^^^^^^^^^^^^^^^^^^^^^^^^^^^^^^^^^^^^
  File "/Users/hubievkasym/Desktop/Python Projects/IT_round/.venv/lib/python3.12/site-packages/aiogram/dispatcher/router.py", line 141, in _wrapped
    return await self._propagate_event(
           ^^^^^^^^^^^^^^^^^^^^^^^^^^^^
  File "/Users/hubievkasym/Desktop/Python Projects/IT_round/.venv/lib/python3.12/site-packages/aiogram/dispatcher/router.py", line 166, in _propagate_event
    response = await observer.trigger(event, **kwargs)
               ^^^^^^^^^^^^^^^^^^^^^^^^^^^^^^^^^^^^^^^
  File "/Users/hubievkasym/Desktop/Python Projects/IT_round/.venv/lib/python3.12/site-packages/aiogram/dispatcher/event/telegram.py", line 121, in trigger
    return await wrapped_inner(event, kwargs)
           ^^^^^^^^^^^^^^^^^^^^^^^^^^^^^^^^^^
  File "/Users/hubievkasym/Desktop/Python Projects/IT_round/.venv/lib/python3.12/site-packages/aiogram/dispatcher/event/handler.py", line 43, in call
    return await wrapped()
           ^^^^^^^^^^^^^^^
  File "/Users/hubievkasym/Desktop/Python Projects/IT_round/app/telebot.py", line 119, in show_schedule
    await message.reply(response)
  File "/Users/hubievkasym/Desktop/Python Projects/IT_round/.venv/lib/python3.12/site-packages/aiogram/methods/base.py", line 84, in emit
    return await bot(self)
           ^^^^^^^^^^^^^^^
  File "/Users/hubievkasym/Desktop/Python Projects/IT_round/.venv/lib/python3.12/site-packages/aiogram/client/bot.py", line 482, in __call__
    return await self.session(self, method, timeout=request_timeout)
           ^^^^^^^^^^^^^^^^^^^^^^^^^^^^^^^^^^^^^^^^^^^^^^^^^^^^^^^^^
  File "/Users/hubievkasym/Desktop/Python Projects/IT_round/.venv/lib/python3.12/site-packages/aiogram/client/session/base.py", line 254, in __call__
    return cast(TelegramType, await middleware(bot, method))
                              ^^^^^^^^^^^^^^^^^^^^^^^^^^^^^
  File "/Users/hubievkasym/Desktop/Python Projects/IT_round/.venv/lib/python3.12/site-packages/aiogram/client/session/aiohttp.py", line 185, in make_request
    response = self.check_response(
               ^^^^^^^^^^^^^^^^^^^^
  File "/Users/hubievkasym/Desktop/Python Projects/IT_round/.venv/lib/python3.12/site-packages/aiogram/client/session/base.py", line 120, in check_response
    raise TelegramBadRequest(method=method, message=description)
aiogram.exceptions.TelegramBadRequest: Telegram server says - Bad Request: message text is empty

During handling of the above exception, another exception occurred:

Traceback (most recent call last):
  File "/Users/hubievkasym/Desktop/Python Projects/IT_round/.venv/lib/python3.12/site-packages/aiogram/dispatcher/dispatcher.py", line 309, in _process_update
    response = await self.feed_update(bot, update, **kwargs)
               ^^^^^^^^^^^^^^^^^^^^^^^^^^^^^^^^^^^^^^^^^^^^^
  File "/Users/hubievkasym/Desktop/Python Projects/IT_round/.venv/lib/python3.12/site-packages/aiogram/dispatcher/dispatcher.py", line 158, in feed_update
    response = await self.update.wrap_outer_middleware(
               ^^^^^^^^^^^^^^^^^^^^^^^^^^^^^^^^^^^^^^^^
  File "/Users/hubievkasym/Desktop/Python Projects/IT_round/.venv/lib/python3.12/site-packages/aiogram/dispatcher/middlewares/error.py", line 29, in __call__
    response = await self.router.propagate_event(
               ^^^^^^^^^^^^^^^^^^^^^^^^^^^^^^^^^^
  File "/Users/hubievkasym/Desktop/Python Projects/IT_round/.venv/lib/python3.12/site-packages/aiogram/dispatcher/router.py", line 146, in propagate_event
    return await observer.wrap_outer_middleware(_wrapped, event=event, data=kwargs)
           ^^^^^^^^^^^^^^^^^^^^^^^^^^^^^^^^^^^^^^^^^^^^^^^^^^^^^^^^^^^^^^^^^^^^^^^^
  File "/Users/hubievkasym/Desktop/Python Projects/IT_round/.venv/lib/python3.12/site-packages/aiogram/dispatcher/router.py", line 141, in _wrapped
    return await self._propagate_event(
           ^^^^^^^^^^^^^^^^^^^^^^^^^^^^
  File "/Users/hubievkasym/Desktop/Python Projects/IT_round/.venv/lib/python3.12/site-packages/aiogram/dispatcher/router.py", line 166, in _propagate_event
    response = await observer.trigger(event, **kwargs)
               ^^^^^^^^^^^^^^^^^^^^^^^^^^^^^^^^^^^^^^^
  File "/Users/hubievkasym/Desktop/Python Projects/IT_round/.venv/lib/python3.12/site-packages/aiogram/dispatcher/event/telegram.py", line 121, in trigger
    return await wrapped_inner(event, kwargs)
           ^^^^^^^^^^^^^^^^^^^^^^^^^^^^^^^^^^
  File "/Users/hubievkasym/Desktop/Python Projects/IT_round/.venv/lib/python3.12/site-packages/aiogram/dispatcher/event/handler.py", line 43, in call
    return await wrapped()
                 ^^^^^^^^^
TypeError: global_error_handler() missing 1 required positional argument: 'error'
INFO:aiogram.event:Update id=607674356 is handled. Duration 123 ms by bot id=7628846836
INFO:aiogram.event:Update id=607674357 is handled. Duration 134 ms by bot id=7628846836
INFO:aiogram.event:Update id=607674358 is handled. Duration 123 ms by bot id=7628846836
INFO:aiogram.event:Update id=607674359 is handled. Duration 125 ms by bot id=7628846836
INFO:aiogram.event:Update id=607674360 is handled. Duration 117 ms by bot id=7628846836
INFO:aiogram.event:Update id=607674361 is handled. Duration 160 ms by bot id=7628846836
INFO:aiogram.event:Update id=607674362 is not handled. Duration 89 ms by bot id=7628846836
ERROR:aiogram.event:Cause exception while process update id=607674362 by bot id=7628846836
TypeError: global_error_handler() missing 1 required positional argument: 'error'
Traceback (most recent call last):
  File "/Users/hubievkasym/Desktop/Python Projects/IT_round/.venv/lib/python3.12/site-packages/aiogram/dispatcher/middlewares/error.py", line 25, in __call__
    return await handler(event, data)
           ^^^^^^^^^^^^^^^^^^^^^^^^^^
  File "/Users/hubievkasym/Desktop/Python Projects/IT_round/.venv/lib/python3.12/site-packages/aiogram/dispatcher/middlewares/user_context.py", line 56, in __call__
    return await handler(event, data)
           ^^^^^^^^^^^^^^^^^^^^^^^^^^
  File "/Users/hubievkasym/Desktop/Python Projects/IT_round/.venv/lib/python3.12/site-packages/aiogram/fsm/middleware.py", line 42, in __call__
    return await handler(event, data)
           ^^^^^^^^^^^^^^^^^^^^^^^^^^
  File "/Users/hubievkasym/Desktop/Python Projects/IT_round/.venv/lib/python3.12/site-packages/aiogram/dispatcher/event/telegram.py", line 121, in trigger
    return await wrapped_inner(event, kwargs)
           ^^^^^^^^^^^^^^^^^^^^^^^^^^^^^^^^^^
  File "/Users/hubievkasym/Desktop/Python Projects/IT_round/.venv/lib/python3.12/site-packages/aiogram/dispatcher/event/handler.py", line 43, in call
    return await wrapped()
           ^^^^^^^^^^^^^^^
  File "/Users/hubievkasym/Desktop/Python Projects/IT_round/.venv/lib/python3.12/site-packages/aiogram/dispatcher/dispatcher.py", line 276, in _listen_update
    return await self.propagate_event(update_type=update_type, event=event, **kwargs)
           ^^^^^^^^^^^^^^^^^^^^^^^^^^^^^^^^^^^^^^^^^^^^^^^^^^^^^^^^^^^^^^^^^^^^^^^^^^
  File "/Users/hubievkasym/Desktop/Python Projects/IT_round/.venv/lib/python3.12/site-packages/aiogram/dispatcher/router.py", line 146, in propagate_event
    return await observer.wrap_outer_middleware(_wrapped, event=event, data=kwargs)
           ^^^^^^^^^^^^^^^^^^^^^^^^^^^^^^^^^^^^^^^^^^^^^^^^^^^^^^^^^^^^^^^^^^^^^^^^
  File "/Users/hubievkasym/Desktop/Python Projects/IT_round/.venv/lib/python3.12/site-packages/aiogram/dispatcher/router.py", line 141, in _wrapped
    return await self._propagate_event(
           ^^^^^^^^^^^^^^^^^^^^^^^^^^^^
  File "/Users/hubievkasym/Desktop/Python Projects/IT_round/.venv/lib/python3.12/site-packages/aiogram/dispatcher/router.py", line 166, in _propagate_event
    response = await observer.trigger(event, **kwargs)
               ^^^^^^^^^^^^^^^^^^^^^^^^^^^^^^^^^^^^^^^
  File "/Users/hubievkasym/Desktop/Python Projects/IT_round/.venv/lib/python3.12/site-packages/aiogram/dispatcher/event/telegram.py", line 121, in trigger
    return await wrapped_inner(event, kwargs)
           ^^^^^^^^^^^^^^^^^^^^^^^^^^^^^^^^^^
  File "/Users/hubievkasym/Desktop/Python Projects/IT_round/.venv/lib/python3.12/site-packages/aiogram/dispatcher/event/handler.py", line 43, in call
    return await wrapped()
           ^^^^^^^^^^^^^^^
  File "/Users/hubievkasym/Desktop/Python Projects/IT_round/app/telebot.py", line 119, in show_schedule
    await message.reply(response)
  File "/Users/hubievkasym/Desktop/Python Projects/IT_round/.venv/lib/python3.12/site-packages/aiogram/methods/base.py", line 84, in emit
    return await bot(self)
           ^^^^^^^^^^^^^^^
  File "/Users/hubievkasym/Desktop/Python Projects/IT_round/.venv/lib/python3.12/site-packages/aiogram/client/bot.py", line 482, in __call__
    return await self.session(self, method, timeout=request_timeout)
           ^^^^^^^^^^^^^^^^^^^^^^^^^^^^^^^^^^^^^^^^^^^^^^^^^^^^^^^^^
  File "/Users/hubievkasym/Desktop/Python Projects/IT_round/.venv/lib/python3.12/site-packages/aiogram/client/session/base.py", line 254, in __call__
    return cast(TelegramType, await middleware(bot, method))
                              ^^^^^^^^^^^^^^^^^^^^^^^^^^^^^
  File "/Users/hubievkasym/Desktop/Python Projects/IT_round/.venv/lib/python3.12/site-packages/aiogram/client/session/aiohttp.py", line 185, in make_request
    response = self.check_response(
               ^^^^^^^^^^^^^^^^^^^^
  File "/Users/hubievkasym/Desktop/Python Projects/IT_round/.venv/lib/python3.12/site-packages/aiogram/client/session/base.py", line 120, in check_response
    raise TelegramBadRequest(method=method, message=description)
aiogram.exceptions.TelegramBadRequest: Telegram server says - Bad Request: message text is empty

During handling of the above exception, another exception occurred:

Traceback (most recent call last):
  File "/Users/hubievkasym/Desktop/Python Projects/IT_round/.venv/lib/python3.12/site-packages/aiogram/dispatcher/dispatcher.py", line 309, in _process_update
    response = await self.feed_update(bot, update, **kwargs)
               ^^^^^^^^^^^^^^^^^^^^^^^^^^^^^^^^^^^^^^^^^^^^^
  File "/Users/hubievkasym/Desktop/Python Projects/IT_round/.venv/lib/python3.12/site-packages/aiogram/dispatcher/dispatcher.py", line 158, in feed_update
    response = await self.update.wrap_outer_middleware(
               ^^^^^^^^^^^^^^^^^^^^^^^^^^^^^^^^^^^^^^^^
  File "/Users/hubievkasym/Desktop/Python Projects/IT_round/.venv/lib/python3.12/site-packages/aiogram/dispatcher/middlewares/error.py", line 29, in __call__
    response = await self.router.propagate_event(
               ^^^^^^^^^^^^^^^^^^^^^^^^^^^^^^^^^^
  File "/Users/hubievkasym/Desktop/Python Projects/IT_round/.venv/lib/python3.12/site-packages/aiogram/dispatcher/router.py", line 146, in propagate_event
    return await observer.wrap_outer_middleware(_wrapped, event=event, data=kwargs)
           ^^^^^^^^^^^^^^^^^^^^^^^^^^^^^^^^^^^^^^^^^^^^^^^^^^^^^^^^^^^^^^^^^^^^^^^^
  File "/Users/hubievkasym/Desktop/Python Projects/IT_round/.venv/lib/python3.12/site-packages/aiogram/dispatcher/router.py", line 141, in _wrapped
    return await self._propagate_event(
           ^^^^^^^^^^^^^^^^^^^^^^^^^^^^
  File "/Users/hubievkasym/Desktop/Python Projects/IT_round/.venv/lib/python3.12/site-packages/aiogram/dispatcher/router.py", line 166, in _propagate_event
    response = await observer.trigger(event, **kwargs)
               ^^^^^^^^^^^^^^^^^^^^^^^^^^^^^^^^^^^^^^^
  File "/Users/hubievkasym/Desktop/Python Projects/IT_round/.venv/lib/python3.12/site-packages/aiogram/dispatcher/event/telegram.py", line 121, in trigger
    return await wrapped_inner(event, kwargs)
           ^^^^^^^^^^^^^^^^^^^^^^^^^^^^^^^^^^
  File "/Users/hubievkasym/Desktop/Python Projects/IT_round/.venv/lib/python3.12/site-packages/aiogram/dispatcher/event/handler.py", line 43, in call
    return await wrapped()
                 ^^^^^^^^^
TypeError: global_error_handler() missing 1 required positional argument: 'error'
INFO:aiogram.event:Update id=607674363 is handled. Duration 120 ms by bot id=7628846836
WARNING:aiogram.dispatcher:Received SIGINT signal
INFO:aiogram.dispatcher:Polling stopped for bot @mariam_chat_bot id=7628846836 - 'mariam_chat_bot'
INFO:aiogram.dispatcher:Polling stopped
INFO:aiogram.dispatcher:Start polling
INFO:aiogram.dispatcher:Run polling for bot @mariam_chat_bot id=7628846836 - 'mariam_chat_bot'
INFO:aiogram.event:Update id=607674364 is handled. Duration 1054 ms by bot id=7628846836
INFO:aiogram.event:Update id=607674365 is handled. Duration 325 ms by bot id=7628846836
WARNING:aiogram.dispatcher:Received SIGINT signal
INFO:aiogram.dispatcher:Polling stopped for bot @mariam_chat_bot id=7628846836 - 'mariam_chat_bot'
INFO:aiogram.dispatcher:Polling stopped
INFO:apscheduler.scheduler:Adding job tentatively -- it will be properly scheduled when the scheduler starts
INFO:apscheduler.scheduler:Added job "check_events" to job store "default"
INFO:apscheduler.scheduler:Scheduler started
INFO:aiogram.dispatcher:Start polling
INFO:aiogram.dispatcher:Polling stopped
INFO:apscheduler.scheduler:Adding job tentatively -- it will be properly scheduled when the scheduler starts
INFO:apscheduler.scheduler:Added job "check_events" to job store "default"
INFO:apscheduler.scheduler:Scheduler started
INFO:aiogram.dispatcher:Start polling
INFO:aiogram.dispatcher:Polling stopped
INFO:apscheduler.scheduler:Adding job tentatively -- it will be properly scheduled when the scheduler starts
INFO:apscheduler.scheduler:Added job "check_events" to job store "default"
INFO:apscheduler.scheduler:Scheduler started
INFO:aiogram.dispatcher:Start polling
INFO:aiogram.dispatcher:Polling stopped
INFO:aiogram.dispatcher:Start polling
INFO:aiogram.dispatcher:Run polling for bot @mariam_chat_bot id=7628846836 - 'mariam_chat_bot'
INFO:aiogram.event:Update id=607674369 is handled. Duration 261 ms by bot id=7628846836
INFO:aiogram.event:Update id=607674366 is handled. Duration 294 ms by bot id=7628846836
INFO:aiogram.event:Update id=607674367 is handled. Duration 311 ms by bot id=7628846836
INFO:aiogram.event:Update id=607674368 is handled. Duration 343 ms by bot id=7628846836
INFO:aiogram.event:Update id=607674370 is handled. Duration 368 ms by bot id=7628846836
INFO:aiogram.event:Update id=607674371 is handled. Duration 165 ms by bot id=7628846836
INFO:aiogram.event:Update id=607674372 is handled. Duration 106 ms by bot id=7628846836
INFO:aiogram.event:Update id=607674373 is not handled. Duration 107 ms by bot id=7628846836
ERROR:aiogram.event:Cause exception while process update id=607674373 by bot id=7628846836
TypeError: global_error_handler() missing 1 required positional argument: 'error'
Traceback (most recent call last):
  File "/Users/hubievkasym/Desktop/Python Projects/IT_round/.venv/lib/python3.12/site-packages/aiogram/dispatcher/middlewares/error.py", line 25, in __call__
    return await handler(event, data)
           ^^^^^^^^^^^^^^^^^^^^^^^^^^
  File "/Users/hubievkasym/Desktop/Python Projects/IT_round/.venv/lib/python3.12/site-packages/aiogram/dispatcher/middlewares/user_context.py", line 56, in __call__
    return await handler(event, data)
           ^^^^^^^^^^^^^^^^^^^^^^^^^^
  File "/Users/hubievkasym/Desktop/Python Projects/IT_round/.venv/lib/python3.12/site-packages/aiogram/fsm/middleware.py", line 42, in __call__
    return await handler(event, data)
           ^^^^^^^^^^^^^^^^^^^^^^^^^^
  File "/Users/hubievkasym/Desktop/Python Projects/IT_round/.venv/lib/python3.12/site-packages/aiogram/dispatcher/event/telegram.py", line 121, in trigger
    return await wrapped_inner(event, kwargs)
           ^^^^^^^^^^^^^^^^^^^^^^^^^^^^^^^^^^
  File "/Users/hubievkasym/Desktop/Python Projects/IT_round/.venv/lib/python3.12/site-packages/aiogram/dispatcher/event/handler.py", line 43, in call
    return await wrapped()
           ^^^^^^^^^^^^^^^
  File "/Users/hubievkasym/Desktop/Python Projects/IT_round/.venv/lib/python3.12/site-packages/aiogram/dispatcher/dispatcher.py", line 276, in _listen_update
    return await self.propagate_event(update_type=update_type, event=event, **kwargs)
           ^^^^^^^^^^^^^^^^^^^^^^^^^^^^^^^^^^^^^^^^^^^^^^^^^^^^^^^^^^^^^^^^^^^^^^^^^^
  File "/Users/hubievkasym/Desktop/Python Projects/IT_round/.venv/lib/python3.12/site-packages/aiogram/dispatcher/router.py", line 146, in propagate_event
    return await observer.wrap_outer_middleware(_wrapped, event=event, data=kwargs)
           ^^^^^^^^^^^^^^^^^^^^^^^^^^^^^^^^^^^^^^^^^^^^^^^^^^^^^^^^^^^^^^^^^^^^^^^^
  File "/Users/hubievkasym/Desktop/Python Projects/IT_round/.venv/lib/python3.12/site-packages/aiogram/dispatcher/router.py", line 141, in _wrapped
    return await self._propagate_event(
           ^^^^^^^^^^^^^^^^^^^^^^^^^^^^
  File "/Users/hubievkasym/Desktop/Python Projects/IT_round/.venv/lib/python3.12/site-packages/aiogram/dispatcher/router.py", line 166, in _propagate_event
    response = await observer.trigger(event, **kwargs)
               ^^^^^^^^^^^^^^^^^^^^^^^^^^^^^^^^^^^^^^^
  File "/Users/hubievkasym/Desktop/Python Projects/IT_round/.venv/lib/python3.12/site-packages/aiogram/dispatcher/event/telegram.py", line 121, in trigger
    return await wrapped_inner(event, kwargs)
           ^^^^^^^^^^^^^^^^^^^^^^^^^^^^^^^^^^
  File "/Users/hubievkasym/Desktop/Python Projects/IT_round/.venv/lib/python3.12/site-packages/aiogram/dispatcher/event/handler.py", line 43, in call
    return await wrapped()
           ^^^^^^^^^^^^^^^
  File "/Users/hubievkasym/Desktop/Python Projects/IT_round/app/telebot.py", line 119, in show_schedule
    await message.reply(response)
  File "/Users/hubievkasym/Desktop/Python Projects/IT_round/.venv/lib/python3.12/site-packages/aiogram/methods/base.py", line 84, in emit
    return await bot(self)
           ^^^^^^^^^^^^^^^
  File "/Users/hubievkasym/Desktop/Python Projects/IT_round/.venv/lib/python3.12/site-packages/aiogram/client/bot.py", line 482, in __call__
    return await self.session(self, method, timeout=request_timeout)
           ^^^^^^^^^^^^^^^^^^^^^^^^^^^^^^^^^^^^^^^^^^^^^^^^^^^^^^^^^
  File "/Users/hubievkasym/Desktop/Python Projects/IT_round/.venv/lib/python3.12/site-packages/aiogram/client/session/base.py", line 254, in __call__
    return cast(TelegramType, await middleware(bot, method))
                              ^^^^^^^^^^^^^^^^^^^^^^^^^^^^^
  File "/Users/hubievkasym/Desktop/Python Projects/IT_round/.venv/lib/python3.12/site-packages/aiogram/client/session/aiohttp.py", line 185, in make_request
    response = self.check_response(
               ^^^^^^^^^^^^^^^^^^^^
  File "/Users/hubievkasym/Desktop/Python Projects/IT_round/.venv/lib/python3.12/site-packages/aiogram/client/session/base.py", line 120, in check_response
    raise TelegramBadRequest(method=method, message=description)
aiogram.exceptions.TelegramBadRequest: Telegram server says - Bad Request: message text is empty

During handling of the above exception, another exception occurred:

Traceback (most recent call last):
  File "/Users/hubievkasym/Desktop/Python Projects/IT_round/.venv/lib/python3.12/site-packages/aiogram/dispatcher/dispatcher.py", line 309, in _process_update
    response = await self.feed_update(bot, update, **kwargs)
               ^^^^^^^^^^^^^^^^^^^^^^^^^^^^^^^^^^^^^^^^^^^^^
  File "/Users/hubievkasym/Desktop/Python Projects/IT_round/.venv/lib/python3.12/site-packages/aiogram/dispatcher/dispatcher.py", line 158, in feed_update
    response = await self.update.wrap_outer_middleware(
               ^^^^^^^^^^^^^^^^^^^^^^^^^^^^^^^^^^^^^^^^
  File "/Users/hubievkasym/Desktop/Python Projects/IT_round/.venv/lib/python3.12/site-packages/aiogram/dispatcher/middlewares/error.py", line 29, in __call__
    response = await self.router.propagate_event(
               ^^^^^^^^^^^^^^^^^^^^^^^^^^^^^^^^^^
  File "/Users/hubievkasym/Desktop/Python Projects/IT_round/.venv/lib/python3.12/site-packages/aiogram/dispatcher/router.py", line 146, in propagate_event
    return await observer.wrap_outer_middleware(_wrapped, event=event, data=kwargs)
           ^^^^^^^^^^^^^^^^^^^^^^^^^^^^^^^^^^^^^^^^^^^^^^^^^^^^^^^^^^^^^^^^^^^^^^^^
  File "/Users/hubievkasym/Desktop/Python Projects/IT_round/.venv/lib/python3.12/site-packages/aiogram/dispatcher/router.py", line 141, in _wrapped
    return await self._propagate_event(
           ^^^^^^^^^^^^^^^^^^^^^^^^^^^^
  File "/Users/hubievkasym/Desktop/Python Projects/IT_round/.venv/lib/python3.12/site-packages/aiogram/dispatcher/router.py", line 166, in _propagate_event
    response = await observer.trigger(event, **kwargs)
               ^^^^^^^^^^^^^^^^^^^^^^^^^^^^^^^^^^^^^^^
  File "/Users/hubievkasym/Desktop/Python Projects/IT_round/.venv/lib/python3.12/site-packages/aiogram/dispatcher/event/telegram.py", line 121, in trigger
    return await wrapped_inner(event, kwargs)
           ^^^^^^^^^^^^^^^^^^^^^^^^^^^^^^^^^^
  File "/Users/hubievkasym/Desktop/Python Projects/IT_round/.venv/lib/python3.12/site-packages/aiogram/dispatcher/event/handler.py", line 43, in call
    return await wrapped()
                 ^^^^^^^^^
TypeError: global_error_handler() missing 1 required positional argument: 'error'
INFO:aiogram.event:Update id=607674374 is handled. Duration 172 ms by bot id=7628846836
INFO:aiogram.event:Update id=607674375 is handled. Duration 103 ms by bot id=7628846836
WARNING:aiogram.dispatcher:Received SIGINT signal
INFO:aiogram.dispatcher:Polling stopped for bot @mariam_chat_bot id=7628846836 - 'mariam_chat_bot'
INFO:aiogram.dispatcher:Polling stopped
INFO:aiogram.dispatcher:Start polling
INFO:aiogram.dispatcher:Run polling for bot @mariam_chat_bot id=7628846836 - 'mariam_chat_bot'
INFO:aiogram.event:Update id=607674376 is handled. Duration 376 ms by bot id=7628846836
WARNING:aiogram.dispatcher:Received SIGINT signal
INFO:aiogram.dispatcher:Polling stopped for bot @mariam_chat_bot id=7628846836 - 'mariam_chat_bot'
INFO:aiogram.dispatcher:Polling stopped
INFO:aiogram.dispatcher:Start polling
INFO:aiogram.dispatcher:Run polling for bot @mariam_chat_bot id=7628846836 - 'mariam_chat_bot'
INFO:aiogram.event:Update id=607674377 is handled. Duration 297 ms by bot id=7628846836
INFO:aiogram.event:Update id=607674378 is handled. Duration 187 ms by bot id=7628846836
INFO:aiogram.event:Update id=607674379 is handled. Duration 139 ms by bot id=7628846836
INFO:aiogram.event:Update id=607674380 is not handled. Duration 96 ms by bot id=7628846836
ERROR:aiogram.event:Cause exception while process update id=607674380 by bot id=7628846836
TypeError: global_error_handler() missing 1 required positional argument: 'error'
Traceback (most recent call last):
  File "/Users/hubievkasym/Desktop/Python Projects/IT_round/.venv/lib/python3.12/site-packages/aiogram/dispatcher/middlewares/error.py", line 25, in __call__
    return await handler(event, data)
           ^^^^^^^^^^^^^^^^^^^^^^^^^^
  File "/Users/hubievkasym/Desktop/Python Projects/IT_round/.venv/lib/python3.12/site-packages/aiogram/dispatcher/middlewares/user_context.py", line 56, in __call__
    return await handler(event, data)
           ^^^^^^^^^^^^^^^^^^^^^^^^^^
  File "/Users/hubievkasym/Desktop/Python Projects/IT_round/.venv/lib/python3.12/site-packages/aiogram/fsm/middleware.py", line 42, in __call__
    return await handler(event, data)
           ^^^^^^^^^^^^^^^^^^^^^^^^^^
  File "/Users/hubievkasym/Desktop/Python Projects/IT_round/.venv/lib/python3.12/site-packages/aiogram/dispatcher/event/telegram.py", line 121, in trigger
    return await wrapped_inner(event, kwargs)
           ^^^^^^^^^^^^^^^^^^^^^^^^^^^^^^^^^^
  File "/Users/hubievkasym/Desktop/Python Projects/IT_round/.venv/lib/python3.12/site-packages/aiogram/dispatcher/event/handler.py", line 43, in call
    return await wrapped()
           ^^^^^^^^^^^^^^^
  File "/Users/hubievkasym/Desktop/Python Projects/IT_round/.venv/lib/python3.12/site-packages/aiogram/dispatcher/dispatcher.py", line 276, in _listen_update
    return await self.propagate_event(update_type=update_type, event=event, **kwargs)
           ^^^^^^^^^^^^^^^^^^^^^^^^^^^^^^^^^^^^^^^^^^^^^^^^^^^^^^^^^^^^^^^^^^^^^^^^^^
  File "/Users/hubievkasym/Desktop/Python Projects/IT_round/.venv/lib/python3.12/site-packages/aiogram/dispatcher/router.py", line 146, in propagate_event
    return await observer.wrap_outer_middleware(_wrapped, event=event, data=kwargs)
           ^^^^^^^^^^^^^^^^^^^^^^^^^^^^^^^^^^^^^^^^^^^^^^^^^^^^^^^^^^^^^^^^^^^^^^^^
  File "/Users/hubievkasym/Desktop/Python Projects/IT_round/.venv/lib/python3.12/site-packages/aiogram/dispatcher/router.py", line 141, in _wrapped
    return await self._propagate_event(
           ^^^^^^^^^^^^^^^^^^^^^^^^^^^^
  File "/Users/hubievkasym/Desktop/Python Projects/IT_round/.venv/lib/python3.12/site-packages/aiogram/dispatcher/router.py", line 166, in _propagate_event
    response = await observer.trigger(event, **kwargs)
               ^^^^^^^^^^^^^^^^^^^^^^^^^^^^^^^^^^^^^^^
  File "/Users/hubievkasym/Desktop/Python Projects/IT_round/.venv/lib/python3.12/site-packages/aiogram/dispatcher/event/telegram.py", line 121, in trigger
    return await wrapped_inner(event, kwargs)
           ^^^^^^^^^^^^^^^^^^^^^^^^^^^^^^^^^^
  File "/Users/hubievkasym/Desktop/Python Projects/IT_round/.venv/lib/python3.12/site-packages/aiogram/dispatcher/event/handler.py", line 43, in call
    return await wrapped()
           ^^^^^^^^^^^^^^^
  File "/Users/hubievkasym/Desktop/Python Projects/IT_round/app/telebot.py", line 120, in show_schedule
    await message.reply(response)
  File "/Users/hubievkasym/Desktop/Python Projects/IT_round/.venv/lib/python3.12/site-packages/aiogram/methods/base.py", line 84, in emit
    return await bot(self)
           ^^^^^^^^^^^^^^^
  File "/Users/hubievkasym/Desktop/Python Projects/IT_round/.venv/lib/python3.12/site-packages/aiogram/client/bot.py", line 482, in __call__
    return await self.session(self, method, timeout=request_timeout)
           ^^^^^^^^^^^^^^^^^^^^^^^^^^^^^^^^^^^^^^^^^^^^^^^^^^^^^^^^^
  File "/Users/hubievkasym/Desktop/Python Projects/IT_round/.venv/lib/python3.12/site-packages/aiogram/client/session/base.py", line 254, in __call__
    return cast(TelegramType, await middleware(bot, method))
                              ^^^^^^^^^^^^^^^^^^^^^^^^^^^^^
  File "/Users/hubievkasym/Desktop/Python Projects/IT_round/.venv/lib/python3.12/site-packages/aiogram/client/session/aiohttp.py", line 185, in make_request
    response = self.check_response(
               ^^^^^^^^^^^^^^^^^^^^
  File "/Users/hubievkasym/Desktop/Python Projects/IT_round/.venv/lib/python3.12/site-packages/aiogram/client/session/base.py", line 120, in check_response
    raise TelegramBadRequest(method=method, message=description)
aiogram.exceptions.TelegramBadRequest: Telegram server says - Bad Request: message text is empty

During handling of the above exception, another exception occurred:

Traceback (most recent call last):
  File "/Users/hubievkasym/Desktop/Python Projects/IT_round/.venv/lib/python3.12/site-packages/aiogram/dispatcher/dispatcher.py", line 309, in _process_update
    response = await self.feed_update(bot, update, **kwargs)
               ^^^^^^^^^^^^^^^^^^^^^^^^^^^^^^^^^^^^^^^^^^^^^
  File "/Users/hubievkasym/Desktop/Python Projects/IT_round/.venv/lib/python3.12/site-packages/aiogram/dispatcher/dispatcher.py", line 158, in feed_update
    response = await self.update.wrap_outer_middleware(
               ^^^^^^^^^^^^^^^^^^^^^^^^^^^^^^^^^^^^^^^^
  File "/Users/hubievkasym/Desktop/Python Projects/IT_round/.venv/lib/python3.12/site-packages/aiogram/dispatcher/middlewares/error.py", line 29, in __call__
    response = await self.router.propagate_event(
               ^^^^^^^^^^^^^^^^^^^^^^^^^^^^^^^^^^
  File "/Users/hubievkasym/Desktop/Python Projects/IT_round/.venv/lib/python3.12/site-packages/aiogram/dispatcher/router.py", line 146, in propagate_event
    return await observer.wrap_outer_middleware(_wrapped, event=event, data=kwargs)
           ^^^^^^^^^^^^^^^^^^^^^^^^^^^^^^^^^^^^^^^^^^^^^^^^^^^^^^^^^^^^^^^^^^^^^^^^
  File "/Users/hubievkasym/Desktop/Python Projects/IT_round/.venv/lib/python3.12/site-packages/aiogram/dispatcher/router.py", line 141, in _wrapped
    return await self._propagate_event(
           ^^^^^^^^^^^^^^^^^^^^^^^^^^^^
  File "/Users/hubievkasym/Desktop/Python Projects/IT_round/.venv/lib/python3.12/site-packages/aiogram/dispatcher/router.py", line 166, in _propagate_event
    response = await observer.trigger(event, **kwargs)
               ^^^^^^^^^^^^^^^^^^^^^^^^^^^^^^^^^^^^^^^
  File "/Users/hubievkasym/Desktop/Python Projects/IT_round/.venv/lib/python3.12/site-packages/aiogram/dispatcher/event/telegram.py", line 121, in trigger
    return await wrapped_inner(event, kwargs)
           ^^^^^^^^^^^^^^^^^^^^^^^^^^^^^^^^^^
  File "/Users/hubievkasym/Desktop/Python Projects/IT_round/.venv/lib/python3.12/site-packages/aiogram/dispatcher/event/handler.py", line 43, in call
    return await wrapped()
                 ^^^^^^^^^
TypeError: global_error_handler() missing 1 required positional argument: 'error'
INFO:aiogram.event:Update id=607674381 is not handled. Duration 87 ms by bot id=7628846836
ERROR:aiogram.event:Cause exception while process update id=607674381 by bot id=7628846836
TypeError: global_error_handler() missing 1 required positional argument: 'error'
Traceback (most recent call last):
  File "/Users/hubievkasym/Desktop/Python Projects/IT_round/.venv/lib/python3.12/site-packages/aiogram/dispatcher/middlewares/error.py", line 25, in __call__
    return await handler(event, data)
           ^^^^^^^^^^^^^^^^^^^^^^^^^^
  File "/Users/hubievkasym/Desktop/Python Projects/IT_round/.venv/lib/python3.12/site-packages/aiogram/dispatcher/middlewares/user_context.py", line 56, in __call__
    return await handler(event, data)
           ^^^^^^^^^^^^^^^^^^^^^^^^^^
  File "/Users/hubievkasym/Desktop/Python Projects/IT_round/.venv/lib/python3.12/site-packages/aiogram/fsm/middleware.py", line 42, in __call__
    return await handler(event, data)
           ^^^^^^^^^^^^^^^^^^^^^^^^^^
  File "/Users/hubievkasym/Desktop/Python Projects/IT_round/.venv/lib/python3.12/site-packages/aiogram/dispatcher/event/telegram.py", line 121, in trigger
    return await wrapped_inner(event, kwargs)
           ^^^^^^^^^^^^^^^^^^^^^^^^^^^^^^^^^^
  File "/Users/hubievkasym/Desktop/Python Projects/IT_round/.venv/lib/python3.12/site-packages/aiogram/dispatcher/event/handler.py", line 43, in call
    return await wrapped()
           ^^^^^^^^^^^^^^^
  File "/Users/hubievkasym/Desktop/Python Projects/IT_round/.venv/lib/python3.12/site-packages/aiogram/dispatcher/dispatcher.py", line 276, in _listen_update
    return await self.propagate_event(update_type=update_type, event=event, **kwargs)
           ^^^^^^^^^^^^^^^^^^^^^^^^^^^^^^^^^^^^^^^^^^^^^^^^^^^^^^^^^^^^^^^^^^^^^^^^^^
  File "/Users/hubievkasym/Desktop/Python Projects/IT_round/.venv/lib/python3.12/site-packages/aiogram/dispatcher/router.py", line 146, in propagate_event
    return await observer.wrap_outer_middleware(_wrapped, event=event, data=kwargs)
           ^^^^^^^^^^^^^^^^^^^^^^^^^^^^^^^^^^^^^^^^^^^^^^^^^^^^^^^^^^^^^^^^^^^^^^^^
  File "/Users/hubievkasym/Desktop/Python Projects/IT_round/.venv/lib/python3.12/site-packages/aiogram/dispatcher/router.py", line 141, in _wrapped
    return await self._propagate_event(
           ^^^^^^^^^^^^^^^^^^^^^^^^^^^^
  File "/Users/hubievkasym/Desktop/Python Projects/IT_round/.venv/lib/python3.12/site-packages/aiogram/dispatcher/router.py", line 166, in _propagate_event
    response = await observer.trigger(event, **kwargs)
               ^^^^^^^^^^^^^^^^^^^^^^^^^^^^^^^^^^^^^^^
  File "/Users/hubievkasym/Desktop/Python Projects/IT_round/.venv/lib/python3.12/site-packages/aiogram/dispatcher/event/telegram.py", line 121, in trigger
    return await wrapped_inner(event, kwargs)
           ^^^^^^^^^^^^^^^^^^^^^^^^^^^^^^^^^^
  File "/Users/hubievkasym/Desktop/Python Projects/IT_round/.venv/lib/python3.12/site-packages/aiogram/dispatcher/event/handler.py", line 43, in call
    return await wrapped()
           ^^^^^^^^^^^^^^^
  File "/Users/hubievkasym/Desktop/Python Projects/IT_round/app/telebot.py", line 120, in show_schedule
    await message.reply(response)
  File "/Users/hubievkasym/Desktop/Python Projects/IT_round/.venv/lib/python3.12/site-packages/aiogram/methods/base.py", line 84, in emit
    return await bot(self)
           ^^^^^^^^^^^^^^^
  File "/Users/hubievkasym/Desktop/Python Projects/IT_round/.venv/lib/python3.12/site-packages/aiogram/client/bot.py", line 482, in __call__
    return await self.session(self, method, timeout=request_timeout)
           ^^^^^^^^^^^^^^^^^^^^^^^^^^^^^^^^^^^^^^^^^^^^^^^^^^^^^^^^^
  File "/Users/hubievkasym/Desktop/Python Projects/IT_round/.venv/lib/python3.12/site-packages/aiogram/client/session/base.py", line 254, in __call__
    return cast(TelegramType, await middleware(bot, method))
                              ^^^^^^^^^^^^^^^^^^^^^^^^^^^^^
  File "/Users/hubievkasym/Desktop/Python Projects/IT_round/.venv/lib/python3.12/site-packages/aiogram/client/session/aiohttp.py", line 185, in make_request
    response = self.check_response(
               ^^^^^^^^^^^^^^^^^^^^
  File "/Users/hubievkasym/Desktop/Python Projects/IT_round/.venv/lib/python3.12/site-packages/aiogram/client/session/base.py", line 120, in check_response
    raise TelegramBadRequest(method=method, message=description)
aiogram.exceptions.TelegramBadRequest: Telegram server says - Bad Request: message text is empty

During handling of the above exception, another exception occurred:

Traceback (most recent call last):
  File "/Users/hubievkasym/Desktop/Python Projects/IT_round/.venv/lib/python3.12/site-packages/aiogram/dispatcher/dispatcher.py", line 309, in _process_update
    response = await self.feed_update(bot, update, **kwargs)
               ^^^^^^^^^^^^^^^^^^^^^^^^^^^^^^^^^^^^^^^^^^^^^
  File "/Users/hubievkasym/Desktop/Python Projects/IT_round/.venv/lib/python3.12/site-packages/aiogram/dispatcher/dispatcher.py", line 158, in feed_update
    response = await self.update.wrap_outer_middleware(
               ^^^^^^^^^^^^^^^^^^^^^^^^^^^^^^^^^^^^^^^^
  File "/Users/hubievkasym/Desktop/Python Projects/IT_round/.venv/lib/python3.12/site-packages/aiogram/dispatcher/middlewares/error.py", line 29, in __call__
    response = await self.router.propagate_event(
               ^^^^^^^^^^^^^^^^^^^^^^^^^^^^^^^^^^
  File "/Users/hubievkasym/Desktop/Python Projects/IT_round/.venv/lib/python3.12/site-packages/aiogram/dispatcher/router.py", line 146, in propagate_event
    return await observer.wrap_outer_middleware(_wrapped, event=event, data=kwargs)
           ^^^^^^^^^^^^^^^^^^^^^^^^^^^^^^^^^^^^^^^^^^^^^^^^^^^^^^^^^^^^^^^^^^^^^^^^
  File "/Users/hubievkasym/Desktop/Python Projects/IT_round/.venv/lib/python3.12/site-packages/aiogram/dispatcher/router.py", line 141, in _wrapped
    return await self._propagate_event(
           ^^^^^^^^^^^^^^^^^^^^^^^^^^^^
  File "/Users/hubievkasym/Desktop/Python Projects/IT_round/.venv/lib/python3.12/site-packages/aiogram/dispatcher/router.py", line 166, in _propagate_event
    response = await observer.trigger(event, **kwargs)
               ^^^^^^^^^^^^^^^^^^^^^^^^^^^^^^^^^^^^^^^
  File "/Users/hubievkasym/Desktop/Python Projects/IT_round/.venv/lib/python3.12/site-packages/aiogram/dispatcher/event/telegram.py", line 121, in trigger
    return await wrapped_inner(event, kwargs)
           ^^^^^^^^^^^^^^^^^^^^^^^^^^^^^^^^^^
  File "/Users/hubievkasym/Desktop/Python Projects/IT_round/.venv/lib/python3.12/site-packages/aiogram/dispatcher/event/handler.py", line 43, in call
    return await wrapped()
                 ^^^^^^^^^
TypeError: global_error_handler() missing 1 required positional argument: 'error'
INFO:aiogram.event:Update id=607674382 is handled. Duration 103 ms by bot id=7628846836
INFO:aiogram.event:Update id=607674383 is handled. Duration 114 ms by bot id=7628846836
INFO:aiogram.event:Update id=607674384 is handled. Duration 106 ms by bot id=7628846836
WARNING:aiogram.dispatcher:Received SIGINT signal
INFO:aiogram.dispatcher:Polling stopped for bot @mariam_chat_bot id=7628846836 - 'mariam_chat_bot'
INFO:aiogram.dispatcher:Polling stopped
INFO:aiogram.dispatcher:Start polling
INFO:aiogram.dispatcher:Run polling for bot @mariam_chat_bot id=7628846836 - 'mariam_chat_bot'
INFO:aiogram.event:Update id=607674385 is handled. Duration 346 ms by bot id=7628846836
INFO:aiogram.event:Update id=607674386 is not handled. Duration 91 ms by bot id=7628846836
ERROR:aiogram.event:Cause exception while process update id=607674386 by bot id=7628846836
TypeError: global_error_handler() missing 1 required positional argument: 'error'
Traceback (most recent call last):
  File "/Users/hubievkasym/Desktop/Python Projects/IT_round/.venv/lib/python3.12/site-packages/aiogram/dispatcher/middlewares/error.py", line 25, in __call__
    return await handler(event, data)
           ^^^^^^^^^^^^^^^^^^^^^^^^^^
  File "/Users/hubievkasym/Desktop/Python Projects/IT_round/.venv/lib/python3.12/site-packages/aiogram/dispatcher/middlewares/user_context.py", line 56, in __call__
    return await handler(event, data)
           ^^^^^^^^^^^^^^^^^^^^^^^^^^
  File "/Users/hubievkasym/Desktop/Python Projects/IT_round/.venv/lib/python3.12/site-packages/aiogram/fsm/middleware.py", line 42, in __call__
    return await handler(event, data)
           ^^^^^^^^^^^^^^^^^^^^^^^^^^
  File "/Users/hubievkasym/Desktop/Python Projects/IT_round/.venv/lib/python3.12/site-packages/aiogram/dispatcher/event/telegram.py", line 121, in trigger
    return await wrapped_inner(event, kwargs)
           ^^^^^^^^^^^^^^^^^^^^^^^^^^^^^^^^^^
  File "/Users/hubievkasym/Desktop/Python Projects/IT_round/.venv/lib/python3.12/site-packages/aiogram/dispatcher/event/handler.py", line 43, in call
    return await wrapped()
           ^^^^^^^^^^^^^^^
  File "/Users/hubievkasym/Desktop/Python Projects/IT_round/.venv/lib/python3.12/site-packages/aiogram/dispatcher/dispatcher.py", line 276, in _listen_update
    return await self.propagate_event(update_type=update_type, event=event, **kwargs)
           ^^^^^^^^^^^^^^^^^^^^^^^^^^^^^^^^^^^^^^^^^^^^^^^^^^^^^^^^^^^^^^^^^^^^^^^^^^
  File "/Users/hubievkasym/Desktop/Python Projects/IT_round/.venv/lib/python3.12/site-packages/aiogram/dispatcher/router.py", line 146, in propagate_event
    return await observer.wrap_outer_middleware(_wrapped, event=event, data=kwargs)
           ^^^^^^^^^^^^^^^^^^^^^^^^^^^^^^^^^^^^^^^^^^^^^^^^^^^^^^^^^^^^^^^^^^^^^^^^
  File "/Users/hubievkasym/Desktop/Python Projects/IT_round/.venv/lib/python3.12/site-packages/aiogram/dispatcher/router.py", line 141, in _wrapped
    return await self._propagate_event(
           ^^^^^^^^^^^^^^^^^^^^^^^^^^^^
  File "/Users/hubievkasym/Desktop/Python Projects/IT_round/.venv/lib/python3.12/site-packages/aiogram/dispatcher/router.py", line 166, in _propagate_event
    response = await observer.trigger(event, **kwargs)
               ^^^^^^^^^^^^^^^^^^^^^^^^^^^^^^^^^^^^^^^
  File "/Users/hubievkasym/Desktop/Python Projects/IT_round/.venv/lib/python3.12/site-packages/aiogram/dispatcher/event/telegram.py", line 121, in trigger
    return await wrapped_inner(event, kwargs)
           ^^^^^^^^^^^^^^^^^^^^^^^^^^^^^^^^^^
  File "/Users/hubievkasym/Desktop/Python Projects/IT_round/.venv/lib/python3.12/site-packages/aiogram/dispatcher/event/handler.py", line 43, in call
    return await wrapped()
           ^^^^^^^^^^^^^^^
  File "/Users/hubievkasym/Desktop/Python Projects/IT_round/app/telebot.py", line 120, in show_schedule
    await message.reply(response)
  File "/Users/hubievkasym/Desktop/Python Projects/IT_round/.venv/lib/python3.12/site-packages/aiogram/methods/base.py", line 84, in emit
    return await bot(self)
           ^^^^^^^^^^^^^^^
  File "/Users/hubievkasym/Desktop/Python Projects/IT_round/.venv/lib/python3.12/site-packages/aiogram/client/bot.py", line 482, in __call__
    return await self.session(self, method, timeout=request_timeout)
           ^^^^^^^^^^^^^^^^^^^^^^^^^^^^^^^^^^^^^^^^^^^^^^^^^^^^^^^^^
  File "/Users/hubievkasym/Desktop/Python Projects/IT_round/.venv/lib/python3.12/site-packages/aiogram/client/session/base.py", line 254, in __call__
    return cast(TelegramType, await middleware(bot, method))
                              ^^^^^^^^^^^^^^^^^^^^^^^^^^^^^
  File "/Users/hubievkasym/Desktop/Python Projects/IT_round/.venv/lib/python3.12/site-packages/aiogram/client/session/aiohttp.py", line 185, in make_request
    response = self.check_response(
               ^^^^^^^^^^^^^^^^^^^^
  File "/Users/hubievkasym/Desktop/Python Projects/IT_round/.venv/lib/python3.12/site-packages/aiogram/client/session/base.py", line 120, in check_response
    raise TelegramBadRequest(method=method, message=description)
aiogram.exceptions.TelegramBadRequest: Telegram server says - Bad Request: message text is empty

During handling of the above exception, another exception occurred:

Traceback (most recent call last):
  File "/Users/hubievkasym/Desktop/Python Projects/IT_round/.venv/lib/python3.12/site-packages/aiogram/dispatcher/dispatcher.py", line 309, in _process_update
    response = await self.feed_update(bot, update, **kwargs)
               ^^^^^^^^^^^^^^^^^^^^^^^^^^^^^^^^^^^^^^^^^^^^^
  File "/Users/hubievkasym/Desktop/Python Projects/IT_round/.venv/lib/python3.12/site-packages/aiogram/dispatcher/dispatcher.py", line 158, in feed_update
    response = await self.update.wrap_outer_middleware(
               ^^^^^^^^^^^^^^^^^^^^^^^^^^^^^^^^^^^^^^^^
  File "/Users/hubievkasym/Desktop/Python Projects/IT_round/.venv/lib/python3.12/site-packages/aiogram/dispatcher/middlewares/error.py", line 29, in __call__
    response = await self.router.propagate_event(
               ^^^^^^^^^^^^^^^^^^^^^^^^^^^^^^^^^^
  File "/Users/hubievkasym/Desktop/Python Projects/IT_round/.venv/lib/python3.12/site-packages/aiogram/dispatcher/router.py", line 146, in propagate_event
    return await observer.wrap_outer_middleware(_wrapped, event=event, data=kwargs)
           ^^^^^^^^^^^^^^^^^^^^^^^^^^^^^^^^^^^^^^^^^^^^^^^^^^^^^^^^^^^^^^^^^^^^^^^^
  File "/Users/hubievkasym/Desktop/Python Projects/IT_round/.venv/lib/python3.12/site-packages/aiogram/dispatcher/router.py", line 141, in _wrapped
    return await self._propagate_event(
           ^^^^^^^^^^^^^^^^^^^^^^^^^^^^
  File "/Users/hubievkasym/Desktop/Python Projects/IT_round/.venv/lib/python3.12/site-packages/aiogram/dispatcher/router.py", line 166, in _propagate_event
    response = await observer.trigger(event, **kwargs)
               ^^^^^^^^^^^^^^^^^^^^^^^^^^^^^^^^^^^^^^^
  File "/Users/hubievkasym/Desktop/Python Projects/IT_round/.venv/lib/python3.12/site-packages/aiogram/dispatcher/event/telegram.py", line 121, in trigger
    return await wrapped_inner(event, kwargs)
           ^^^^^^^^^^^^^^^^^^^^^^^^^^^^^^^^^^
  File "/Users/hubievkasym/Desktop/Python Projects/IT_round/.venv/lib/python3.12/site-packages/aiogram/dispatcher/event/handler.py", line 43, in call
    return await wrapped()
                 ^^^^^^^^^
TypeError: global_error_handler() missing 1 required positional argument: 'error'
INFO:aiogram.event:Update id=607674387 is handled. Duration 151 ms by bot id=7628846836
WARNING:aiogram.dispatcher:Received SIGINT signal
INFO:aiogram.dispatcher:Polling stopped for bot @mariam_chat_bot id=7628846836 - 'mariam_chat_bot'
INFO:aiogram.dispatcher:Polling stopped
INFO:aiogram.dispatcher:Start polling
INFO:aiogram.dispatcher:Run polling for bot @mariam_chat_bot id=7628846836 - 'mariam_chat_bot'
INFO:aiogram.event:Update id=607674388 is handled. Duration 304 ms by bot id=7628846836
WARNING:aiogram.dispatcher:Received SIGINT signal
INFO:aiogram.dispatcher:Polling stopped for bot @mariam_chat_bot id=7628846836 - 'mariam_chat_bot'
INFO:aiogram.dispatcher:Polling stopped
INFO:aiogram.dispatcher:Start polling
INFO:aiogram.dispatcher:Run polling for bot @mariam_chat_bot id=7628846836 - 'mariam_chat_bot'
INFO:aiogram.event:Update id=607674389 is handled. Duration 302 ms by bot id=7628846836
INFO:aiogram.event:Update id=607674390 is not handled. Duration 172 ms by bot id=7628846836
ERROR:aiogram.event:Cause exception while process update id=607674390 by bot id=7628846836
TypeError: global_error_handler() missing 1 required positional argument: 'error'
Traceback (most recent call last):
  File "/Users/hubievkasym/Desktop/Python Projects/IT_round/.venv/lib/python3.12/site-packages/aiogram/dispatcher/middlewares/error.py", line 25, in __call__
    return await handler(event, data)
           ^^^^^^^^^^^^^^^^^^^^^^^^^^
  File "/Users/hubievkasym/Desktop/Python Projects/IT_round/.venv/lib/python3.12/site-packages/aiogram/dispatcher/middlewares/user_context.py", line 56, in __call__
    return await handler(event, data)
           ^^^^^^^^^^^^^^^^^^^^^^^^^^
  File "/Users/hubievkasym/Desktop/Python Projects/IT_round/.venv/lib/python3.12/site-packages/aiogram/fsm/middleware.py", line 42, in __call__
    return await handler(event, data)
           ^^^^^^^^^^^^^^^^^^^^^^^^^^
  File "/Users/hubievkasym/Desktop/Python Projects/IT_round/.venv/lib/python3.12/site-packages/aiogram/dispatcher/event/telegram.py", line 121, in trigger
    return await wrapped_inner(event, kwargs)
           ^^^^^^^^^^^^^^^^^^^^^^^^^^^^^^^^^^
  File "/Users/hubievkasym/Desktop/Python Projects/IT_round/.venv/lib/python3.12/site-packages/aiogram/dispatcher/event/handler.py", line 43, in call
    return await wrapped()
           ^^^^^^^^^^^^^^^
  File "/Users/hubievkasym/Desktop/Python Projects/IT_round/.venv/lib/python3.12/site-packages/aiogram/dispatcher/dispatcher.py", line 276, in _listen_update
    return await self.propagate_event(update_type=update_type, event=event, **kwargs)
           ^^^^^^^^^^^^^^^^^^^^^^^^^^^^^^^^^^^^^^^^^^^^^^^^^^^^^^^^^^^^^^^^^^^^^^^^^^
  File "/Users/hubievkasym/Desktop/Python Projects/IT_round/.venv/lib/python3.12/site-packages/aiogram/dispatcher/router.py", line 146, in propagate_event
    return await observer.wrap_outer_middleware(_wrapped, event=event, data=kwargs)
           ^^^^^^^^^^^^^^^^^^^^^^^^^^^^^^^^^^^^^^^^^^^^^^^^^^^^^^^^^^^^^^^^^^^^^^^^
  File "/Users/hubievkasym/Desktop/Python Projects/IT_round/.venv/lib/python3.12/site-packages/aiogram/dispatcher/router.py", line 141, in _wrapped
    return await self._propagate_event(
           ^^^^^^^^^^^^^^^^^^^^^^^^^^^^
  File "/Users/hubievkasym/Desktop/Python Projects/IT_round/.venv/lib/python3.12/site-packages/aiogram/dispatcher/router.py", line 166, in _propagate_event
    response = await observer.trigger(event, **kwargs)
               ^^^^^^^^^^^^^^^^^^^^^^^^^^^^^^^^^^^^^^^
  File "/Users/hubievkasym/Desktop/Python Projects/IT_round/.venv/lib/python3.12/site-packages/aiogram/dispatcher/event/telegram.py", line 121, in trigger
    return await wrapped_inner(event, kwargs)
           ^^^^^^^^^^^^^^^^^^^^^^^^^^^^^^^^^^
  File "/Users/hubievkasym/Desktop/Python Projects/IT_round/.venv/lib/python3.12/site-packages/aiogram/dispatcher/event/handler.py", line 43, in call
    return await wrapped()
           ^^^^^^^^^^^^^^^
  File "/Users/hubievkasym/Desktop/Python Projects/IT_round/app/telebot.py", line 146, in add_event_start
    await check_events()
  File "/Users/hubievkasym/Desktop/Python Projects/IT_round/app/telebot.py", line 153, in check_events
    events = database.get_events(start=now, end=end)
             ^^^^^^^^^^^^^^^^^^^^^^^^^^^^^^^^^^^^^^^
  File "/Users/hubievkasym/Desktop/Python Projects/IT_round/app/database/sql.py", line 25, in wrapper
    raise e
  File "/Users/hubievkasym/Desktop/Python Projects/IT_round/app/database/sql.py", line 18, in wrapper
    result = func(session=session, *args, **kwargs)
             ^^^^^^^^^^^^^^^^^^^^^^^^^^^^^^^^^^^^^^
  File "/Users/hubievkasym/Desktop/Python Projects/IT_round/app/database/sql.py", line 48, in get_events
    EventNotofication(
  File "/Users/hubievkasym/Desktop/Python Projects/IT_round/.venv/lib/python3.12/site-packages/pydantic/main.py", line 253, in __init__
    validated_self = self.__pydantic_validator__.validate_python(data, self_instance=self)
                     ^^^^^^^^^^^^^^^^^^^^^^^^^^^^^^^^^^^^^^^^^^^^^^^^^^^^^^^^^^^^^^^^^^^^^
pydantic_core._pydantic_core.ValidationError: 1 validation error for EventNotofication
event_name
  Input should be a valid string [type=string_type, input_value=datetime.datetime(2025, 7, 12, 15, 0), input_type=datetime]
    For further information visit https://errors.pydantic.dev/2.11/v/string_type

During handling of the above exception, another exception occurred:

Traceback (most recent call last):
  File "/Users/hubievkasym/Desktop/Python Projects/IT_round/.venv/lib/python3.12/site-packages/aiogram/dispatcher/dispatcher.py", line 309, in _process_update
    response = await self.feed_update(bot, update, **kwargs)
               ^^^^^^^^^^^^^^^^^^^^^^^^^^^^^^^^^^^^^^^^^^^^^
  File "/Users/hubievkasym/Desktop/Python Projects/IT_round/.venv/lib/python3.12/site-packages/aiogram/dispatcher/dispatcher.py", line 158, in feed_update
    response = await self.update.wrap_outer_middleware(
               ^^^^^^^^^^^^^^^^^^^^^^^^^^^^^^^^^^^^^^^^
  File "/Users/hubievkasym/Desktop/Python Projects/IT_round/.venv/lib/python3.12/site-packages/aiogram/dispatcher/middlewares/error.py", line 29, in __call__
    response = await self.router.propagate_event(
               ^^^^^^^^^^^^^^^^^^^^^^^^^^^^^^^^^^
  File "/Users/hubievkasym/Desktop/Python Projects/IT_round/.venv/lib/python3.12/site-packages/aiogram/dispatcher/router.py", line 146, in propagate_event
    return await observer.wrap_outer_middleware(_wrapped, event=event, data=kwargs)
           ^^^^^^^^^^^^^^^^^^^^^^^^^^^^^^^^^^^^^^^^^^^^^^^^^^^^^^^^^^^^^^^^^^^^^^^^
  File "/Users/hubievkasym/Desktop/Python Projects/IT_round/.venv/lib/python3.12/site-packages/aiogram/dispatcher/router.py", line 141, in _wrapped
    return await self._propagate_event(
           ^^^^^^^^^^^^^^^^^^^^^^^^^^^^
  File "/Users/hubievkasym/Desktop/Python Projects/IT_round/.venv/lib/python3.12/site-packages/aiogram/dispatcher/router.py", line 166, in _propagate_event
    response = await observer.trigger(event, **kwargs)
               ^^^^^^^^^^^^^^^^^^^^^^^^^^^^^^^^^^^^^^^
  File "/Users/hubievkasym/Desktop/Python Projects/IT_round/.venv/lib/python3.12/site-packages/aiogram/dispatcher/event/telegram.py", line 121, in trigger
    return await wrapped_inner(event, kwargs)
           ^^^^^^^^^^^^^^^^^^^^^^^^^^^^^^^^^^
  File "/Users/hubievkasym/Desktop/Python Projects/IT_round/.venv/lib/python3.12/site-packages/aiogram/dispatcher/event/handler.py", line 43, in call
    return await wrapped()
                 ^^^^^^^^^
TypeError: global_error_handler() missing 1 required positional argument: 'error'
INFO:aiogram.event:Update id=607674391 is not handled. Duration 2 ms by bot id=7628846836
ERROR:aiogram.event:Cause exception while process update id=607674391 by bot id=7628846836
TypeError: global_error_handler() missing 1 required positional argument: 'error'
Traceback (most recent call last):
  File "/Users/hubievkasym/Desktop/Python Projects/IT_round/.venv/lib/python3.12/site-packages/aiogram/dispatcher/middlewares/error.py", line 25, in __call__
    return await handler(event, data)
           ^^^^^^^^^^^^^^^^^^^^^^^^^^
  File "/Users/hubievkasym/Desktop/Python Projects/IT_round/.venv/lib/python3.12/site-packages/aiogram/dispatcher/middlewares/user_context.py", line 56, in __call__
    return await handler(event, data)
           ^^^^^^^^^^^^^^^^^^^^^^^^^^
  File "/Users/hubievkasym/Desktop/Python Projects/IT_round/.venv/lib/python3.12/site-packages/aiogram/fsm/middleware.py", line 42, in __call__
    return await handler(event, data)
           ^^^^^^^^^^^^^^^^^^^^^^^^^^
  File "/Users/hubievkasym/Desktop/Python Projects/IT_round/.venv/lib/python3.12/site-packages/aiogram/dispatcher/event/telegram.py", line 121, in trigger
    return await wrapped_inner(event, kwargs)
           ^^^^^^^^^^^^^^^^^^^^^^^^^^^^^^^^^^
  File "/Users/hubievkasym/Desktop/Python Projects/IT_round/.venv/lib/python3.12/site-packages/aiogram/dispatcher/event/handler.py", line 43, in call
    return await wrapped()
           ^^^^^^^^^^^^^^^
  File "/Users/hubievkasym/Desktop/Python Projects/IT_round/.venv/lib/python3.12/site-packages/aiogram/dispatcher/dispatcher.py", line 276, in _listen_update
    return await self.propagate_event(update_type=update_type, event=event, **kwargs)
           ^^^^^^^^^^^^^^^^^^^^^^^^^^^^^^^^^^^^^^^^^^^^^^^^^^^^^^^^^^^^^^^^^^^^^^^^^^
  File "/Users/hubievkasym/Desktop/Python Projects/IT_round/.venv/lib/python3.12/site-packages/aiogram/dispatcher/router.py", line 146, in propagate_event
    return await observer.wrap_outer_middleware(_wrapped, event=event, data=kwargs)
           ^^^^^^^^^^^^^^^^^^^^^^^^^^^^^^^^^^^^^^^^^^^^^^^^^^^^^^^^^^^^^^^^^^^^^^^^
  File "/Users/hubievkasym/Desktop/Python Projects/IT_round/.venv/lib/python3.12/site-packages/aiogram/dispatcher/router.py", line 141, in _wrapped
    return await self._propagate_event(
           ^^^^^^^^^^^^^^^^^^^^^^^^^^^^
  File "/Users/hubievkasym/Desktop/Python Projects/IT_round/.venv/lib/python3.12/site-packages/aiogram/dispatcher/router.py", line 166, in _propagate_event
    response = await observer.trigger(event, **kwargs)
               ^^^^^^^^^^^^^^^^^^^^^^^^^^^^^^^^^^^^^^^
  File "/Users/hubievkasym/Desktop/Python Projects/IT_round/.venv/lib/python3.12/site-packages/aiogram/dispatcher/event/telegram.py", line 121, in trigger
    return await wrapped_inner(event, kwargs)
           ^^^^^^^^^^^^^^^^^^^^^^^^^^^^^^^^^^
  File "/Users/hubievkasym/Desktop/Python Projects/IT_round/.venv/lib/python3.12/site-packages/aiogram/dispatcher/event/handler.py", line 43, in call
    return await wrapped()
           ^^^^^^^^^^^^^^^
  File "/Users/hubievkasym/Desktop/Python Projects/IT_round/app/telebot.py", line 111, in show_schedule
    events = database.get_user_events(str(message.chat.id), start, end)
             ^^^^^^^^^^^^^^^^^^^^^^^^^^^^^^^^^^^^^^^^^^^^^^^^^^^^^^^^^^
  File "/Users/hubievkasym/Desktop/Python Projects/IT_round/app/database/sql.py", line 25, in wrapper
    raise e
  File "/Users/hubievkasym/Desktop/Python Projects/IT_round/app/database/sql.py", line 18, in wrapper
    result = func(session=session, *args, **kwargs)
             ^^^^^^^^^^^^^^^^^^^^^^^^^^^^^^^^^^^^^^
  File "/Users/hubievkasym/Desktop/Python Projects/IT_round/app/database/sql.py", line 85, in get_user_events
    EventResponse(
  File "/Users/hubievkasym/Desktop/Python Projects/IT_round/.venv/lib/python3.12/site-packages/pydantic/main.py", line 253, in __init__
    validated_self = self.__pydantic_validator__.validate_python(data, self_instance=self)
                     ^^^^^^^^^^^^^^^^^^^^^^^^^^^^^^^^^^^^^^^^^^^^^^^^^^^^^^^^^^^^^^^^^^^^^
pydantic_core._pydantic_core.ValidationError: 1 validation error for EventResponse
event_type
  Field required [type=missing, input_value={'event_name': 'Meeting',...', 'event_time': '15:0'}, input_type=dict]
    For further information visit https://errors.pydantic.dev/2.11/v/missing

During handling of the above exception, another exception occurred:

Traceback (most recent call last):
  File "/Users/hubievkasym/Desktop/Python Projects/IT_round/.venv/lib/python3.12/site-packages/aiogram/dispatcher/dispatcher.py", line 309, in _process_update
    response = await self.feed_update(bot, update, **kwargs)
               ^^^^^^^^^^^^^^^^^^^^^^^^^^^^^^^^^^^^^^^^^^^^^
  File "/Users/hubievkasym/Desktop/Python Projects/IT_round/.venv/lib/python3.12/site-packages/aiogram/dispatcher/dispatcher.py", line 158, in feed_update
    response = await self.update.wrap_outer_middleware(
               ^^^^^^^^^^^^^^^^^^^^^^^^^^^^^^^^^^^^^^^^
  File "/Users/hubievkasym/Desktop/Python Projects/IT_round/.venv/lib/python3.12/site-packages/aiogram/dispatcher/middlewares/error.py", line 29, in __call__
    response = await self.router.propagate_event(
               ^^^^^^^^^^^^^^^^^^^^^^^^^^^^^^^^^^
  File "/Users/hubievkasym/Desktop/Python Projects/IT_round/.venv/lib/python3.12/site-packages/aiogram/dispatcher/router.py", line 146, in propagate_event
    return await observer.wrap_outer_middleware(_wrapped, event=event, data=kwargs)
           ^^^^^^^^^^^^^^^^^^^^^^^^^^^^^^^^^^^^^^^^^^^^^^^^^^^^^^^^^^^^^^^^^^^^^^^^
  File "/Users/hubievkasym/Desktop/Python Projects/IT_round/.venv/lib/python3.12/site-packages/aiogram/dispatcher/router.py", line 141, in _wrapped
    return await self._propagate_event(
           ^^^^^^^^^^^^^^^^^^^^^^^^^^^^
  File "/Users/hubievkasym/Desktop/Python Projects/IT_round/.venv/lib/python3.12/site-packages/aiogram/dispatcher/router.py", line 166, in _propagate_event
    response = await observer.trigger(event, **kwargs)
               ^^^^^^^^^^^^^^^^^^^^^^^^^^^^^^^^^^^^^^^
  File "/Users/hubievkasym/Desktop/Python Projects/IT_round/.venv/lib/python3.12/site-packages/aiogram/dispatcher/event/telegram.py", line 121, in trigger
    return await wrapped_inner(event, kwargs)
           ^^^^^^^^^^^^^^^^^^^^^^^^^^^^^^^^^^
  File "/Users/hubievkasym/Desktop/Python Projects/IT_round/.venv/lib/python3.12/site-packages/aiogram/dispatcher/event/handler.py", line 43, in call
    return await wrapped()
                 ^^^^^^^^^
TypeError: global_error_handler() missing 1 required positional argument: 'error'
WARNING:aiogram.dispatcher:Received SIGINT signal
INFO:aiogram.dispatcher:Polling stopped for bot @mariam_chat_bot id=7628846836 - 'mariam_chat_bot'
INFO:aiogram.dispatcher:Polling stopped
INFO:aiogram.dispatcher:Start polling
INFO:aiogram.dispatcher:Run polling for bot @mariam_chat_bot id=7628846836 - 'mariam_chat_bot'
INFO:aiogram.event:Update id=607674392 is not handled. Duration 9 ms by bot id=7628846836
ERROR:aiogram.event:Cause exception while process update id=607674392 by bot id=7628846836
TypeError: global_error_handler() missing 1 required positional argument: 'error'
Traceback (most recent call last):
  File "/Users/hubievkasym/Desktop/Python Projects/IT_round/.venv/lib/python3.12/site-packages/aiogram/dispatcher/middlewares/error.py", line 25, in __call__
    return await handler(event, data)
           ^^^^^^^^^^^^^^^^^^^^^^^^^^
  File "/Users/hubievkasym/Desktop/Python Projects/IT_round/.venv/lib/python3.12/site-packages/aiogram/dispatcher/middlewares/user_context.py", line 56, in __call__
    return await handler(event, data)
           ^^^^^^^^^^^^^^^^^^^^^^^^^^
  File "/Users/hubievkasym/Desktop/Python Projects/IT_round/.venv/lib/python3.12/site-packages/aiogram/fsm/middleware.py", line 42, in __call__
    return await handler(event, data)
           ^^^^^^^^^^^^^^^^^^^^^^^^^^
  File "/Users/hubievkasym/Desktop/Python Projects/IT_round/.venv/lib/python3.12/site-packages/aiogram/dispatcher/event/telegram.py", line 121, in trigger
    return await wrapped_inner(event, kwargs)
           ^^^^^^^^^^^^^^^^^^^^^^^^^^^^^^^^^^
  File "/Users/hubievkasym/Desktop/Python Projects/IT_round/.venv/lib/python3.12/site-packages/aiogram/dispatcher/event/handler.py", line 43, in call
    return await wrapped()
           ^^^^^^^^^^^^^^^
  File "/Users/hubievkasym/Desktop/Python Projects/IT_round/.venv/lib/python3.12/site-packages/aiogram/dispatcher/dispatcher.py", line 276, in _listen_update
    return await self.propagate_event(update_type=update_type, event=event, **kwargs)
           ^^^^^^^^^^^^^^^^^^^^^^^^^^^^^^^^^^^^^^^^^^^^^^^^^^^^^^^^^^^^^^^^^^^^^^^^^^
  File "/Users/hubievkasym/Desktop/Python Projects/IT_round/.venv/lib/python3.12/site-packages/aiogram/dispatcher/router.py", line 146, in propagate_event
    return await observer.wrap_outer_middleware(_wrapped, event=event, data=kwargs)
           ^^^^^^^^^^^^^^^^^^^^^^^^^^^^^^^^^^^^^^^^^^^^^^^^^^^^^^^^^^^^^^^^^^^^^^^^
  File "/Users/hubievkasym/Desktop/Python Projects/IT_round/.venv/lib/python3.12/site-packages/aiogram/dispatcher/router.py", line 141, in _wrapped
    return await self._propagate_event(
           ^^^^^^^^^^^^^^^^^^^^^^^^^^^^
  File "/Users/hubievkasym/Desktop/Python Projects/IT_round/.venv/lib/python3.12/site-packages/aiogram/dispatcher/router.py", line 166, in _propagate_event
    response = await observer.trigger(event, **kwargs)
               ^^^^^^^^^^^^^^^^^^^^^^^^^^^^^^^^^^^^^^^
  File "/Users/hubievkasym/Desktop/Python Projects/IT_round/.venv/lib/python3.12/site-packages/aiogram/dispatcher/event/telegram.py", line 121, in trigger
    return await wrapped_inner(event, kwargs)
           ^^^^^^^^^^^^^^^^^^^^^^^^^^^^^^^^^^
  File "/Users/hubievkasym/Desktop/Python Projects/IT_round/.venv/lib/python3.12/site-packages/aiogram/dispatcher/event/handler.py", line 43, in call
    return await wrapped()
           ^^^^^^^^^^^^^^^
  File "/Users/hubievkasym/Desktop/Python Projects/IT_round/app/telebot.py", line 111, in show_schedule
    events = database.get_user_events(str(message.chat.id), start, end)
             ^^^^^^^^^^^^^^^^^^^^^^^^^^^^^^^^^^^^^^^^^^^^^^^^^^^^^^^^^^
  File "/Users/hubievkasym/Desktop/Python Projects/IT_round/app/database/sql.py", line 25, in wrapper
    raise e
  File "/Users/hubievkasym/Desktop/Python Projects/IT_round/app/database/sql.py", line 18, in wrapper
    result = func(session=session, *args, **kwargs)
             ^^^^^^^^^^^^^^^^^^^^^^^^^^^^^^^^^^^^^^
  File "/Users/hubievkasym/Desktop/Python Projects/IT_round/app/database/sql.py", line 85, in get_user_events
    EventResponse(
  File "/Users/hubievkasym/Desktop/Python Projects/IT_round/.venv/lib/python3.12/site-packages/pydantic/main.py", line 253, in __init__
    validated_self = self.__pydantic_validator__.validate_python(data, self_instance=self)
                     ^^^^^^^^^^^^^^^^^^^^^^^^^^^^^^^^^^^^^^^^^^^^^^^^^^^^^^^^^^^^^^^^^^^^^
pydantic_core._pydantic_core.ValidationError: 1 validation error for EventResponse
event_type
  Field required [type=missing, input_value={'event_name': 'Meeting',...', 'event_time': '15:0'}, input_type=dict]
    For further information visit https://errors.pydantic.dev/2.11/v/missing

During handling of the above exception, another exception occurred:

Traceback (most recent call last):
  File "/Users/hubievkasym/Desktop/Python Projects/IT_round/.venv/lib/python3.12/site-packages/aiogram/dispatcher/dispatcher.py", line 309, in _process_update
    response = await self.feed_update(bot, update, **kwargs)
               ^^^^^^^^^^^^^^^^^^^^^^^^^^^^^^^^^^^^^^^^^^^^^
  File "/Users/hubievkasym/Desktop/Python Projects/IT_round/.venv/lib/python3.12/site-packages/aiogram/dispatcher/dispatcher.py", line 158, in feed_update
    response = await self.update.wrap_outer_middleware(
               ^^^^^^^^^^^^^^^^^^^^^^^^^^^^^^^^^^^^^^^^
  File "/Users/hubievkasym/Desktop/Python Projects/IT_round/.venv/lib/python3.12/site-packages/aiogram/dispatcher/middlewares/error.py", line 29, in __call__
    response = await self.router.propagate_event(
               ^^^^^^^^^^^^^^^^^^^^^^^^^^^^^^^^^^
  File "/Users/hubievkasym/Desktop/Python Projects/IT_round/.venv/lib/python3.12/site-packages/aiogram/dispatcher/router.py", line 146, in propagate_event
    return await observer.wrap_outer_middleware(_wrapped, event=event, data=kwargs)
           ^^^^^^^^^^^^^^^^^^^^^^^^^^^^^^^^^^^^^^^^^^^^^^^^^^^^^^^^^^^^^^^^^^^^^^^^
  File "/Users/hubievkasym/Desktop/Python Projects/IT_round/.venv/lib/python3.12/site-packages/aiogram/dispatcher/router.py", line 141, in _wrapped
    return await self._propagate_event(
           ^^^^^^^^^^^^^^^^^^^^^^^^^^^^
  File "/Users/hubievkasym/Desktop/Python Projects/IT_round/.venv/lib/python3.12/site-packages/aiogram/dispatcher/router.py", line 166, in _propagate_event
    response = await observer.trigger(event, **kwargs)
               ^^^^^^^^^^^^^^^^^^^^^^^^^^^^^^^^^^^^^^^
  File "/Users/hubievkasym/Desktop/Python Projects/IT_round/.venv/lib/python3.12/site-packages/aiogram/dispatcher/event/telegram.py", line 121, in trigger
    return await wrapped_inner(event, kwargs)
           ^^^^^^^^^^^^^^^^^^^^^^^^^^^^^^^^^^
  File "/Users/hubievkasym/Desktop/Python Projects/IT_round/.venv/lib/python3.12/site-packages/aiogram/dispatcher/event/handler.py", line 43, in call
    return await wrapped()
                 ^^^^^^^^^
TypeError: global_error_handler() missing 1 required positional argument: 'error'
WARNING:aiogram.dispatcher:Received SIGINT signal
INFO:aiogram.dispatcher:Polling stopped for bot @mariam_chat_bot id=7628846836 - 'mariam_chat_bot'
INFO:aiogram.dispatcher:Polling stopped
INFO:aiogram.dispatcher:Start polling
INFO:aiogram.dispatcher:Run polling for bot @mariam_chat_bot id=7628846836 - 'mariam_chat_bot'
INFO:aiogram.event:Update id=607674393 is handled. Duration 843 ms by bot id=7628846836
INFO:aiogram.event:Update id=607674394 is handled. Duration 123 ms by bot id=7628846836
